[2023-12-11T00:00:00.997+0000] {processor.py:157} INFO - Started process (PID=3603) to work on /opt/airflow/dags/main_de_project_1_dag.py
[2023-12-11T00:00:00.999+0000] {processor.py:829} INFO - Processing file /opt/airflow/dags/main_de_project_1_dag.py for tasks to queue
[2023-12-11T00:00:01.005+0000] {logging_mixin.py:154} INFO - [2023-12-11T00:00:01.004+0000] {dagbag.py:536} INFO - Filling up the DagBag from /opt/airflow/dags/main_de_project_1_dag.py
[2023-12-11T00:00:01.017+0000] {logging_mixin.py:154} INFO - [2023-12-11T00:00:01.015+0000] {dagbag.py:346} ERROR - Failed to import: /opt/airflow/dags/main_de_project_1_dag.py
Traceback (most recent call last):
  File "/home/airflow/.local/lib/python3.8/site-packages/airflow/models/dagbag.py", line 342, in parse
    loader.exec_module(new_module)
  File "<frozen importlib._bootstrap_external>", line 843, in exec_module
  File "<frozen importlib._bootstrap>", line 219, in _call_with_frames_removed
  File "/opt/airflow/dags/main_de_project_1_dag.py", line 11, in <module>
    import create_tables
ModuleNotFoundError: No module named 'create_tables'
[2023-12-11T00:00:01.019+0000] {processor.py:841} WARNING - No viable dags retrieved from /opt/airflow/dags/main_de_project_1_dag.py
[2023-12-11T00:00:01.040+0000] {processor.py:179} INFO - Processing /opt/airflow/dags/main_de_project_1_dag.py took 0.047 seconds
[2023-12-11T00:00:31.168+0000] {processor.py:157} INFO - Started process (PID=3611) to work on /opt/airflow/dags/main_de_project_1_dag.py
[2023-12-11T00:00:31.169+0000] {processor.py:829} INFO - Processing file /opt/airflow/dags/main_de_project_1_dag.py for tasks to queue
[2023-12-11T00:00:31.173+0000] {logging_mixin.py:154} INFO - [2023-12-11T00:00:31.172+0000] {dagbag.py:536} INFO - Filling up the DagBag from /opt/airflow/dags/main_de_project_1_dag.py
[2023-12-11T00:00:31.182+0000] {logging_mixin.py:154} INFO - [2023-12-11T00:00:31.180+0000] {dagbag.py:346} ERROR - Failed to import: /opt/airflow/dags/main_de_project_1_dag.py
Traceback (most recent call last):
  File "/home/airflow/.local/lib/python3.8/site-packages/airflow/models/dagbag.py", line 342, in parse
    loader.exec_module(new_module)
  File "<frozen importlib._bootstrap_external>", line 843, in exec_module
  File "<frozen importlib._bootstrap>", line 219, in _call_with_frames_removed
  File "/opt/airflow/dags/main_de_project_1_dag.py", line 11, in <module>
    import create_tables
ModuleNotFoundError: No module named 'create_tables'
[2023-12-11T00:00:31.183+0000] {processor.py:841} WARNING - No viable dags retrieved from /opt/airflow/dags/main_de_project_1_dag.py
[2023-12-11T00:00:31.206+0000] {processor.py:179} INFO - Processing /opt/airflow/dags/main_de_project_1_dag.py took 0.044 seconds
[2023-12-11T00:01:01.432+0000] {processor.py:157} INFO - Started process (PID=3619) to work on /opt/airflow/dags/main_de_project_1_dag.py
[2023-12-11T00:01:01.433+0000] {processor.py:829} INFO - Processing file /opt/airflow/dags/main_de_project_1_dag.py for tasks to queue
[2023-12-11T00:01:01.437+0000] {logging_mixin.py:154} INFO - [2023-12-11T00:01:01.436+0000] {dagbag.py:536} INFO - Filling up the DagBag from /opt/airflow/dags/main_de_project_1_dag.py
[2023-12-11T00:01:01.447+0000] {logging_mixin.py:154} INFO - [2023-12-11T00:01:01.445+0000] {dagbag.py:346} ERROR - Failed to import: /opt/airflow/dags/main_de_project_1_dag.py
Traceback (most recent call last):
  File "/home/airflow/.local/lib/python3.8/site-packages/airflow/models/dagbag.py", line 342, in parse
    loader.exec_module(new_module)
  File "<frozen importlib._bootstrap_external>", line 843, in exec_module
  File "<frozen importlib._bootstrap>", line 219, in _call_with_frames_removed
  File "/opt/airflow/dags/main_de_project_1_dag.py", line 11, in <module>
    import create_tables
ModuleNotFoundError: No module named 'create_tables'
[2023-12-11T00:01:01.449+0000] {processor.py:841} WARNING - No viable dags retrieved from /opt/airflow/dags/main_de_project_1_dag.py
[2023-12-11T00:01:01.475+0000] {processor.py:179} INFO - Processing /opt/airflow/dags/main_de_project_1_dag.py took 0.048 seconds
[2023-12-11T00:01:31.687+0000] {processor.py:157} INFO - Started process (PID=3627) to work on /opt/airflow/dags/main_de_project_1_dag.py
[2023-12-11T00:01:31.688+0000] {processor.py:829} INFO - Processing file /opt/airflow/dags/main_de_project_1_dag.py for tasks to queue
[2023-12-11T00:01:31.691+0000] {logging_mixin.py:154} INFO - [2023-12-11T00:01:31.691+0000] {dagbag.py:536} INFO - Filling up the DagBag from /opt/airflow/dags/main_de_project_1_dag.py
[2023-12-11T00:01:31.701+0000] {logging_mixin.py:154} INFO - [2023-12-11T00:01:31.699+0000] {dagbag.py:346} ERROR - Failed to import: /opt/airflow/dags/main_de_project_1_dag.py
Traceback (most recent call last):
  File "/home/airflow/.local/lib/python3.8/site-packages/airflow/models/dagbag.py", line 342, in parse
    loader.exec_module(new_module)
  File "<frozen importlib._bootstrap_external>", line 843, in exec_module
  File "<frozen importlib._bootstrap>", line 219, in _call_with_frames_removed
  File "/opt/airflow/dags/main_de_project_1_dag.py", line 11, in <module>
    import create_tables
ModuleNotFoundError: No module named 'create_tables'
[2023-12-11T00:01:31.703+0000] {processor.py:841} WARNING - No viable dags retrieved from /opt/airflow/dags/main_de_project_1_dag.py
[2023-12-11T00:01:31.728+0000] {processor.py:179} INFO - Processing /opt/airflow/dags/main_de_project_1_dag.py took 0.046 seconds
[2023-12-11T00:02:01.905+0000] {processor.py:157} INFO - Started process (PID=3636) to work on /opt/airflow/dags/main_de_project_1_dag.py
[2023-12-11T00:02:01.907+0000] {processor.py:829} INFO - Processing file /opt/airflow/dags/main_de_project_1_dag.py for tasks to queue
[2023-12-11T00:02:01.911+0000] {logging_mixin.py:154} INFO - [2023-12-11T00:02:01.911+0000] {dagbag.py:536} INFO - Filling up the DagBag from /opt/airflow/dags/main_de_project_1_dag.py
[2023-12-11T00:02:01.923+0000] {logging_mixin.py:154} INFO - [2023-12-11T00:02:01.920+0000] {dagbag.py:346} ERROR - Failed to import: /opt/airflow/dags/main_de_project_1_dag.py
Traceback (most recent call last):
  File "/home/airflow/.local/lib/python3.8/site-packages/airflow/models/dagbag.py", line 342, in parse
    loader.exec_module(new_module)
  File "<frozen importlib._bootstrap_external>", line 843, in exec_module
  File "<frozen importlib._bootstrap>", line 219, in _call_with_frames_removed
  File "/opt/airflow/dags/main_de_project_1_dag.py", line 11, in <module>
    import create_tables
ModuleNotFoundError: No module named 'create_tables'
[2023-12-11T00:02:01.924+0000] {processor.py:841} WARNING - No viable dags retrieved from /opt/airflow/dags/main_de_project_1_dag.py
[2023-12-11T00:02:01.955+0000] {processor.py:179} INFO - Processing /opt/airflow/dags/main_de_project_1_dag.py took 0.056 seconds
[2023-12-11T00:02:32.107+0000] {processor.py:157} INFO - Started process (PID=3644) to work on /opt/airflow/dags/main_de_project_1_dag.py
[2023-12-11T00:02:32.152+0000] {processor.py:829} INFO - Processing file /opt/airflow/dags/main_de_project_1_dag.py for tasks to queue
[2023-12-11T00:02:32.164+0000] {logging_mixin.py:154} INFO - [2023-12-11T00:02:32.164+0000] {dagbag.py:536} INFO - Filling up the DagBag from /opt/airflow/dags/main_de_project_1_dag.py
[2023-12-11T00:02:32.174+0000] {logging_mixin.py:154} INFO - [2023-12-11T00:02:32.172+0000] {dagbag.py:346} ERROR - Failed to import: /opt/airflow/dags/main_de_project_1_dag.py
Traceback (most recent call last):
  File "/home/airflow/.local/lib/python3.8/site-packages/airflow/models/dagbag.py", line 342, in parse
    loader.exec_module(new_module)
  File "<frozen importlib._bootstrap_external>", line 843, in exec_module
  File "<frozen importlib._bootstrap>", line 219, in _call_with_frames_removed
  File "/opt/airflow/dags/main_de_project_1_dag.py", line 11, in <module>
    import create_tables
ModuleNotFoundError: No module named 'create_tables'
[2023-12-11T00:02:32.175+0000] {processor.py:841} WARNING - No viable dags retrieved from /opt/airflow/dags/main_de_project_1_dag.py
[2023-12-11T00:02:32.229+0000] {processor.py:179} INFO - Processing /opt/airflow/dags/main_de_project_1_dag.py took 0.126 seconds
[2023-12-11T00:03:02.434+0000] {processor.py:157} INFO - Started process (PID=3652) to work on /opt/airflow/dags/main_de_project_1_dag.py
[2023-12-11T00:03:02.435+0000] {processor.py:829} INFO - Processing file /opt/airflow/dags/main_de_project_1_dag.py for tasks to queue
[2023-12-11T00:03:02.439+0000] {logging_mixin.py:154} INFO - [2023-12-11T00:03:02.439+0000] {dagbag.py:536} INFO - Filling up the DagBag from /opt/airflow/dags/main_de_project_1_dag.py
[2023-12-11T00:03:02.452+0000] {logging_mixin.py:154} INFO - [2023-12-11T00:03:02.450+0000] {dagbag.py:346} ERROR - Failed to import: /opt/airflow/dags/main_de_project_1_dag.py
Traceback (most recent call last):
  File "/home/airflow/.local/lib/python3.8/site-packages/airflow/models/dagbag.py", line 342, in parse
    loader.exec_module(new_module)
  File "<frozen importlib._bootstrap_external>", line 843, in exec_module
  File "<frozen importlib._bootstrap>", line 219, in _call_with_frames_removed
  File "/opt/airflow/dags/main_de_project_1_dag.py", line 11, in <module>
    import create_tables
ModuleNotFoundError: No module named 'create_tables'
[2023-12-11T00:03:02.453+0000] {processor.py:841} WARNING - No viable dags retrieved from /opt/airflow/dags/main_de_project_1_dag.py
[2023-12-11T00:03:02.481+0000] {processor.py:179} INFO - Processing /opt/airflow/dags/main_de_project_1_dag.py took 0.050 seconds
[2023-12-11T00:03:32.672+0000] {processor.py:157} INFO - Started process (PID=3659) to work on /opt/airflow/dags/main_de_project_1_dag.py
[2023-12-11T00:03:32.674+0000] {processor.py:829} INFO - Processing file /opt/airflow/dags/main_de_project_1_dag.py for tasks to queue
[2023-12-11T00:03:32.678+0000] {logging_mixin.py:154} INFO - [2023-12-11T00:03:32.678+0000] {dagbag.py:536} INFO - Filling up the DagBag from /opt/airflow/dags/main_de_project_1_dag.py
[2023-12-11T00:03:32.688+0000] {logging_mixin.py:154} INFO - [2023-12-11T00:03:32.686+0000] {dagbag.py:346} ERROR - Failed to import: /opt/airflow/dags/main_de_project_1_dag.py
Traceback (most recent call last):
  File "/home/airflow/.local/lib/python3.8/site-packages/airflow/models/dagbag.py", line 342, in parse
    loader.exec_module(new_module)
  File "<frozen importlib._bootstrap_external>", line 843, in exec_module
  File "<frozen importlib._bootstrap>", line 219, in _call_with_frames_removed
  File "/opt/airflow/dags/main_de_project_1_dag.py", line 11, in <module>
    import create_tables
ModuleNotFoundError: No module named 'create_tables'
[2023-12-11T00:03:32.688+0000] {processor.py:841} WARNING - No viable dags retrieved from /opt/airflow/dags/main_de_project_1_dag.py
[2023-12-11T00:03:32.717+0000] {processor.py:179} INFO - Processing /opt/airflow/dags/main_de_project_1_dag.py took 0.048 seconds
[2023-12-11T00:04:02.967+0000] {processor.py:157} INFO - Started process (PID=3667) to work on /opt/airflow/dags/main_de_project_1_dag.py
[2023-12-11T00:04:02.980+0000] {processor.py:829} INFO - Processing file /opt/airflow/dags/main_de_project_1_dag.py for tasks to queue
[2023-12-11T00:04:02.998+0000] {logging_mixin.py:154} INFO - [2023-12-11T00:04:02.994+0000] {dagbag.py:536} INFO - Filling up the DagBag from /opt/airflow/dags/main_de_project_1_dag.py
[2023-12-11T00:04:03.042+0000] {logging_mixin.py:154} INFO - [2023-12-11T00:04:03.040+0000] {dagbag.py:346} ERROR - Failed to import: /opt/airflow/dags/main_de_project_1_dag.py
Traceback (most recent call last):
  File "/home/airflow/.local/lib/python3.8/site-packages/airflow/models/dagbag.py", line 342, in parse
    loader.exec_module(new_module)
  File "<frozen importlib._bootstrap_external>", line 843, in exec_module
  File "<frozen importlib._bootstrap>", line 219, in _call_with_frames_removed
  File "/opt/airflow/dags/main_de_project_1_dag.py", line 11, in <module>
    import create_tables
ModuleNotFoundError: No module named 'create_tables'
[2023-12-11T00:04:03.045+0000] {processor.py:841} WARNING - No viable dags retrieved from /opt/airflow/dags/main_de_project_1_dag.py
[2023-12-11T00:04:03.091+0000] {processor.py:179} INFO - Processing /opt/airflow/dags/main_de_project_1_dag.py took 0.131 seconds
[2023-12-11T00:04:33.316+0000] {processor.py:157} INFO - Started process (PID=3675) to work on /opt/airflow/dags/main_de_project_1_dag.py
[2023-12-11T00:04:33.318+0000] {processor.py:829} INFO - Processing file /opt/airflow/dags/main_de_project_1_dag.py for tasks to queue
[2023-12-11T00:04:33.321+0000] {logging_mixin.py:154} INFO - [2023-12-11T00:04:33.321+0000] {dagbag.py:536} INFO - Filling up the DagBag from /opt/airflow/dags/main_de_project_1_dag.py
[2023-12-11T00:04:33.332+0000] {logging_mixin.py:154} INFO - [2023-12-11T00:04:33.330+0000] {dagbag.py:346} ERROR - Failed to import: /opt/airflow/dags/main_de_project_1_dag.py
Traceback (most recent call last):
  File "/home/airflow/.local/lib/python3.8/site-packages/airflow/models/dagbag.py", line 342, in parse
    loader.exec_module(new_module)
  File "<frozen importlib._bootstrap_external>", line 843, in exec_module
  File "<frozen importlib._bootstrap>", line 219, in _call_with_frames_removed
  File "/opt/airflow/dags/main_de_project_1_dag.py", line 11, in <module>
    import create_tables
ModuleNotFoundError: No module named 'create_tables'
[2023-12-11T00:04:33.333+0000] {processor.py:841} WARNING - No viable dags retrieved from /opt/airflow/dags/main_de_project_1_dag.py
[2023-12-11T00:04:33.355+0000] {processor.py:179} INFO - Processing /opt/airflow/dags/main_de_project_1_dag.py took 0.043 seconds
[2023-12-11T00:05:03.551+0000] {processor.py:157} INFO - Started process (PID=3683) to work on /opt/airflow/dags/main_de_project_1_dag.py
[2023-12-11T00:05:03.553+0000] {processor.py:829} INFO - Processing file /opt/airflow/dags/main_de_project_1_dag.py for tasks to queue
[2023-12-11T00:05:03.559+0000] {logging_mixin.py:154} INFO - [2023-12-11T00:05:03.558+0000] {dagbag.py:536} INFO - Filling up the DagBag from /opt/airflow/dags/main_de_project_1_dag.py
[2023-12-11T00:05:03.572+0000] {logging_mixin.py:154} INFO - [2023-12-11T00:05:03.570+0000] {dagbag.py:346} ERROR - Failed to import: /opt/airflow/dags/main_de_project_1_dag.py
Traceback (most recent call last):
  File "/home/airflow/.local/lib/python3.8/site-packages/airflow/models/dagbag.py", line 342, in parse
    loader.exec_module(new_module)
  File "<frozen importlib._bootstrap_external>", line 843, in exec_module
  File "<frozen importlib._bootstrap>", line 219, in _call_with_frames_removed
  File "/opt/airflow/dags/main_de_project_1_dag.py", line 11, in <module>
    import create_tables
ModuleNotFoundError: No module named 'create_tables'
[2023-12-11T00:05:03.573+0000] {processor.py:841} WARNING - No viable dags retrieved from /opt/airflow/dags/main_de_project_1_dag.py
[2023-12-11T00:05:03.602+0000] {processor.py:179} INFO - Processing /opt/airflow/dags/main_de_project_1_dag.py took 0.057 seconds
[2023-12-11T00:05:34.085+0000] {processor.py:157} INFO - Started process (PID=3690) to work on /opt/airflow/dags/main_de_project_1_dag.py
[2023-12-11T00:05:34.105+0000] {processor.py:829} INFO - Processing file /opt/airflow/dags/main_de_project_1_dag.py for tasks to queue
[2023-12-11T00:05:34.130+0000] {logging_mixin.py:154} INFO - [2023-12-11T00:05:34.130+0000] {dagbag.py:536} INFO - Filling up the DagBag from /opt/airflow/dags/main_de_project_1_dag.py
[2023-12-11T00:05:34.165+0000] {logging_mixin.py:154} INFO - [2023-12-11T00:05:34.162+0000] {dagbag.py:346} ERROR - Failed to import: /opt/airflow/dags/main_de_project_1_dag.py
Traceback (most recent call last):
  File "/home/airflow/.local/lib/python3.8/site-packages/airflow/models/dagbag.py", line 342, in parse
    loader.exec_module(new_module)
  File "<frozen importlib._bootstrap_external>", line 843, in exec_module
  File "<frozen importlib._bootstrap>", line 219, in _call_with_frames_removed
  File "/opt/airflow/dags/main_de_project_1_dag.py", line 11, in <module>
    import create_tables
ModuleNotFoundError: No module named 'create_tables'
[2023-12-11T00:05:34.171+0000] {processor.py:841} WARNING - No viable dags retrieved from /opt/airflow/dags/main_de_project_1_dag.py
[2023-12-11T00:05:34.202+0000] {processor.py:179} INFO - Processing /opt/airflow/dags/main_de_project_1_dag.py took 0.142 seconds
[2023-12-11T00:06:04.321+0000] {processor.py:157} INFO - Started process (PID=3698) to work on /opt/airflow/dags/main_de_project_1_dag.py
[2023-12-11T00:06:04.322+0000] {processor.py:829} INFO - Processing file /opt/airflow/dags/main_de_project_1_dag.py for tasks to queue
[2023-12-11T00:06:04.325+0000] {logging_mixin.py:154} INFO - [2023-12-11T00:06:04.325+0000] {dagbag.py:536} INFO - Filling up the DagBag from /opt/airflow/dags/main_de_project_1_dag.py
[2023-12-11T00:06:04.334+0000] {logging_mixin.py:154} INFO - [2023-12-11T00:06:04.332+0000] {dagbag.py:346} ERROR - Failed to import: /opt/airflow/dags/main_de_project_1_dag.py
Traceback (most recent call last):
  File "/home/airflow/.local/lib/python3.8/site-packages/airflow/models/dagbag.py", line 342, in parse
    loader.exec_module(new_module)
  File "<frozen importlib._bootstrap_external>", line 843, in exec_module
  File "<frozen importlib._bootstrap>", line 219, in _call_with_frames_removed
  File "/opt/airflow/dags/main_de_project_1_dag.py", line 11, in <module>
    import create_tables
ModuleNotFoundError: No module named 'create_tables'
[2023-12-11T00:06:04.335+0000] {processor.py:841} WARNING - No viable dags retrieved from /opt/airflow/dags/main_de_project_1_dag.py
[2023-12-11T00:06:04.366+0000] {processor.py:179} INFO - Processing /opt/airflow/dags/main_de_project_1_dag.py took 0.054 seconds
[2023-12-11T00:06:34.558+0000] {processor.py:157} INFO - Started process (PID=3706) to work on /opt/airflow/dags/main_de_project_1_dag.py
[2023-12-11T00:06:34.560+0000] {processor.py:829} INFO - Processing file /opt/airflow/dags/main_de_project_1_dag.py for tasks to queue
[2023-12-11T00:06:34.563+0000] {logging_mixin.py:154} INFO - [2023-12-11T00:06:34.563+0000] {dagbag.py:536} INFO - Filling up the DagBag from /opt/airflow/dags/main_de_project_1_dag.py
[2023-12-11T00:06:34.573+0000] {logging_mixin.py:154} INFO - [2023-12-11T00:06:34.571+0000] {dagbag.py:346} ERROR - Failed to import: /opt/airflow/dags/main_de_project_1_dag.py
Traceback (most recent call last):
  File "/home/airflow/.local/lib/python3.8/site-packages/airflow/models/dagbag.py", line 342, in parse
    loader.exec_module(new_module)
  File "<frozen importlib._bootstrap_external>", line 843, in exec_module
  File "<frozen importlib._bootstrap>", line 219, in _call_with_frames_removed
  File "/opt/airflow/dags/main_de_project_1_dag.py", line 11, in <module>
    import create_tables
ModuleNotFoundError: No module named 'create_tables'
[2023-12-11T00:06:34.574+0000] {processor.py:841} WARNING - No viable dags retrieved from /opt/airflow/dags/main_de_project_1_dag.py
[2023-12-11T00:06:34.600+0000] {processor.py:179} INFO - Processing /opt/airflow/dags/main_de_project_1_dag.py took 0.046 seconds
[2023-12-11T00:07:04.782+0000] {processor.py:157} INFO - Started process (PID=3714) to work on /opt/airflow/dags/main_de_project_1_dag.py
[2023-12-11T00:07:04.784+0000] {processor.py:829} INFO - Processing file /opt/airflow/dags/main_de_project_1_dag.py for tasks to queue
[2023-12-11T00:07:04.789+0000] {logging_mixin.py:154} INFO - [2023-12-11T00:07:04.788+0000] {dagbag.py:536} INFO - Filling up the DagBag from /opt/airflow/dags/main_de_project_1_dag.py
[2023-12-11T00:07:04.806+0000] {logging_mixin.py:154} INFO - [2023-12-11T00:07:04.803+0000] {dagbag.py:346} ERROR - Failed to import: /opt/airflow/dags/main_de_project_1_dag.py
Traceback (most recent call last):
  File "/home/airflow/.local/lib/python3.8/site-packages/airflow/models/dagbag.py", line 342, in parse
    loader.exec_module(new_module)
  File "<frozen importlib._bootstrap_external>", line 843, in exec_module
  File "<frozen importlib._bootstrap>", line 219, in _call_with_frames_removed
  File "/opt/airflow/dags/main_de_project_1_dag.py", line 11, in <module>
    import create_tables
ModuleNotFoundError: No module named 'create_tables'
[2023-12-11T00:07:04.808+0000] {processor.py:841} WARNING - No viable dags retrieved from /opt/airflow/dags/main_de_project_1_dag.py
[2023-12-11T00:07:04.836+0000] {processor.py:179} INFO - Processing /opt/airflow/dags/main_de_project_1_dag.py took 0.064 seconds
[2023-12-11T00:07:35.019+0000] {processor.py:157} INFO - Started process (PID=3722) to work on /opt/airflow/dags/main_de_project_1_dag.py
[2023-12-11T00:07:35.021+0000] {processor.py:829} INFO - Processing file /opt/airflow/dags/main_de_project_1_dag.py for tasks to queue
[2023-12-11T00:07:35.025+0000] {logging_mixin.py:154} INFO - [2023-12-11T00:07:35.025+0000] {dagbag.py:536} INFO - Filling up the DagBag from /opt/airflow/dags/main_de_project_1_dag.py
[2023-12-11T00:07:35.034+0000] {logging_mixin.py:154} INFO - [2023-12-11T00:07:35.032+0000] {dagbag.py:346} ERROR - Failed to import: /opt/airflow/dags/main_de_project_1_dag.py
Traceback (most recent call last):
  File "/home/airflow/.local/lib/python3.8/site-packages/airflow/models/dagbag.py", line 342, in parse
    loader.exec_module(new_module)
  File "<frozen importlib._bootstrap_external>", line 843, in exec_module
  File "<frozen importlib._bootstrap>", line 219, in _call_with_frames_removed
  File "/opt/airflow/dags/main_de_project_1_dag.py", line 11, in <module>
    import create_tables
ModuleNotFoundError: No module named 'create_tables'
[2023-12-11T00:07:35.035+0000] {processor.py:841} WARNING - No viable dags retrieved from /opt/airflow/dags/main_de_project_1_dag.py
[2023-12-11T00:07:35.063+0000] {processor.py:179} INFO - Processing /opt/airflow/dags/main_de_project_1_dag.py took 0.048 seconds
[2023-12-11T00:08:05.245+0000] {processor.py:157} INFO - Started process (PID=3730) to work on /opt/airflow/dags/main_de_project_1_dag.py
[2023-12-11T00:08:05.253+0000] {processor.py:829} INFO - Processing file /opt/airflow/dags/main_de_project_1_dag.py for tasks to queue
[2023-12-11T00:08:05.261+0000] {logging_mixin.py:154} INFO - [2023-12-11T00:08:05.261+0000] {dagbag.py:536} INFO - Filling up the DagBag from /opt/airflow/dags/main_de_project_1_dag.py
[2023-12-11T00:08:05.281+0000] {logging_mixin.py:154} INFO - [2023-12-11T00:08:05.279+0000] {dagbag.py:346} ERROR - Failed to import: /opt/airflow/dags/main_de_project_1_dag.py
Traceback (most recent call last):
  File "/home/airflow/.local/lib/python3.8/site-packages/airflow/models/dagbag.py", line 342, in parse
    loader.exec_module(new_module)
  File "<frozen importlib._bootstrap_external>", line 843, in exec_module
  File "<frozen importlib._bootstrap>", line 219, in _call_with_frames_removed
  File "/opt/airflow/dags/main_de_project_1_dag.py", line 11, in <module>
    import create_tables
ModuleNotFoundError: No module named 'create_tables'
[2023-12-11T00:08:05.282+0000] {processor.py:841} WARNING - No viable dags retrieved from /opt/airflow/dags/main_de_project_1_dag.py
[2023-12-11T00:08:05.337+0000] {processor.py:179} INFO - Processing /opt/airflow/dags/main_de_project_1_dag.py took 0.098 seconds
[2023-12-11T00:08:35.564+0000] {processor.py:157} INFO - Started process (PID=3738) to work on /opt/airflow/dags/main_de_project_1_dag.py
[2023-12-11T00:08:35.566+0000] {processor.py:829} INFO - Processing file /opt/airflow/dags/main_de_project_1_dag.py for tasks to queue
[2023-12-11T00:08:35.570+0000] {logging_mixin.py:154} INFO - [2023-12-11T00:08:35.569+0000] {dagbag.py:536} INFO - Filling up the DagBag from /opt/airflow/dags/main_de_project_1_dag.py
[2023-12-11T00:08:35.580+0000] {logging_mixin.py:154} INFO - [2023-12-11T00:08:35.578+0000] {dagbag.py:346} ERROR - Failed to import: /opt/airflow/dags/main_de_project_1_dag.py
Traceback (most recent call last):
  File "/home/airflow/.local/lib/python3.8/site-packages/airflow/models/dagbag.py", line 342, in parse
    loader.exec_module(new_module)
  File "<frozen importlib._bootstrap_external>", line 843, in exec_module
  File "<frozen importlib._bootstrap>", line 219, in _call_with_frames_removed
  File "/opt/airflow/dags/main_de_project_1_dag.py", line 11, in <module>
    import create_tables
ModuleNotFoundError: No module named 'create_tables'
[2023-12-11T00:08:35.581+0000] {processor.py:841} WARNING - No viable dags retrieved from /opt/airflow/dags/main_de_project_1_dag.py
[2023-12-11T00:08:35.607+0000] {processor.py:179} INFO - Processing /opt/airflow/dags/main_de_project_1_dag.py took 0.046 seconds
[2023-12-11T00:09:05.866+0000] {processor.py:157} INFO - Started process (PID=3746) to work on /opt/airflow/dags/main_de_project_1_dag.py
[2023-12-11T00:09:05.918+0000] {processor.py:829} INFO - Processing file /opt/airflow/dags/main_de_project_1_dag.py for tasks to queue
[2023-12-11T00:09:05.924+0000] {logging_mixin.py:154} INFO - [2023-12-11T00:09:05.923+0000] {dagbag.py:536} INFO - Filling up the DagBag from /opt/airflow/dags/main_de_project_1_dag.py
[2023-12-11T00:09:05.934+0000] {logging_mixin.py:154} INFO - [2023-12-11T00:09:05.932+0000] {dagbag.py:346} ERROR - Failed to import: /opt/airflow/dags/main_de_project_1_dag.py
Traceback (most recent call last):
  File "/home/airflow/.local/lib/python3.8/site-packages/airflow/models/dagbag.py", line 342, in parse
    loader.exec_module(new_module)
  File "<frozen importlib._bootstrap_external>", line 843, in exec_module
  File "<frozen importlib._bootstrap>", line 219, in _call_with_frames_removed
  File "/opt/airflow/dags/main_de_project_1_dag.py", line 11, in <module>
    import create_tables
ModuleNotFoundError: No module named 'create_tables'
[2023-12-11T00:09:05.935+0000] {processor.py:841} WARNING - No viable dags retrieved from /opt/airflow/dags/main_de_project_1_dag.py
[2023-12-11T00:09:05.966+0000] {processor.py:179} INFO - Processing /opt/airflow/dags/main_de_project_1_dag.py took 0.104 seconds
[2023-12-11T00:09:36.115+0000] {processor.py:157} INFO - Started process (PID=3754) to work on /opt/airflow/dags/main_de_project_1_dag.py
[2023-12-11T00:09:36.117+0000] {processor.py:829} INFO - Processing file /opt/airflow/dags/main_de_project_1_dag.py for tasks to queue
[2023-12-11T00:09:36.121+0000] {logging_mixin.py:154} INFO - [2023-12-11T00:09:36.121+0000] {dagbag.py:536} INFO - Filling up the DagBag from /opt/airflow/dags/main_de_project_1_dag.py
[2023-12-11T00:09:36.130+0000] {logging_mixin.py:154} INFO - [2023-12-11T00:09:36.129+0000] {dagbag.py:346} ERROR - Failed to import: /opt/airflow/dags/main_de_project_1_dag.py
Traceback (most recent call last):
  File "/home/airflow/.local/lib/python3.8/site-packages/airflow/models/dagbag.py", line 342, in parse
    loader.exec_module(new_module)
  File "<frozen importlib._bootstrap_external>", line 843, in exec_module
  File "<frozen importlib._bootstrap>", line 219, in _call_with_frames_removed
  File "/opt/airflow/dags/main_de_project_1_dag.py", line 11, in <module>
    import create_tables
ModuleNotFoundError: No module named 'create_tables'
[2023-12-11T00:09:36.131+0000] {processor.py:841} WARNING - No viable dags retrieved from /opt/airflow/dags/main_de_project_1_dag.py
[2023-12-11T00:09:36.157+0000] {processor.py:179} INFO - Processing /opt/airflow/dags/main_de_project_1_dag.py took 0.045 seconds
[2023-12-11T00:10:06.348+0000] {processor.py:157} INFO - Started process (PID=3762) to work on /opt/airflow/dags/main_de_project_1_dag.py
[2023-12-11T00:10:06.350+0000] {processor.py:829} INFO - Processing file /opt/airflow/dags/main_de_project_1_dag.py for tasks to queue
[2023-12-11T00:10:06.355+0000] {logging_mixin.py:154} INFO - [2023-12-11T00:10:06.355+0000] {dagbag.py:536} INFO - Filling up the DagBag from /opt/airflow/dags/main_de_project_1_dag.py
[2023-12-11T00:10:06.369+0000] {logging_mixin.py:154} INFO - [2023-12-11T00:10:06.365+0000] {dagbag.py:346} ERROR - Failed to import: /opt/airflow/dags/main_de_project_1_dag.py
Traceback (most recent call last):
  File "/home/airflow/.local/lib/python3.8/site-packages/airflow/models/dagbag.py", line 342, in parse
    loader.exec_module(new_module)
  File "<frozen importlib._bootstrap_external>", line 843, in exec_module
  File "<frozen importlib._bootstrap>", line 219, in _call_with_frames_removed
  File "/opt/airflow/dags/main_de_project_1_dag.py", line 11, in <module>
    import create_tables
ModuleNotFoundError: No module named 'create_tables'
[2023-12-11T00:10:06.370+0000] {processor.py:841} WARNING - No viable dags retrieved from /opt/airflow/dags/main_de_project_1_dag.py
[2023-12-11T00:10:06.400+0000] {processor.py:179} INFO - Processing /opt/airflow/dags/main_de_project_1_dag.py took 0.058 seconds
[2023-12-11T00:10:36.573+0000] {processor.py:157} INFO - Started process (PID=3770) to work on /opt/airflow/dags/main_de_project_1_dag.py
[2023-12-11T00:10:36.575+0000] {processor.py:829} INFO - Processing file /opt/airflow/dags/main_de_project_1_dag.py for tasks to queue
[2023-12-11T00:10:36.579+0000] {logging_mixin.py:154} INFO - [2023-12-11T00:10:36.578+0000] {dagbag.py:536} INFO - Filling up the DagBag from /opt/airflow/dags/main_de_project_1_dag.py
[2023-12-11T00:10:36.588+0000] {logging_mixin.py:154} INFO - [2023-12-11T00:10:36.586+0000] {dagbag.py:346} ERROR - Failed to import: /opt/airflow/dags/main_de_project_1_dag.py
Traceback (most recent call last):
  File "/home/airflow/.local/lib/python3.8/site-packages/airflow/models/dagbag.py", line 342, in parse
    loader.exec_module(new_module)
  File "<frozen importlib._bootstrap_external>", line 843, in exec_module
  File "<frozen importlib._bootstrap>", line 219, in _call_with_frames_removed
  File "/opt/airflow/dags/main_de_project_1_dag.py", line 11, in <module>
    import create_tables
ModuleNotFoundError: No module named 'create_tables'
[2023-12-11T00:10:36.589+0000] {processor.py:841} WARNING - No viable dags retrieved from /opt/airflow/dags/main_de_project_1_dag.py
[2023-12-11T00:10:36.614+0000] {processor.py:179} INFO - Processing /opt/airflow/dags/main_de_project_1_dag.py took 0.045 seconds
[2023-12-11T00:11:06.788+0000] {processor.py:157} INFO - Started process (PID=3778) to work on /opt/airflow/dags/main_de_project_1_dag.py
[2023-12-11T00:11:06.790+0000] {processor.py:829} INFO - Processing file /opt/airflow/dags/main_de_project_1_dag.py for tasks to queue
[2023-12-11T00:11:06.795+0000] {logging_mixin.py:154} INFO - [2023-12-11T00:11:06.794+0000] {dagbag.py:536} INFO - Filling up the DagBag from /opt/airflow/dags/main_de_project_1_dag.py
[2023-12-11T00:11:06.861+0000] {logging_mixin.py:154} INFO - [2023-12-11T00:11:06.855+0000] {dagbag.py:346} ERROR - Failed to import: /opt/airflow/dags/main_de_project_1_dag.py
Traceback (most recent call last):
  File "/home/airflow/.local/lib/python3.8/site-packages/airflow/models/dagbag.py", line 342, in parse
    loader.exec_module(new_module)
  File "<frozen importlib._bootstrap_external>", line 843, in exec_module
  File "<frozen importlib._bootstrap>", line 219, in _call_with_frames_removed
  File "/opt/airflow/dags/main_de_project_1_dag.py", line 11, in <module>
    import create_tables
ModuleNotFoundError: No module named 'create_tables'
[2023-12-11T00:11:06.862+0000] {processor.py:841} WARNING - No viable dags retrieved from /opt/airflow/dags/main_de_project_1_dag.py
[2023-12-11T00:11:06.897+0000] {processor.py:179} INFO - Processing /opt/airflow/dags/main_de_project_1_dag.py took 0.115 seconds
[2023-12-11T00:11:37.022+0000] {processor.py:157} INFO - Started process (PID=3785) to work on /opt/airflow/dags/main_de_project_1_dag.py
[2023-12-11T00:11:37.023+0000] {processor.py:829} INFO - Processing file /opt/airflow/dags/main_de_project_1_dag.py for tasks to queue
[2023-12-11T00:11:37.028+0000] {logging_mixin.py:154} INFO - [2023-12-11T00:11:37.027+0000] {dagbag.py:536} INFO - Filling up the DagBag from /opt/airflow/dags/main_de_project_1_dag.py
[2023-12-11T00:11:37.037+0000] {logging_mixin.py:154} INFO - [2023-12-11T00:11:37.035+0000] {dagbag.py:346} ERROR - Failed to import: /opt/airflow/dags/main_de_project_1_dag.py
Traceback (most recent call last):
  File "/home/airflow/.local/lib/python3.8/site-packages/airflow/models/dagbag.py", line 342, in parse
    loader.exec_module(new_module)
  File "<frozen importlib._bootstrap_external>", line 843, in exec_module
  File "<frozen importlib._bootstrap>", line 219, in _call_with_frames_removed
  File "/opt/airflow/dags/main_de_project_1_dag.py", line 11, in <module>
    import create_tables
ModuleNotFoundError: No module named 'create_tables'
[2023-12-11T00:11:37.038+0000] {processor.py:841} WARNING - No viable dags retrieved from /opt/airflow/dags/main_de_project_1_dag.py
[2023-12-11T00:11:37.067+0000] {processor.py:179} INFO - Processing /opt/airflow/dags/main_de_project_1_dag.py took 0.051 seconds
[2023-12-11T00:12:07.276+0000] {processor.py:157} INFO - Started process (PID=3793) to work on /opt/airflow/dags/main_de_project_1_dag.py
[2023-12-11T00:12:07.278+0000] {processor.py:829} INFO - Processing file /opt/airflow/dags/main_de_project_1_dag.py for tasks to queue
[2023-12-11T00:12:07.282+0000] {logging_mixin.py:154} INFO - [2023-12-11T00:12:07.282+0000] {dagbag.py:536} INFO - Filling up the DagBag from /opt/airflow/dags/main_de_project_1_dag.py
[2023-12-11T00:12:07.293+0000] {logging_mixin.py:154} INFO - [2023-12-11T00:12:07.291+0000] {dagbag.py:346} ERROR - Failed to import: /opt/airflow/dags/main_de_project_1_dag.py
Traceback (most recent call last):
  File "/home/airflow/.local/lib/python3.8/site-packages/airflow/models/dagbag.py", line 342, in parse
    loader.exec_module(new_module)
  File "<frozen importlib._bootstrap_external>", line 843, in exec_module
  File "<frozen importlib._bootstrap>", line 219, in _call_with_frames_removed
  File "/opt/airflow/dags/main_de_project_1_dag.py", line 11, in <module>
    import create_tables
ModuleNotFoundError: No module named 'create_tables'
[2023-12-11T00:12:07.294+0000] {processor.py:841} WARNING - No viable dags retrieved from /opt/airflow/dags/main_de_project_1_dag.py
[2023-12-11T00:12:07.319+0000] {processor.py:179} INFO - Processing /opt/airflow/dags/main_de_project_1_dag.py took 0.047 seconds
[2023-12-11T00:12:37.514+0000] {processor.py:157} INFO - Started process (PID=3800) to work on /opt/airflow/dags/main_de_project_1_dag.py
[2023-12-11T00:12:37.515+0000] {processor.py:829} INFO - Processing file /opt/airflow/dags/main_de_project_1_dag.py for tasks to queue
[2023-12-11T00:12:37.518+0000] {logging_mixin.py:154} INFO - [2023-12-11T00:12:37.518+0000] {dagbag.py:536} INFO - Filling up the DagBag from /opt/airflow/dags/main_de_project_1_dag.py
[2023-12-11T00:12:37.528+0000] {logging_mixin.py:154} INFO - [2023-12-11T00:12:37.525+0000] {dagbag.py:346} ERROR - Failed to import: /opt/airflow/dags/main_de_project_1_dag.py
Traceback (most recent call last):
  File "/home/airflow/.local/lib/python3.8/site-packages/airflow/models/dagbag.py", line 342, in parse
    loader.exec_module(new_module)
  File "<frozen importlib._bootstrap_external>", line 843, in exec_module
  File "<frozen importlib._bootstrap>", line 219, in _call_with_frames_removed
  File "/opt/airflow/dags/main_de_project_1_dag.py", line 11, in <module>
    import create_tables
ModuleNotFoundError: No module named 'create_tables'
[2023-12-11T00:12:37.529+0000] {processor.py:841} WARNING - No viable dags retrieved from /opt/airflow/dags/main_de_project_1_dag.py
[2023-12-11T00:12:37.555+0000] {processor.py:179} INFO - Processing /opt/airflow/dags/main_de_project_1_dag.py took 0.045 seconds
[2023-12-11T00:13:07.702+0000] {processor.py:157} INFO - Started process (PID=3808) to work on /opt/airflow/dags/main_de_project_1_dag.py
[2023-12-11T00:13:07.704+0000] {processor.py:829} INFO - Processing file /opt/airflow/dags/main_de_project_1_dag.py for tasks to queue
[2023-12-11T00:13:07.708+0000] {logging_mixin.py:154} INFO - [2023-12-11T00:13:07.708+0000] {dagbag.py:536} INFO - Filling up the DagBag from /opt/airflow/dags/main_de_project_1_dag.py
[2023-12-11T00:13:07.729+0000] {logging_mixin.py:154} INFO - [2023-12-11T00:13:07.726+0000] {dagbag.py:346} ERROR - Failed to import: /opt/airflow/dags/main_de_project_1_dag.py
Traceback (most recent call last):
  File "/home/airflow/.local/lib/python3.8/site-packages/airflow/models/dagbag.py", line 342, in parse
    loader.exec_module(new_module)
  File "<frozen importlib._bootstrap_external>", line 843, in exec_module
  File "<frozen importlib._bootstrap>", line 219, in _call_with_frames_removed
  File "/opt/airflow/dags/main_de_project_1_dag.py", line 11, in <module>
    import create_tables
ModuleNotFoundError: No module named 'create_tables'
[2023-12-11T00:13:07.731+0000] {processor.py:841} WARNING - No viable dags retrieved from /opt/airflow/dags/main_de_project_1_dag.py
[2023-12-11T00:13:07.761+0000] {processor.py:179} INFO - Processing /opt/airflow/dags/main_de_project_1_dag.py took 0.067 seconds
[2023-12-11T00:13:38.053+0000] {processor.py:157} INFO - Started process (PID=3816) to work on /opt/airflow/dags/main_de_project_1_dag.py
[2023-12-11T00:13:38.054+0000] {processor.py:829} INFO - Processing file /opt/airflow/dags/main_de_project_1_dag.py for tasks to queue
[2023-12-11T00:13:38.058+0000] {logging_mixin.py:154} INFO - [2023-12-11T00:13:38.058+0000] {dagbag.py:536} INFO - Filling up the DagBag from /opt/airflow/dags/main_de_project_1_dag.py
[2023-12-11T00:13:38.068+0000] {logging_mixin.py:154} INFO - [2023-12-11T00:13:38.066+0000] {dagbag.py:346} ERROR - Failed to import: /opt/airflow/dags/main_de_project_1_dag.py
Traceback (most recent call last):
  File "/home/airflow/.local/lib/python3.8/site-packages/airflow/models/dagbag.py", line 342, in parse
    loader.exec_module(new_module)
  File "<frozen importlib._bootstrap_external>", line 843, in exec_module
  File "<frozen importlib._bootstrap>", line 219, in _call_with_frames_removed
  File "/opt/airflow/dags/main_de_project_1_dag.py", line 11, in <module>
    import create_tables
ModuleNotFoundError: No module named 'create_tables'
[2023-12-11T00:13:38.069+0000] {processor.py:841} WARNING - No viable dags retrieved from /opt/airflow/dags/main_de_project_1_dag.py
[2023-12-11T00:13:38.099+0000] {processor.py:179} INFO - Processing /opt/airflow/dags/main_de_project_1_dag.py took 0.051 seconds
[2023-12-11T00:14:08.307+0000] {processor.py:157} INFO - Started process (PID=3824) to work on /opt/airflow/dags/main_de_project_1_dag.py
[2023-12-11T00:14:08.309+0000] {processor.py:829} INFO - Processing file /opt/airflow/dags/main_de_project_1_dag.py for tasks to queue
[2023-12-11T00:14:08.312+0000] {logging_mixin.py:154} INFO - [2023-12-11T00:14:08.312+0000] {dagbag.py:536} INFO - Filling up the DagBag from /opt/airflow/dags/main_de_project_1_dag.py
[2023-12-11T00:14:08.321+0000] {logging_mixin.py:154} INFO - [2023-12-11T00:14:08.319+0000] {dagbag.py:346} ERROR - Failed to import: /opt/airflow/dags/main_de_project_1_dag.py
Traceback (most recent call last):
  File "/home/airflow/.local/lib/python3.8/site-packages/airflow/models/dagbag.py", line 342, in parse
    loader.exec_module(new_module)
  File "<frozen importlib._bootstrap_external>", line 843, in exec_module
  File "<frozen importlib._bootstrap>", line 219, in _call_with_frames_removed
  File "/opt/airflow/dags/main_de_project_1_dag.py", line 11, in <module>
    import create_tables
ModuleNotFoundError: No module named 'create_tables'
[2023-12-11T00:14:08.322+0000] {processor.py:841} WARNING - No viable dags retrieved from /opt/airflow/dags/main_de_project_1_dag.py
[2023-12-11T00:14:08.345+0000] {processor.py:179} INFO - Processing /opt/airflow/dags/main_de_project_1_dag.py took 0.043 seconds
[2023-12-11T00:14:38.524+0000] {processor.py:157} INFO - Started process (PID=3832) to work on /opt/airflow/dags/main_de_project_1_dag.py
[2023-12-11T00:14:38.525+0000] {processor.py:829} INFO - Processing file /opt/airflow/dags/main_de_project_1_dag.py for tasks to queue
[2023-12-11T00:14:38.528+0000] {logging_mixin.py:154} INFO - [2023-12-11T00:14:38.528+0000] {dagbag.py:536} INFO - Filling up the DagBag from /opt/airflow/dags/main_de_project_1_dag.py
[2023-12-11T00:14:38.537+0000] {logging_mixin.py:154} INFO - [2023-12-11T00:14:38.535+0000] {dagbag.py:346} ERROR - Failed to import: /opt/airflow/dags/main_de_project_1_dag.py
Traceback (most recent call last):
  File "/home/airflow/.local/lib/python3.8/site-packages/airflow/models/dagbag.py", line 342, in parse
    loader.exec_module(new_module)
  File "<frozen importlib._bootstrap_external>", line 843, in exec_module
  File "<frozen importlib._bootstrap>", line 219, in _call_with_frames_removed
  File "/opt/airflow/dags/main_de_project_1_dag.py", line 11, in <module>
    import create_tables
ModuleNotFoundError: No module named 'create_tables'
[2023-12-11T00:14:38.538+0000] {processor.py:841} WARNING - No viable dags retrieved from /opt/airflow/dags/main_de_project_1_dag.py
[2023-12-11T00:14:38.568+0000] {processor.py:179} INFO - Processing /opt/airflow/dags/main_de_project_1_dag.py took 0.049 seconds
[2023-12-11T00:15:08.828+0000] {processor.py:157} INFO - Started process (PID=3840) to work on /opt/airflow/dags/main_de_project_1_dag.py
[2023-12-11T00:15:08.832+0000] {processor.py:829} INFO - Processing file /opt/airflow/dags/main_de_project_1_dag.py for tasks to queue
[2023-12-11T00:15:08.837+0000] {logging_mixin.py:154} INFO - [2023-12-11T00:15:08.836+0000] {dagbag.py:536} INFO - Filling up the DagBag from /opt/airflow/dags/main_de_project_1_dag.py
[2023-12-11T00:15:08.851+0000] {logging_mixin.py:154} INFO - [2023-12-11T00:15:08.847+0000] {dagbag.py:346} ERROR - Failed to import: /opt/airflow/dags/main_de_project_1_dag.py
Traceback (most recent call last):
  File "/home/airflow/.local/lib/python3.8/site-packages/airflow/models/dagbag.py", line 342, in parse
    loader.exec_module(new_module)
  File "<frozen importlib._bootstrap_external>", line 843, in exec_module
  File "<frozen importlib._bootstrap>", line 219, in _call_with_frames_removed
  File "/opt/airflow/dags/main_de_project_1_dag.py", line 11, in <module>
    import create_tables
ModuleNotFoundError: No module named 'create_tables'
[2023-12-11T00:15:08.853+0000] {processor.py:841} WARNING - No viable dags retrieved from /opt/airflow/dags/main_de_project_1_dag.py
[2023-12-11T00:15:08.888+0000] {processor.py:179} INFO - Processing /opt/airflow/dags/main_de_project_1_dag.py took 0.066 seconds
[2023-12-11T00:15:39.217+0000] {processor.py:157} INFO - Started process (PID=3848) to work on /opt/airflow/dags/main_de_project_1_dag.py
[2023-12-11T00:15:39.219+0000] {processor.py:829} INFO - Processing file /opt/airflow/dags/main_de_project_1_dag.py for tasks to queue
[2023-12-11T00:15:39.223+0000] {logging_mixin.py:154} INFO - [2023-12-11T00:15:39.222+0000] {dagbag.py:536} INFO - Filling up the DagBag from /opt/airflow/dags/main_de_project_1_dag.py
[2023-12-11T00:15:39.233+0000] {logging_mixin.py:154} INFO - [2023-12-11T00:15:39.231+0000] {dagbag.py:346} ERROR - Failed to import: /opt/airflow/dags/main_de_project_1_dag.py
Traceback (most recent call last):
  File "/home/airflow/.local/lib/python3.8/site-packages/airflow/models/dagbag.py", line 342, in parse
    loader.exec_module(new_module)
  File "<frozen importlib._bootstrap_external>", line 843, in exec_module
  File "<frozen importlib._bootstrap>", line 219, in _call_with_frames_removed
  File "/opt/airflow/dags/main_de_project_1_dag.py", line 11, in <module>
    import create_tables
ModuleNotFoundError: No module named 'create_tables'
[2023-12-11T00:15:39.234+0000] {processor.py:841} WARNING - No viable dags retrieved from /opt/airflow/dags/main_de_project_1_dag.py
[2023-12-11T00:15:39.264+0000] {processor.py:179} INFO - Processing /opt/airflow/dags/main_de_project_1_dag.py took 0.052 seconds
[2023-12-11T00:16:09.523+0000] {processor.py:157} INFO - Started process (PID=3856) to work on /opt/airflow/dags/main_de_project_1_dag.py
[2023-12-11T00:16:09.525+0000] {processor.py:829} INFO - Processing file /opt/airflow/dags/main_de_project_1_dag.py for tasks to queue
[2023-12-11T00:16:09.528+0000] {logging_mixin.py:154} INFO - [2023-12-11T00:16:09.528+0000] {dagbag.py:536} INFO - Filling up the DagBag from /opt/airflow/dags/main_de_project_1_dag.py
[2023-12-11T00:16:09.540+0000] {logging_mixin.py:154} INFO - [2023-12-11T00:16:09.538+0000] {dagbag.py:346} ERROR - Failed to import: /opt/airflow/dags/main_de_project_1_dag.py
Traceback (most recent call last):
  File "/home/airflow/.local/lib/python3.8/site-packages/airflow/models/dagbag.py", line 342, in parse
    loader.exec_module(new_module)
  File "<frozen importlib._bootstrap_external>", line 843, in exec_module
  File "<frozen importlib._bootstrap>", line 219, in _call_with_frames_removed
  File "/opt/airflow/dags/main_de_project_1_dag.py", line 11, in <module>
    import create_tables
ModuleNotFoundError: No module named 'create_tables'
[2023-12-11T00:16:09.542+0000] {processor.py:841} WARNING - No viable dags retrieved from /opt/airflow/dags/main_de_project_1_dag.py
[2023-12-11T00:16:09.566+0000] {processor.py:179} INFO - Processing /opt/airflow/dags/main_de_project_1_dag.py took 0.049 seconds
[2023-12-11T00:16:39.744+0000] {processor.py:157} INFO - Started process (PID=3865) to work on /opt/airflow/dags/main_de_project_1_dag.py
[2023-12-11T00:16:39.746+0000] {processor.py:829} INFO - Processing file /opt/airflow/dags/main_de_project_1_dag.py for tasks to queue
[2023-12-11T00:16:39.750+0000] {logging_mixin.py:154} INFO - [2023-12-11T00:16:39.750+0000] {dagbag.py:536} INFO - Filling up the DagBag from /opt/airflow/dags/main_de_project_1_dag.py
[2023-12-11T00:16:39.759+0000] {logging_mixin.py:154} INFO - [2023-12-11T00:16:39.757+0000] {dagbag.py:346} ERROR - Failed to import: /opt/airflow/dags/main_de_project_1_dag.py
Traceback (most recent call last):
  File "/home/airflow/.local/lib/python3.8/site-packages/airflow/models/dagbag.py", line 342, in parse
    loader.exec_module(new_module)
  File "<frozen importlib._bootstrap_external>", line 843, in exec_module
  File "<frozen importlib._bootstrap>", line 219, in _call_with_frames_removed
  File "/opt/airflow/dags/main_de_project_1_dag.py", line 11, in <module>
    import create_tables
ModuleNotFoundError: No module named 'create_tables'
[2023-12-11T00:16:39.761+0000] {processor.py:841} WARNING - No viable dags retrieved from /opt/airflow/dags/main_de_project_1_dag.py
[2023-12-11T00:16:39.785+0000] {processor.py:179} INFO - Processing /opt/airflow/dags/main_de_project_1_dag.py took 0.047 seconds
[2023-12-11T00:17:09.969+0000] {processor.py:157} INFO - Started process (PID=3873) to work on /opt/airflow/dags/main_de_project_1_dag.py
[2023-12-11T00:17:09.974+0000] {processor.py:829} INFO - Processing file /opt/airflow/dags/main_de_project_1_dag.py for tasks to queue
[2023-12-11T00:17:09.979+0000] {logging_mixin.py:154} INFO - [2023-12-11T00:17:09.978+0000] {dagbag.py:536} INFO - Filling up the DagBag from /opt/airflow/dags/main_de_project_1_dag.py
[2023-12-11T00:17:09.989+0000] {logging_mixin.py:154} INFO - [2023-12-11T00:17:09.987+0000] {dagbag.py:346} ERROR - Failed to import: /opt/airflow/dags/main_de_project_1_dag.py
Traceback (most recent call last):
  File "/home/airflow/.local/lib/python3.8/site-packages/airflow/models/dagbag.py", line 342, in parse
    loader.exec_module(new_module)
  File "<frozen importlib._bootstrap_external>", line 843, in exec_module
  File "<frozen importlib._bootstrap>", line 219, in _call_with_frames_removed
  File "/opt/airflow/dags/main_de_project_1_dag.py", line 11, in <module>
    import create_tables
ModuleNotFoundError: No module named 'create_tables'
[2023-12-11T00:17:09.991+0000] {processor.py:841} WARNING - No viable dags retrieved from /opt/airflow/dags/main_de_project_1_dag.py
[2023-12-11T00:17:10.032+0000] {processor.py:179} INFO - Processing /opt/airflow/dags/main_de_project_1_dag.py took 0.068 seconds
[2023-12-11T00:17:40.199+0000] {processor.py:157} INFO - Started process (PID=3881) to work on /opt/airflow/dags/main_de_project_1_dag.py
[2023-12-11T00:17:40.201+0000] {processor.py:829} INFO - Processing file /opt/airflow/dags/main_de_project_1_dag.py for tasks to queue
[2023-12-11T00:17:40.205+0000] {logging_mixin.py:154} INFO - [2023-12-11T00:17:40.205+0000] {dagbag.py:536} INFO - Filling up the DagBag from /opt/airflow/dags/main_de_project_1_dag.py
[2023-12-11T00:17:40.217+0000] {logging_mixin.py:154} INFO - [2023-12-11T00:17:40.214+0000] {dagbag.py:346} ERROR - Failed to import: /opt/airflow/dags/main_de_project_1_dag.py
Traceback (most recent call last):
  File "/home/airflow/.local/lib/python3.8/site-packages/airflow/models/dagbag.py", line 342, in parse
    loader.exec_module(new_module)
  File "<frozen importlib._bootstrap_external>", line 843, in exec_module
  File "<frozen importlib._bootstrap>", line 219, in _call_with_frames_removed
  File "/opt/airflow/dags/main_de_project_1_dag.py", line 11, in <module>
    import create_tables
ModuleNotFoundError: No module named 'create_tables'
[2023-12-11T00:17:40.219+0000] {processor.py:841} WARNING - No viable dags retrieved from /opt/airflow/dags/main_de_project_1_dag.py
[2023-12-11T00:17:40.250+0000] {processor.py:179} INFO - Processing /opt/airflow/dags/main_de_project_1_dag.py took 0.057 seconds
[2023-12-11T00:18:10.514+0000] {processor.py:157} INFO - Started process (PID=3889) to work on /opt/airflow/dags/main_de_project_1_dag.py
[2023-12-11T00:18:10.516+0000] {processor.py:829} INFO - Processing file /opt/airflow/dags/main_de_project_1_dag.py for tasks to queue
[2023-12-11T00:18:10.519+0000] {logging_mixin.py:154} INFO - [2023-12-11T00:18:10.519+0000] {dagbag.py:536} INFO - Filling up the DagBag from /opt/airflow/dags/main_de_project_1_dag.py
[2023-12-11T00:18:10.531+0000] {logging_mixin.py:154} INFO - [2023-12-11T00:18:10.529+0000] {dagbag.py:346} ERROR - Failed to import: /opt/airflow/dags/main_de_project_1_dag.py
Traceback (most recent call last):
  File "/home/airflow/.local/lib/python3.8/site-packages/airflow/models/dagbag.py", line 342, in parse
    loader.exec_module(new_module)
  File "<frozen importlib._bootstrap_external>", line 843, in exec_module
  File "<frozen importlib._bootstrap>", line 219, in _call_with_frames_removed
  File "/opt/airflow/dags/main_de_project_1_dag.py", line 11, in <module>
    import create_tables
ModuleNotFoundError: No module named 'create_tables'
[2023-12-11T00:18:10.533+0000] {processor.py:841} WARNING - No viable dags retrieved from /opt/airflow/dags/main_de_project_1_dag.py
[2023-12-11T00:18:10.558+0000] {processor.py:179} INFO - Processing /opt/airflow/dags/main_de_project_1_dag.py took 0.050 seconds
[2023-12-11T00:18:40.775+0000] {processor.py:157} INFO - Started process (PID=3897) to work on /opt/airflow/dags/main_de_project_1_dag.py
[2023-12-11T00:18:40.777+0000] {processor.py:829} INFO - Processing file /opt/airflow/dags/main_de_project_1_dag.py for tasks to queue
[2023-12-11T00:18:40.780+0000] {logging_mixin.py:154} INFO - [2023-12-11T00:18:40.780+0000] {dagbag.py:536} INFO - Filling up the DagBag from /opt/airflow/dags/main_de_project_1_dag.py
[2023-12-11T00:18:40.790+0000] {logging_mixin.py:154} INFO - [2023-12-11T00:18:40.788+0000] {dagbag.py:346} ERROR - Failed to import: /opt/airflow/dags/main_de_project_1_dag.py
Traceback (most recent call last):
  File "/home/airflow/.local/lib/python3.8/site-packages/airflow/models/dagbag.py", line 342, in parse
    loader.exec_module(new_module)
  File "<frozen importlib._bootstrap_external>", line 843, in exec_module
  File "<frozen importlib._bootstrap>", line 219, in _call_with_frames_removed
  File "/opt/airflow/dags/main_de_project_1_dag.py", line 11, in <module>
    import create_tables
ModuleNotFoundError: No module named 'create_tables'
[2023-12-11T00:18:40.791+0000] {processor.py:841} WARNING - No viable dags retrieved from /opt/airflow/dags/main_de_project_1_dag.py
[2023-12-11T00:18:40.832+0000] {processor.py:179} INFO - Processing /opt/airflow/dags/main_de_project_1_dag.py took 0.062 seconds
[2023-12-11T00:19:11.001+0000] {processor.py:157} INFO - Started process (PID=3905) to work on /opt/airflow/dags/main_de_project_1_dag.py
[2023-12-11T00:19:11.003+0000] {processor.py:829} INFO - Processing file /opt/airflow/dags/main_de_project_1_dag.py for tasks to queue
[2023-12-11T00:19:11.010+0000] {logging_mixin.py:154} INFO - [2023-12-11T00:19:11.009+0000] {dagbag.py:536} INFO - Filling up the DagBag from /opt/airflow/dags/main_de_project_1_dag.py
[2023-12-11T00:19:11.116+0000] {logging_mixin.py:154} INFO - [2023-12-11T00:19:11.113+0000] {dagbag.py:346} ERROR - Failed to import: /opt/airflow/dags/main_de_project_1_dag.py
Traceback (most recent call last):
  File "/home/airflow/.local/lib/python3.8/site-packages/airflow/models/dagbag.py", line 342, in parse
    loader.exec_module(new_module)
  File "<frozen importlib._bootstrap_external>", line 843, in exec_module
  File "<frozen importlib._bootstrap>", line 219, in _call_with_frames_removed
  File "/opt/airflow/dags/main_de_project_1_dag.py", line 11, in <module>
    import create_tables
ModuleNotFoundError: No module named 'create_tables'
[2023-12-11T00:19:11.117+0000] {processor.py:841} WARNING - No viable dags retrieved from /opt/airflow/dags/main_de_project_1_dag.py
[2023-12-11T00:19:11.150+0000] {processor.py:179} INFO - Processing /opt/airflow/dags/main_de_project_1_dag.py took 0.156 seconds
[2023-12-11T00:19:41.345+0000] {processor.py:157} INFO - Started process (PID=3913) to work on /opt/airflow/dags/main_de_project_1_dag.py
[2023-12-11T00:19:41.362+0000] {processor.py:829} INFO - Processing file /opt/airflow/dags/main_de_project_1_dag.py for tasks to queue
[2023-12-11T00:19:41.377+0000] {logging_mixin.py:154} INFO - [2023-12-11T00:19:41.376+0000] {dagbag.py:536} INFO - Filling up the DagBag from /opt/airflow/dags/main_de_project_1_dag.py
[2023-12-11T00:19:41.435+0000] {logging_mixin.py:154} INFO - [2023-12-11T00:19:41.414+0000] {dagbag.py:346} ERROR - Failed to import: /opt/airflow/dags/main_de_project_1_dag.py
Traceback (most recent call last):
  File "/home/airflow/.local/lib/python3.8/site-packages/airflow/models/dagbag.py", line 342, in parse
    loader.exec_module(new_module)
  File "<frozen importlib._bootstrap_external>", line 843, in exec_module
  File "<frozen importlib._bootstrap>", line 219, in _call_with_frames_removed
  File "/opt/airflow/dags/main_de_project_1_dag.py", line 11, in <module>
    import create_tables
ModuleNotFoundError: No module named 'create_tables'
[2023-12-11T00:19:41.439+0000] {processor.py:841} WARNING - No viable dags retrieved from /opt/airflow/dags/main_de_project_1_dag.py
[2023-12-11T00:19:41.516+0000] {processor.py:179} INFO - Processing /opt/airflow/dags/main_de_project_1_dag.py took 0.188 seconds
[2023-12-11T00:20:11.665+0000] {processor.py:157} INFO - Started process (PID=3922) to work on /opt/airflow/dags/main_de_project_1_dag.py
[2023-12-11T00:20:11.679+0000] {processor.py:829} INFO - Processing file /opt/airflow/dags/main_de_project_1_dag.py for tasks to queue
[2023-12-11T00:20:11.701+0000] {logging_mixin.py:154} INFO - [2023-12-11T00:20:11.700+0000] {dagbag.py:536} INFO - Filling up the DagBag from /opt/airflow/dags/main_de_project_1_dag.py
[2023-12-11T00:20:11.749+0000] {logging_mixin.py:154} INFO - [2023-12-11T00:20:11.742+0000] {dagbag.py:346} ERROR - Failed to import: /opt/airflow/dags/main_de_project_1_dag.py
Traceback (most recent call last):
  File "/home/airflow/.local/lib/python3.8/site-packages/airflow/models/dagbag.py", line 342, in parse
    loader.exec_module(new_module)
  File "<frozen importlib._bootstrap_external>", line 843, in exec_module
  File "<frozen importlib._bootstrap>", line 219, in _call_with_frames_removed
  File "/opt/airflow/dags/main_de_project_1_dag.py", line 11, in <module>
    import create_tables
ModuleNotFoundError: No module named 'create_tables'
[2023-12-11T00:20:11.753+0000] {processor.py:841} WARNING - No viable dags retrieved from /opt/airflow/dags/main_de_project_1_dag.py
[2023-12-11T00:20:11.861+0000] {processor.py:179} INFO - Processing /opt/airflow/dags/main_de_project_1_dag.py took 0.212 seconds
[2023-12-11T00:20:42.086+0000] {processor.py:157} INFO - Started process (PID=3930) to work on /opt/airflow/dags/main_de_project_1_dag.py
[2023-12-11T00:20:42.089+0000] {processor.py:829} INFO - Processing file /opt/airflow/dags/main_de_project_1_dag.py for tasks to queue
[2023-12-11T00:20:42.097+0000] {logging_mixin.py:154} INFO - [2023-12-11T00:20:42.096+0000] {dagbag.py:536} INFO - Filling up the DagBag from /opt/airflow/dags/main_de_project_1_dag.py
[2023-12-11T00:20:42.145+0000] {logging_mixin.py:154} INFO - [2023-12-11T00:20:42.134+0000] {dagbag.py:346} ERROR - Failed to import: /opt/airflow/dags/main_de_project_1_dag.py
Traceback (most recent call last):
  File "/home/airflow/.local/lib/python3.8/site-packages/airflow/models/dagbag.py", line 342, in parse
    loader.exec_module(new_module)
  File "<frozen importlib._bootstrap_external>", line 843, in exec_module
  File "<frozen importlib._bootstrap>", line 219, in _call_with_frames_removed
  File "/opt/airflow/dags/main_de_project_1_dag.py", line 11, in <module>
    import create_tables
ModuleNotFoundError: No module named 'create_tables'
[2023-12-11T00:20:42.151+0000] {processor.py:841} WARNING - No viable dags retrieved from /opt/airflow/dags/main_de_project_1_dag.py
[2023-12-11T00:20:42.230+0000] {processor.py:179} INFO - Processing /opt/airflow/dags/main_de_project_1_dag.py took 0.150 seconds
[2023-12-11T00:21:12.536+0000] {processor.py:157} INFO - Started process (PID=3938) to work on /opt/airflow/dags/main_de_project_1_dag.py
[2023-12-11T00:21:12.549+0000] {processor.py:829} INFO - Processing file /opt/airflow/dags/main_de_project_1_dag.py for tasks to queue
[2023-12-11T00:21:12.575+0000] {logging_mixin.py:154} INFO - [2023-12-11T00:21:12.574+0000] {dagbag.py:536} INFO - Filling up the DagBag from /opt/airflow/dags/main_de_project_1_dag.py
[2023-12-11T00:21:12.633+0000] {logging_mixin.py:154} INFO - [2023-12-11T00:21:12.616+0000] {dagbag.py:346} ERROR - Failed to import: /opt/airflow/dags/main_de_project_1_dag.py
Traceback (most recent call last):
  File "/home/airflow/.local/lib/python3.8/site-packages/airflow/models/dagbag.py", line 342, in parse
    loader.exec_module(new_module)
  File "<frozen importlib._bootstrap_external>", line 843, in exec_module
  File "<frozen importlib._bootstrap>", line 219, in _call_with_frames_removed
  File "/opt/airflow/dags/main_de_project_1_dag.py", line 11, in <module>
    import create_tables
ModuleNotFoundError: No module named 'create_tables'
[2023-12-11T00:21:12.648+0000] {processor.py:841} WARNING - No viable dags retrieved from /opt/airflow/dags/main_de_project_1_dag.py
[2023-12-11T00:21:12.796+0000] {processor.py:179} INFO - Processing /opt/airflow/dags/main_de_project_1_dag.py took 0.276 seconds
[2023-12-11T00:21:43.139+0000] {processor.py:157} INFO - Started process (PID=3946) to work on /opt/airflow/dags/main_de_project_1_dag.py
[2023-12-11T00:21:43.152+0000] {processor.py:829} INFO - Processing file /opt/airflow/dags/main_de_project_1_dag.py for tasks to queue
[2023-12-11T00:21:43.168+0000] {logging_mixin.py:154} INFO - [2023-12-11T00:21:43.167+0000] {dagbag.py:536} INFO - Filling up the DagBag from /opt/airflow/dags/main_de_project_1_dag.py
[2023-12-11T00:21:43.198+0000] {logging_mixin.py:154} INFO - [2023-12-11T00:21:43.187+0000] {dagbag.py:346} ERROR - Failed to import: /opt/airflow/dags/main_de_project_1_dag.py
Traceback (most recent call last):
  File "/home/airflow/.local/lib/python3.8/site-packages/airflow/models/dagbag.py", line 342, in parse
    loader.exec_module(new_module)
  File "<frozen importlib._bootstrap_external>", line 843, in exec_module
  File "<frozen importlib._bootstrap>", line 219, in _call_with_frames_removed
  File "/opt/airflow/dags/main_de_project_1_dag.py", line 11, in <module>
    import create_tables
ModuleNotFoundError: No module named 'create_tables'
[2023-12-11T00:21:43.201+0000] {processor.py:841} WARNING - No viable dags retrieved from /opt/airflow/dags/main_de_project_1_dag.py
[2023-12-11T00:21:43.272+0000] {processor.py:179} INFO - Processing /opt/airflow/dags/main_de_project_1_dag.py took 0.140 seconds
[2023-12-11T00:22:13.409+0000] {processor.py:157} INFO - Started process (PID=3954) to work on /opt/airflow/dags/main_de_project_1_dag.py
[2023-12-11T00:22:13.416+0000] {processor.py:829} INFO - Processing file /opt/airflow/dags/main_de_project_1_dag.py for tasks to queue
[2023-12-11T00:22:13.421+0000] {logging_mixin.py:154} INFO - [2023-12-11T00:22:13.420+0000] {dagbag.py:536} INFO - Filling up the DagBag from /opt/airflow/dags/main_de_project_1_dag.py
[2023-12-11T00:22:13.443+0000] {logging_mixin.py:154} INFO - [2023-12-11T00:22:13.439+0000] {dagbag.py:346} ERROR - Failed to import: /opt/airflow/dags/main_de_project_1_dag.py
Traceback (most recent call last):
  File "/home/airflow/.local/lib/python3.8/site-packages/airflow/models/dagbag.py", line 342, in parse
    loader.exec_module(new_module)
  File "<frozen importlib._bootstrap_external>", line 843, in exec_module
  File "<frozen importlib._bootstrap>", line 219, in _call_with_frames_removed
  File "/opt/airflow/dags/main_de_project_1_dag.py", line 11, in <module>
    import create_tables
ModuleNotFoundError: No module named 'create_tables'
[2023-12-11T00:22:13.447+0000] {processor.py:841} WARNING - No viable dags retrieved from /opt/airflow/dags/main_de_project_1_dag.py
[2023-12-11T00:22:13.536+0000] {processor.py:179} INFO - Processing /opt/airflow/dags/main_de_project_1_dag.py took 0.140 seconds
[2023-12-11T00:22:43.708+0000] {processor.py:157} INFO - Started process (PID=3962) to work on /opt/airflow/dags/main_de_project_1_dag.py
[2023-12-11T00:22:43.721+0000] {processor.py:829} INFO - Processing file /opt/airflow/dags/main_de_project_1_dag.py for tasks to queue
[2023-12-11T00:22:43.735+0000] {logging_mixin.py:154} INFO - [2023-12-11T00:22:43.734+0000] {dagbag.py:536} INFO - Filling up the DagBag from /opt/airflow/dags/main_de_project_1_dag.py
[2023-12-11T00:22:43.773+0000] {logging_mixin.py:154} INFO - [2023-12-11T00:22:43.763+0000] {dagbag.py:346} ERROR - Failed to import: /opt/airflow/dags/main_de_project_1_dag.py
Traceback (most recent call last):
  File "/home/airflow/.local/lib/python3.8/site-packages/airflow/models/dagbag.py", line 342, in parse
    loader.exec_module(new_module)
  File "<frozen importlib._bootstrap_external>", line 843, in exec_module
  File "<frozen importlib._bootstrap>", line 219, in _call_with_frames_removed
  File "/opt/airflow/dags/main_de_project_1_dag.py", line 11, in <module>
    import create_tables
ModuleNotFoundError: No module named 'create_tables'
[2023-12-11T00:22:43.774+0000] {processor.py:841} WARNING - No viable dags retrieved from /opt/airflow/dags/main_de_project_1_dag.py
[2023-12-11T00:22:43.888+0000] {processor.py:179} INFO - Processing /opt/airflow/dags/main_de_project_1_dag.py took 0.196 seconds
[2023-12-11T00:23:14.184+0000] {processor.py:157} INFO - Started process (PID=3969) to work on /opt/airflow/dags/main_de_project_1_dag.py
[2023-12-11T00:23:14.187+0000] {processor.py:829} INFO - Processing file /opt/airflow/dags/main_de_project_1_dag.py for tasks to queue
[2023-12-11T00:23:14.198+0000] {logging_mixin.py:154} INFO - [2023-12-11T00:23:14.196+0000] {dagbag.py:536} INFO - Filling up the DagBag from /opt/airflow/dags/main_de_project_1_dag.py
[2023-12-11T00:23:14.230+0000] {logging_mixin.py:154} INFO - [2023-12-11T00:23:14.224+0000] {dagbag.py:346} ERROR - Failed to import: /opt/airflow/dags/main_de_project_1_dag.py
Traceback (most recent call last):
  File "/home/airflow/.local/lib/python3.8/site-packages/airflow/models/dagbag.py", line 342, in parse
    loader.exec_module(new_module)
  File "<frozen importlib._bootstrap_external>", line 843, in exec_module
  File "<frozen importlib._bootstrap>", line 219, in _call_with_frames_removed
  File "/opt/airflow/dags/main_de_project_1_dag.py", line 11, in <module>
    import create_tables
ModuleNotFoundError: No module named 'create_tables'
[2023-12-11T00:23:14.232+0000] {processor.py:841} WARNING - No viable dags retrieved from /opt/airflow/dags/main_de_project_1_dag.py
[2023-12-11T00:23:14.307+0000] {processor.py:179} INFO - Processing /opt/airflow/dags/main_de_project_1_dag.py took 0.139 seconds
[2023-12-11T00:23:44.514+0000] {processor.py:157} INFO - Started process (PID=3977) to work on /opt/airflow/dags/main_de_project_1_dag.py
[2023-12-11T00:23:44.526+0000] {processor.py:829} INFO - Processing file /opt/airflow/dags/main_de_project_1_dag.py for tasks to queue
[2023-12-11T00:23:44.538+0000] {logging_mixin.py:154} INFO - [2023-12-11T00:23:44.537+0000] {dagbag.py:536} INFO - Filling up the DagBag from /opt/airflow/dags/main_de_project_1_dag.py
[2023-12-11T00:23:44.581+0000] {logging_mixin.py:154} INFO - [2023-12-11T00:23:44.569+0000] {dagbag.py:346} ERROR - Failed to import: /opt/airflow/dags/main_de_project_1_dag.py
Traceback (most recent call last):
  File "/home/airflow/.local/lib/python3.8/site-packages/airflow/models/dagbag.py", line 342, in parse
    loader.exec_module(new_module)
  File "<frozen importlib._bootstrap_external>", line 843, in exec_module
  File "<frozen importlib._bootstrap>", line 219, in _call_with_frames_removed
  File "/opt/airflow/dags/main_de_project_1_dag.py", line 11, in <module>
    import create_tables
ModuleNotFoundError: No module named 'create_tables'
[2023-12-11T00:23:44.588+0000] {processor.py:841} WARNING - No viable dags retrieved from /opt/airflow/dags/main_de_project_1_dag.py
[2023-12-11T00:23:44.757+0000] {processor.py:179} INFO - Processing /opt/airflow/dags/main_de_project_1_dag.py took 0.260 seconds
[2023-12-11T00:24:15.028+0000] {processor.py:157} INFO - Started process (PID=3984) to work on /opt/airflow/dags/main_de_project_1_dag.py
[2023-12-11T00:24:15.050+0000] {processor.py:829} INFO - Processing file /opt/airflow/dags/main_de_project_1_dag.py for tasks to queue
[2023-12-11T00:24:15.078+0000] {logging_mixin.py:154} INFO - [2023-12-11T00:24:15.077+0000] {dagbag.py:536} INFO - Filling up the DagBag from /opt/airflow/dags/main_de_project_1_dag.py
[2023-12-11T00:24:15.134+0000] {logging_mixin.py:154} INFO - [2023-12-11T00:24:15.127+0000] {dagbag.py:346} ERROR - Failed to import: /opt/airflow/dags/main_de_project_1_dag.py
Traceback (most recent call last):
  File "/home/airflow/.local/lib/python3.8/site-packages/airflow/models/dagbag.py", line 342, in parse
    loader.exec_module(new_module)
  File "<frozen importlib._bootstrap_external>", line 843, in exec_module
  File "<frozen importlib._bootstrap>", line 219, in _call_with_frames_removed
  File "/opt/airflow/dags/main_de_project_1_dag.py", line 11, in <module>
    import create_tables
ModuleNotFoundError: No module named 'create_tables'
[2023-12-11T00:24:15.144+0000] {processor.py:841} WARNING - No viable dags retrieved from /opt/airflow/dags/main_de_project_1_dag.py
[2023-12-11T00:24:15.298+0000] {processor.py:179} INFO - Processing /opt/airflow/dags/main_de_project_1_dag.py took 0.298 seconds
[2023-12-11T00:24:45.755+0000] {processor.py:157} INFO - Started process (PID=3992) to work on /opt/airflow/dags/main_de_project_1_dag.py
[2023-12-11T00:24:45.763+0000] {processor.py:829} INFO - Processing file /opt/airflow/dags/main_de_project_1_dag.py for tasks to queue
[2023-12-11T00:24:45.770+0000] {logging_mixin.py:154} INFO - [2023-12-11T00:24:45.770+0000] {dagbag.py:536} INFO - Filling up the DagBag from /opt/airflow/dags/main_de_project_1_dag.py
[2023-12-11T00:24:45.787+0000] {logging_mixin.py:154} INFO - [2023-12-11T00:24:45.784+0000] {dagbag.py:346} ERROR - Failed to import: /opt/airflow/dags/main_de_project_1_dag.py
Traceback (most recent call last):
  File "/home/airflow/.local/lib/python3.8/site-packages/airflow/models/dagbag.py", line 342, in parse
    loader.exec_module(new_module)
  File "<frozen importlib._bootstrap_external>", line 843, in exec_module
  File "<frozen importlib._bootstrap>", line 219, in _call_with_frames_removed
  File "/opt/airflow/dags/main_de_project_1_dag.py", line 11, in <module>
    import create_tables
ModuleNotFoundError: No module named 'create_tables'
[2023-12-11T00:24:45.789+0000] {processor.py:841} WARNING - No viable dags retrieved from /opt/airflow/dags/main_de_project_1_dag.py
[2023-12-11T00:24:45.875+0000] {processor.py:179} INFO - Processing /opt/airflow/dags/main_de_project_1_dag.py took 0.207 seconds
[2023-12-11T00:25:16.285+0000] {processor.py:157} INFO - Started process (PID=4000) to work on /opt/airflow/dags/main_de_project_1_dag.py
[2023-12-11T00:25:16.291+0000] {processor.py:829} INFO - Processing file /opt/airflow/dags/main_de_project_1_dag.py for tasks to queue
[2023-12-11T00:25:16.309+0000] {logging_mixin.py:154} INFO - [2023-12-11T00:25:16.308+0000] {dagbag.py:536} INFO - Filling up the DagBag from /opt/airflow/dags/main_de_project_1_dag.py
[2023-12-11T00:25:16.537+0000] {logging_mixin.py:154} INFO - [2023-12-11T00:25:16.507+0000] {dagbag.py:346} ERROR - Failed to import: /opt/airflow/dags/main_de_project_1_dag.py
Traceback (most recent call last):
  File "/home/airflow/.local/lib/python3.8/site-packages/airflow/models/dagbag.py", line 342, in parse
    loader.exec_module(new_module)
  File "<frozen importlib._bootstrap_external>", line 843, in exec_module
  File "<frozen importlib._bootstrap>", line 219, in _call_with_frames_removed
  File "/opt/airflow/dags/main_de_project_1_dag.py", line 11, in <module>
    import create_tables
ModuleNotFoundError: No module named 'create_tables'
[2023-12-11T00:25:16.568+0000] {processor.py:841} WARNING - No viable dags retrieved from /opt/airflow/dags/main_de_project_1_dag.py
[2023-12-11T00:25:16.871+0000] {processor.py:179} INFO - Processing /opt/airflow/dags/main_de_project_1_dag.py took 0.662 seconds
[2023-12-11T00:25:47.143+0000] {processor.py:157} INFO - Started process (PID=4008) to work on /opt/airflow/dags/main_de_project_1_dag.py
[2023-12-11T00:25:47.165+0000] {processor.py:829} INFO - Processing file /opt/airflow/dags/main_de_project_1_dag.py for tasks to queue
[2023-12-11T00:25:47.182+0000] {logging_mixin.py:154} INFO - [2023-12-11T00:25:47.181+0000] {dagbag.py:536} INFO - Filling up the DagBag from /opt/airflow/dags/main_de_project_1_dag.py
[2023-12-11T00:25:47.234+0000] {logging_mixin.py:154} INFO - [2023-12-11T00:25:47.230+0000] {dagbag.py:346} ERROR - Failed to import: /opt/airflow/dags/main_de_project_1_dag.py
Traceback (most recent call last):
  File "/home/airflow/.local/lib/python3.8/site-packages/airflow/models/dagbag.py", line 342, in parse
    loader.exec_module(new_module)
  File "<frozen importlib._bootstrap_external>", line 843, in exec_module
  File "<frozen importlib._bootstrap>", line 219, in _call_with_frames_removed
  File "/opt/airflow/dags/main_de_project_1_dag.py", line 11, in <module>
    import create_tables
ModuleNotFoundError: No module named 'create_tables'
[2023-12-11T00:25:47.240+0000] {processor.py:841} WARNING - No viable dags retrieved from /opt/airflow/dags/main_de_project_1_dag.py
[2023-12-11T00:25:47.297+0000] {processor.py:179} INFO - Processing /opt/airflow/dags/main_de_project_1_dag.py took 0.192 seconds
[2023-12-11T00:26:17.513+0000] {processor.py:157} INFO - Started process (PID=4016) to work on /opt/airflow/dags/main_de_project_1_dag.py
[2023-12-11T00:26:17.517+0000] {processor.py:829} INFO - Processing file /opt/airflow/dags/main_de_project_1_dag.py for tasks to queue
[2023-12-11T00:26:17.528+0000] {logging_mixin.py:154} INFO - [2023-12-11T00:26:17.527+0000] {dagbag.py:536} INFO - Filling up the DagBag from /opt/airflow/dags/main_de_project_1_dag.py
[2023-12-11T00:26:17.570+0000] {logging_mixin.py:154} INFO - [2023-12-11T00:26:17.542+0000] {dagbag.py:346} ERROR - Failed to import: /opt/airflow/dags/main_de_project_1_dag.py
Traceback (most recent call last):
  File "/home/airflow/.local/lib/python3.8/site-packages/airflow/models/dagbag.py", line 342, in parse
    loader.exec_module(new_module)
  File "<frozen importlib._bootstrap_external>", line 843, in exec_module
  File "<frozen importlib._bootstrap>", line 219, in _call_with_frames_removed
  File "/opt/airflow/dags/main_de_project_1_dag.py", line 11, in <module>
    import create_tables
ModuleNotFoundError: No module named 'create_tables'
[2023-12-11T00:26:17.573+0000] {processor.py:841} WARNING - No viable dags retrieved from /opt/airflow/dags/main_de_project_1_dag.py
[2023-12-11T00:26:17.640+0000] {processor.py:179} INFO - Processing /opt/airflow/dags/main_de_project_1_dag.py took 0.143 seconds
[2023-12-11T00:26:48.083+0000] {processor.py:157} INFO - Started process (PID=4024) to work on /opt/airflow/dags/main_de_project_1_dag.py
[2023-12-11T00:26:48.090+0000] {processor.py:829} INFO - Processing file /opt/airflow/dags/main_de_project_1_dag.py for tasks to queue
[2023-12-11T00:26:48.133+0000] {logging_mixin.py:154} INFO - [2023-12-11T00:26:48.123+0000] {dagbag.py:536} INFO - Filling up the DagBag from /opt/airflow/dags/main_de_project_1_dag.py
[2023-12-11T00:26:48.191+0000] {logging_mixin.py:154} INFO - [2023-12-11T00:26:48.182+0000] {dagbag.py:346} ERROR - Failed to import: /opt/airflow/dags/main_de_project_1_dag.py
Traceback (most recent call last):
  File "/home/airflow/.local/lib/python3.8/site-packages/airflow/models/dagbag.py", line 342, in parse
    loader.exec_module(new_module)
  File "<frozen importlib._bootstrap_external>", line 843, in exec_module
  File "<frozen importlib._bootstrap>", line 219, in _call_with_frames_removed
  File "/opt/airflow/dags/main_de_project_1_dag.py", line 11, in <module>
    import create_tables
ModuleNotFoundError: No module named 'create_tables'
[2023-12-11T00:26:48.197+0000] {processor.py:841} WARNING - No viable dags retrieved from /opt/airflow/dags/main_de_project_1_dag.py
[2023-12-11T00:26:48.273+0000] {processor.py:179} INFO - Processing /opt/airflow/dags/main_de_project_1_dag.py took 0.291 seconds
[2023-12-11T00:27:18.471+0000] {processor.py:157} INFO - Started process (PID=4031) to work on /opt/airflow/dags/main_de_project_1_dag.py
[2023-12-11T00:27:18.487+0000] {processor.py:829} INFO - Processing file /opt/airflow/dags/main_de_project_1_dag.py for tasks to queue
[2023-12-11T00:27:18.500+0000] {logging_mixin.py:154} INFO - [2023-12-11T00:27:18.499+0000] {dagbag.py:536} INFO - Filling up the DagBag from /opt/airflow/dags/main_de_project_1_dag.py
[2023-12-11T00:27:18.520+0000] {logging_mixin.py:154} INFO - [2023-12-11T00:27:18.514+0000] {dagbag.py:346} ERROR - Failed to import: /opt/airflow/dags/main_de_project_1_dag.py
Traceback (most recent call last):
  File "/home/airflow/.local/lib/python3.8/site-packages/airflow/models/dagbag.py", line 342, in parse
    loader.exec_module(new_module)
  File "<frozen importlib._bootstrap_external>", line 843, in exec_module
  File "<frozen importlib._bootstrap>", line 219, in _call_with_frames_removed
  File "/opt/airflow/dags/main_de_project_1_dag.py", line 11, in <module>
    import create_tables
ModuleNotFoundError: No module named 'create_tables'
[2023-12-11T00:27:18.523+0000] {processor.py:841} WARNING - No viable dags retrieved from /opt/airflow/dags/main_de_project_1_dag.py
[2023-12-11T00:27:18.607+0000] {processor.py:179} INFO - Processing /opt/airflow/dags/main_de_project_1_dag.py took 0.163 seconds
[2023-12-11T00:27:48.946+0000] {processor.py:157} INFO - Started process (PID=4039) to work on /opt/airflow/dags/main_de_project_1_dag.py
[2023-12-11T00:27:48.949+0000] {processor.py:829} INFO - Processing file /opt/airflow/dags/main_de_project_1_dag.py for tasks to queue
[2023-12-11T00:27:48.981+0000] {logging_mixin.py:154} INFO - [2023-12-11T00:27:48.980+0000] {dagbag.py:536} INFO - Filling up the DagBag from /opt/airflow/dags/main_de_project_1_dag.py
[2023-12-11T00:27:49.022+0000] {logging_mixin.py:154} INFO - [2023-12-11T00:27:49.015+0000] {dagbag.py:346} ERROR - Failed to import: /opt/airflow/dags/main_de_project_1_dag.py
Traceback (most recent call last):
  File "/home/airflow/.local/lib/python3.8/site-packages/airflow/models/dagbag.py", line 342, in parse
    loader.exec_module(new_module)
  File "<frozen importlib._bootstrap_external>", line 843, in exec_module
  File "<frozen importlib._bootstrap>", line 219, in _call_with_frames_removed
  File "/opt/airflow/dags/main_de_project_1_dag.py", line 11, in <module>
    import create_tables
ModuleNotFoundError: No module named 'create_tables'
[2023-12-11T00:27:49.030+0000] {processor.py:841} WARNING - No viable dags retrieved from /opt/airflow/dags/main_de_project_1_dag.py
[2023-12-11T00:27:49.110+0000] {processor.py:179} INFO - Processing /opt/airflow/dags/main_de_project_1_dag.py took 0.198 seconds
[2023-12-11T00:28:19.335+0000] {processor.py:157} INFO - Started process (PID=4047) to work on /opt/airflow/dags/main_de_project_1_dag.py
[2023-12-11T00:28:19.348+0000] {processor.py:829} INFO - Processing file /opt/airflow/dags/main_de_project_1_dag.py for tasks to queue
[2023-12-11T00:28:19.366+0000] {logging_mixin.py:154} INFO - [2023-12-11T00:28:19.365+0000] {dagbag.py:536} INFO - Filling up the DagBag from /opt/airflow/dags/main_de_project_1_dag.py
[2023-12-11T00:28:19.409+0000] {logging_mixin.py:154} INFO - [2023-12-11T00:28:19.397+0000] {dagbag.py:346} ERROR - Failed to import: /opt/airflow/dags/main_de_project_1_dag.py
Traceback (most recent call last):
  File "/home/airflow/.local/lib/python3.8/site-packages/airflow/models/dagbag.py", line 342, in parse
    loader.exec_module(new_module)
  File "<frozen importlib._bootstrap_external>", line 843, in exec_module
  File "<frozen importlib._bootstrap>", line 219, in _call_with_frames_removed
  File "/opt/airflow/dags/main_de_project_1_dag.py", line 11, in <module>
    import create_tables
ModuleNotFoundError: No module named 'create_tables'
[2023-12-11T00:28:19.412+0000] {processor.py:841} WARNING - No viable dags retrieved from /opt/airflow/dags/main_de_project_1_dag.py
[2023-12-11T00:28:19.639+0000] {processor.py:179} INFO - Processing /opt/airflow/dags/main_de_project_1_dag.py took 0.331 seconds
[2023-12-11T00:28:50.132+0000] {processor.py:157} INFO - Started process (PID=4055) to work on /opt/airflow/dags/main_de_project_1_dag.py
[2023-12-11T00:28:50.137+0000] {processor.py:829} INFO - Processing file /opt/airflow/dags/main_de_project_1_dag.py for tasks to queue
[2023-12-11T00:28:50.191+0000] {logging_mixin.py:154} INFO - [2023-12-11T00:28:50.190+0000] {dagbag.py:536} INFO - Filling up the DagBag from /opt/airflow/dags/main_de_project_1_dag.py
[2023-12-11T00:28:50.292+0000] {logging_mixin.py:154} INFO - [2023-12-11T00:28:50.284+0000] {dagbag.py:346} ERROR - Failed to import: /opt/airflow/dags/main_de_project_1_dag.py
Traceback (most recent call last):
  File "/home/airflow/.local/lib/python3.8/site-packages/airflow/models/dagbag.py", line 342, in parse
    loader.exec_module(new_module)
  File "<frozen importlib._bootstrap_external>", line 843, in exec_module
  File "<frozen importlib._bootstrap>", line 219, in _call_with_frames_removed
  File "/opt/airflow/dags/main_de_project_1_dag.py", line 11, in <module>
    import create_tables
ModuleNotFoundError: No module named 'create_tables'
[2023-12-11T00:28:50.297+0000] {processor.py:841} WARNING - No viable dags retrieved from /opt/airflow/dags/main_de_project_1_dag.py
[2023-12-11T00:28:50.402+0000] {processor.py:179} INFO - Processing /opt/airflow/dags/main_de_project_1_dag.py took 0.340 seconds
[2023-12-11T00:29:20.978+0000] {processor.py:157} INFO - Started process (PID=4063) to work on /opt/airflow/dags/main_de_project_1_dag.py
[2023-12-11T00:29:21.005+0000] {processor.py:829} INFO - Processing file /opt/airflow/dags/main_de_project_1_dag.py for tasks to queue
[2023-12-11T00:29:21.049+0000] {logging_mixin.py:154} INFO - [2023-12-11T00:29:21.048+0000] {dagbag.py:536} INFO - Filling up the DagBag from /opt/airflow/dags/main_de_project_1_dag.py
[2023-12-11T00:29:21.128+0000] {logging_mixin.py:154} INFO - [2023-12-11T00:29:21.108+0000] {dagbag.py:346} ERROR - Failed to import: /opt/airflow/dags/main_de_project_1_dag.py
Traceback (most recent call last):
  File "/home/airflow/.local/lib/python3.8/site-packages/airflow/models/dagbag.py", line 342, in parse
    loader.exec_module(new_module)
  File "<frozen importlib._bootstrap_external>", line 843, in exec_module
  File "<frozen importlib._bootstrap>", line 219, in _call_with_frames_removed
  File "/opt/airflow/dags/main_de_project_1_dag.py", line 11, in <module>
    import create_tables
ModuleNotFoundError: No module named 'create_tables'
[2023-12-11T00:29:21.144+0000] {processor.py:841} WARNING - No viable dags retrieved from /opt/airflow/dags/main_de_project_1_dag.py
[2023-12-11T00:29:21.454+0000] {processor.py:179} INFO - Processing /opt/airflow/dags/main_de_project_1_dag.py took 0.576 seconds
[2023-12-11T00:29:52.224+0000] {processor.py:157} INFO - Started process (PID=4071) to work on /opt/airflow/dags/main_de_project_1_dag.py
[2023-12-11T00:29:52.240+0000] {processor.py:829} INFO - Processing file /opt/airflow/dags/main_de_project_1_dag.py for tasks to queue
[2023-12-11T00:29:52.262+0000] {logging_mixin.py:154} INFO - [2023-12-11T00:29:52.261+0000] {dagbag.py:536} INFO - Filling up the DagBag from /opt/airflow/dags/main_de_project_1_dag.py
[2023-12-11T00:29:52.295+0000] {logging_mixin.py:154} INFO - [2023-12-11T00:29:52.287+0000] {dagbag.py:346} ERROR - Failed to import: /opt/airflow/dags/main_de_project_1_dag.py
Traceback (most recent call last):
  File "/home/airflow/.local/lib/python3.8/site-packages/airflow/models/dagbag.py", line 342, in parse
    loader.exec_module(new_module)
  File "<frozen importlib._bootstrap_external>", line 843, in exec_module
  File "<frozen importlib._bootstrap>", line 219, in _call_with_frames_removed
  File "/opt/airflow/dags/main_de_project_1_dag.py", line 11, in <module>
    import create_tables
ModuleNotFoundError: No module named 'create_tables'
[2023-12-11T00:29:52.303+0000] {processor.py:841} WARNING - No viable dags retrieved from /opt/airflow/dags/main_de_project_1_dag.py
[2023-12-11T00:29:52.576+0000] {processor.py:179} INFO - Processing /opt/airflow/dags/main_de_project_1_dag.py took 0.368 seconds
[2023-12-11T00:30:23.371+0000] {processor.py:157} INFO - Started process (PID=4079) to work on /opt/airflow/dags/main_de_project_1_dag.py
[2023-12-11T00:30:23.398+0000] {processor.py:829} INFO - Processing file /opt/airflow/dags/main_de_project_1_dag.py for tasks to queue
[2023-12-11T00:30:23.445+0000] {logging_mixin.py:154} INFO - [2023-12-11T00:30:23.444+0000] {dagbag.py:536} INFO - Filling up the DagBag from /opt/airflow/dags/main_de_project_1_dag.py
[2023-12-11T00:30:23.512+0000] {logging_mixin.py:154} INFO - [2023-12-11T00:30:23.505+0000] {dagbag.py:346} ERROR - Failed to import: /opt/airflow/dags/main_de_project_1_dag.py
Traceback (most recent call last):
  File "/home/airflow/.local/lib/python3.8/site-packages/airflow/models/dagbag.py", line 342, in parse
    loader.exec_module(new_module)
  File "<frozen importlib._bootstrap_external>", line 843, in exec_module
  File "<frozen importlib._bootstrap>", line 219, in _call_with_frames_removed
  File "/opt/airflow/dags/main_de_project_1_dag.py", line 11, in <module>
    import create_tables
ModuleNotFoundError: No module named 'create_tables'
[2023-12-11T00:30:23.526+0000] {processor.py:841} WARNING - No viable dags retrieved from /opt/airflow/dags/main_de_project_1_dag.py
[2023-12-11T00:30:23.666+0000] {processor.py:179} INFO - Processing /opt/airflow/dags/main_de_project_1_dag.py took 0.349 seconds
[2023-12-11T00:30:54.266+0000] {processor.py:157} INFO - Started process (PID=4087) to work on /opt/airflow/dags/main_de_project_1_dag.py
[2023-12-11T00:30:54.291+0000] {processor.py:829} INFO - Processing file /opt/airflow/dags/main_de_project_1_dag.py for tasks to queue
[2023-12-11T00:30:54.326+0000] {logging_mixin.py:154} INFO - [2023-12-11T00:30:54.325+0000] {dagbag.py:536} INFO - Filling up the DagBag from /opt/airflow/dags/main_de_project_1_dag.py
[2023-12-11T00:30:54.385+0000] {logging_mixin.py:154} INFO - [2023-12-11T00:30:54.371+0000] {dagbag.py:346} ERROR - Failed to import: /opt/airflow/dags/main_de_project_1_dag.py
Traceback (most recent call last):
  File "/home/airflow/.local/lib/python3.8/site-packages/airflow/models/dagbag.py", line 342, in parse
    loader.exec_module(new_module)
  File "<frozen importlib._bootstrap_external>", line 843, in exec_module
  File "<frozen importlib._bootstrap>", line 219, in _call_with_frames_removed
  File "/opt/airflow/dags/main_de_project_1_dag.py", line 11, in <module>
    import create_tables
ModuleNotFoundError: No module named 'create_tables'
[2023-12-11T00:30:54.389+0000] {processor.py:841} WARNING - No viable dags retrieved from /opt/airflow/dags/main_de_project_1_dag.py
[2023-12-11T00:30:54.581+0000] {processor.py:179} INFO - Processing /opt/airflow/dags/main_de_project_1_dag.py took 0.373 seconds
[2023-12-11T00:31:24.677+0000] {processor.py:157} INFO - Started process (PID=4095) to work on /opt/airflow/dags/main_de_project_1_dag.py
[2023-12-11T00:31:24.682+0000] {processor.py:829} INFO - Processing file /opt/airflow/dags/main_de_project_1_dag.py for tasks to queue
[2023-12-11T00:31:24.695+0000] {logging_mixin.py:154} INFO - [2023-12-11T00:31:24.694+0000] {dagbag.py:536} INFO - Filling up the DagBag from /opt/airflow/dags/main_de_project_1_dag.py
[2023-12-11T00:31:24.726+0000] {logging_mixin.py:154} INFO - [2023-12-11T00:31:24.721+0000] {dagbag.py:346} ERROR - Failed to import: /opt/airflow/dags/main_de_project_1_dag.py
Traceback (most recent call last):
  File "/home/airflow/.local/lib/python3.8/site-packages/airflow/models/dagbag.py", line 342, in parse
    loader.exec_module(new_module)
  File "<frozen importlib._bootstrap_external>", line 843, in exec_module
  File "<frozen importlib._bootstrap>", line 219, in _call_with_frames_removed
  File "/opt/airflow/dags/main_de_project_1_dag.py", line 11, in <module>
    import create_tables
ModuleNotFoundError: No module named 'create_tables'
[2023-12-11T00:31:24.729+0000] {processor.py:841} WARNING - No viable dags retrieved from /opt/airflow/dags/main_de_project_1_dag.py
[2023-12-11T00:31:24.815+0000] {processor.py:179} INFO - Processing /opt/airflow/dags/main_de_project_1_dag.py took 0.146 seconds
[2023-12-11T00:31:54.932+0000] {processor.py:157} INFO - Started process (PID=4103) to work on /opt/airflow/dags/main_de_project_1_dag.py
[2023-12-11T00:31:54.941+0000] {processor.py:829} INFO - Processing file /opt/airflow/dags/main_de_project_1_dag.py for tasks to queue
[2023-12-11T00:31:54.975+0000] {logging_mixin.py:154} INFO - [2023-12-11T00:31:54.974+0000] {dagbag.py:536} INFO - Filling up the DagBag from /opt/airflow/dags/main_de_project_1_dag.py
[2023-12-11T00:31:55.038+0000] {logging_mixin.py:154} INFO - [2023-12-11T00:31:55.034+0000] {dagbag.py:346} ERROR - Failed to import: /opt/airflow/dags/main_de_project_1_dag.py
Traceback (most recent call last):
  File "/home/airflow/.local/lib/python3.8/site-packages/airflow/models/dagbag.py", line 342, in parse
    loader.exec_module(new_module)
  File "<frozen importlib._bootstrap_external>", line 843, in exec_module
  File "<frozen importlib._bootstrap>", line 219, in _call_with_frames_removed
  File "/opt/airflow/dags/main_de_project_1_dag.py", line 11, in <module>
    import create_tables
ModuleNotFoundError: No module named 'create_tables'
[2023-12-11T00:31:55.041+0000] {processor.py:841} WARNING - No viable dags retrieved from /opt/airflow/dags/main_de_project_1_dag.py
[2023-12-11T00:31:55.169+0000] {processor.py:179} INFO - Processing /opt/airflow/dags/main_de_project_1_dag.py took 0.282 seconds
[2023-12-11T00:32:25.514+0000] {processor.py:157} INFO - Started process (PID=4111) to work on /opt/airflow/dags/main_de_project_1_dag.py
[2023-12-11T00:32:25.521+0000] {processor.py:829} INFO - Processing file /opt/airflow/dags/main_de_project_1_dag.py for tasks to queue
[2023-12-11T00:32:25.525+0000] {logging_mixin.py:154} INFO - [2023-12-11T00:32:25.525+0000] {dagbag.py:536} INFO - Filling up the DagBag from /opt/airflow/dags/main_de_project_1_dag.py
[2023-12-11T00:32:25.534+0000] {logging_mixin.py:154} INFO - [2023-12-11T00:32:25.532+0000] {dagbag.py:346} ERROR - Failed to import: /opt/airflow/dags/main_de_project_1_dag.py
Traceback (most recent call last):
  File "/home/airflow/.local/lib/python3.8/site-packages/airflow/models/dagbag.py", line 342, in parse
    loader.exec_module(new_module)
  File "<frozen importlib._bootstrap_external>", line 843, in exec_module
  File "<frozen importlib._bootstrap>", line 219, in _call_with_frames_removed
  File "/opt/airflow/dags/main_de_project_1_dag.py", line 11, in <module>
    import create_tables
ModuleNotFoundError: No module named 'create_tables'
[2023-12-11T00:32:25.535+0000] {processor.py:841} WARNING - No viable dags retrieved from /opt/airflow/dags/main_de_project_1_dag.py
[2023-12-11T00:32:25.586+0000] {processor.py:179} INFO - Processing /opt/airflow/dags/main_de_project_1_dag.py took 0.080 seconds
[2023-12-11T00:32:55.700+0000] {processor.py:157} INFO - Started process (PID=4119) to work on /opt/airflow/dags/main_de_project_1_dag.py
[2023-12-11T00:32:55.703+0000] {processor.py:829} INFO - Processing file /opt/airflow/dags/main_de_project_1_dag.py for tasks to queue
[2023-12-11T00:32:55.718+0000] {logging_mixin.py:154} INFO - [2023-12-11T00:32:55.717+0000] {dagbag.py:536} INFO - Filling up the DagBag from /opt/airflow/dags/main_de_project_1_dag.py
[2023-12-11T00:32:55.734+0000] {logging_mixin.py:154} INFO - [2023-12-11T00:32:55.731+0000] {dagbag.py:346} ERROR - Failed to import: /opt/airflow/dags/main_de_project_1_dag.py
Traceback (most recent call last):
  File "/home/airflow/.local/lib/python3.8/site-packages/airflow/models/dagbag.py", line 342, in parse
    loader.exec_module(new_module)
  File "<frozen importlib._bootstrap_external>", line 843, in exec_module
  File "<frozen importlib._bootstrap>", line 219, in _call_with_frames_removed
  File "/opt/airflow/dags/main_de_project_1_dag.py", line 11, in <module>
    import create_tables
ModuleNotFoundError: No module named 'create_tables'
[2023-12-11T00:32:55.735+0000] {processor.py:841} WARNING - No viable dags retrieved from /opt/airflow/dags/main_de_project_1_dag.py
[2023-12-11T00:32:55.776+0000] {processor.py:179} INFO - Processing /opt/airflow/dags/main_de_project_1_dag.py took 0.084 seconds
[2023-12-11T00:33:26.047+0000] {processor.py:157} INFO - Started process (PID=4126) to work on /opt/airflow/dags/main_de_project_1_dag.py
[2023-12-11T00:33:26.054+0000] {processor.py:829} INFO - Processing file /opt/airflow/dags/main_de_project_1_dag.py for tasks to queue
[2023-12-11T00:33:26.060+0000] {logging_mixin.py:154} INFO - [2023-12-11T00:33:26.059+0000] {dagbag.py:536} INFO - Filling up the DagBag from /opt/airflow/dags/main_de_project_1_dag.py
[2023-12-11T00:33:26.094+0000] {logging_mixin.py:154} INFO - [2023-12-11T00:33:26.091+0000] {dagbag.py:346} ERROR - Failed to import: /opt/airflow/dags/main_de_project_1_dag.py
Traceback (most recent call last):
  File "/home/airflow/.local/lib/python3.8/site-packages/airflow/models/dagbag.py", line 342, in parse
    loader.exec_module(new_module)
  File "<frozen importlib._bootstrap_external>", line 843, in exec_module
  File "<frozen importlib._bootstrap>", line 219, in _call_with_frames_removed
  File "/opt/airflow/dags/main_de_project_1_dag.py", line 11, in <module>
    import create_tables
ModuleNotFoundError: No module named 'create_tables'
[2023-12-11T00:33:26.095+0000] {processor.py:841} WARNING - No viable dags retrieved from /opt/airflow/dags/main_de_project_1_dag.py
[2023-12-11T00:33:26.138+0000] {processor.py:179} INFO - Processing /opt/airflow/dags/main_de_project_1_dag.py took 0.105 seconds
[2023-12-11T00:33:56.686+0000] {processor.py:157} INFO - Started process (PID=4134) to work on /opt/airflow/dags/main_de_project_1_dag.py
[2023-12-11T00:33:56.693+0000] {processor.py:829} INFO - Processing file /opt/airflow/dags/main_de_project_1_dag.py for tasks to queue
[2023-12-11T00:33:56.700+0000] {logging_mixin.py:154} INFO - [2023-12-11T00:33:56.699+0000] {dagbag.py:536} INFO - Filling up the DagBag from /opt/airflow/dags/main_de_project_1_dag.py
[2023-12-11T00:33:56.716+0000] {logging_mixin.py:154} INFO - [2023-12-11T00:33:56.714+0000] {dagbag.py:346} ERROR - Failed to import: /opt/airflow/dags/main_de_project_1_dag.py
Traceback (most recent call last):
  File "/home/airflow/.local/lib/python3.8/site-packages/airflow/models/dagbag.py", line 342, in parse
    loader.exec_module(new_module)
  File "<frozen importlib._bootstrap_external>", line 843, in exec_module
  File "<frozen importlib._bootstrap>", line 219, in _call_with_frames_removed
  File "/opt/airflow/dags/main_de_project_1_dag.py", line 11, in <module>
    import create_tables
ModuleNotFoundError: No module named 'create_tables'
[2023-12-11T00:33:56.718+0000] {processor.py:841} WARNING - No viable dags retrieved from /opt/airflow/dags/main_de_project_1_dag.py
[2023-12-11T00:33:56.786+0000] {processor.py:179} INFO - Processing /opt/airflow/dags/main_de_project_1_dag.py took 0.105 seconds
[2023-12-11T01:04:00.676+0000] {processor.py:157} INFO - Started process (PID=4143) to work on /opt/airflow/dags/main_de_project_1_dag.py
[2023-12-11T01:04:00.699+0000] {processor.py:829} INFO - Processing file /opt/airflow/dags/main_de_project_1_dag.py for tasks to queue
[2023-12-11T01:04:00.751+0000] {logging_mixin.py:154} INFO - [2023-12-11T01:04:00.750+0000] {dagbag.py:536} INFO - Filling up the DagBag from /opt/airflow/dags/main_de_project_1_dag.py
[2023-12-11T01:04:00.919+0000] {logging_mixin.py:154} INFO - [2023-12-11T01:04:00.894+0000] {dagbag.py:346} ERROR - Failed to import: /opt/airflow/dags/main_de_project_1_dag.py
Traceback (most recent call last):
  File "/home/airflow/.local/lib/python3.8/site-packages/airflow/models/dagbag.py", line 342, in parse
    loader.exec_module(new_module)
  File "<frozen importlib._bootstrap_external>", line 843, in exec_module
  File "<frozen importlib._bootstrap>", line 219, in _call_with_frames_removed
  File "/opt/airflow/dags/main_de_project_1_dag.py", line 11, in <module>
    import create_tables
ModuleNotFoundError: No module named 'create_tables'
[2023-12-11T01:04:00.933+0000] {processor.py:841} WARNING - No viable dags retrieved from /opt/airflow/dags/main_de_project_1_dag.py
[2023-12-11T01:04:01.009+0000] {processor.py:179} INFO - Processing /opt/airflow/dags/main_de_project_1_dag.py took 0.350 seconds
[2023-12-11T01:05:04.366+0000] {processor.py:157} INFO - Started process (PID=4144) to work on /opt/airflow/dags/main_de_project_1_dag.py
[2023-12-11T01:05:04.951+0000] {processor.py:829} INFO - Processing file /opt/airflow/dags/main_de_project_1_dag.py for tasks to queue
[2023-12-11T01:05:05.334+0000] {logging_mixin.py:154} INFO - [2023-12-11T01:05:05.281+0000] {dagbag.py:536} INFO - Filling up the DagBag from /opt/airflow/dags/main_de_project_1_dag.py
[2023-12-11T01:05:06.912+0000] {logging_mixin.py:154} INFO - [2023-12-11T01:05:06.500+0000] {dagbag.py:346} ERROR - Failed to import: /opt/airflow/dags/main_de_project_1_dag.py
Traceback (most recent call last):
  File "/home/airflow/.local/lib/python3.8/site-packages/airflow/models/dagbag.py", line 342, in parse
    loader.exec_module(new_module)
  File "<frozen importlib._bootstrap_external>", line 843, in exec_module
  File "<frozen importlib._bootstrap>", line 219, in _call_with_frames_removed
  File "/opt/airflow/dags/main_de_project_1_dag.py", line 11, in <module>
    import create_tables
ModuleNotFoundError: No module named 'create_tables'
[2023-12-11T01:05:07.046+0000] {processor.py:841} WARNING - No viable dags retrieved from /opt/airflow/dags/main_de_project_1_dag.py
[2023-12-11T01:05:09.316+0000] {processor.py:179} INFO - Processing /opt/airflow/dags/main_de_project_1_dag.py took 14.444 seconds
[2023-12-11T01:05:40.864+0000] {processor.py:157} INFO - Started process (PID=4158) to work on /opt/airflow/dags/main_de_project_1_dag.py
[2023-12-11T01:05:40.941+0000] {processor.py:829} INFO - Processing file /opt/airflow/dags/main_de_project_1_dag.py for tasks to queue
[2023-12-11T01:05:41.074+0000] {logging_mixin.py:154} INFO - [2023-12-11T01:05:41.073+0000] {dagbag.py:536} INFO - Filling up the DagBag from /opt/airflow/dags/main_de_project_1_dag.py
[2023-12-11T01:05:41.377+0000] {logging_mixin.py:154} INFO - [2023-12-11T01:05:41.313+0000] {dagbag.py:346} ERROR - Failed to import: /opt/airflow/dags/main_de_project_1_dag.py
Traceback (most recent call last):
  File "/home/airflow/.local/lib/python3.8/site-packages/airflow/models/dagbag.py", line 342, in parse
    loader.exec_module(new_module)
  File "<frozen importlib._bootstrap_external>", line 843, in exec_module
  File "<frozen importlib._bootstrap>", line 219, in _call_with_frames_removed
  File "/opt/airflow/dags/main_de_project_1_dag.py", line 11, in <module>
    import create_tables
ModuleNotFoundError: No module named 'create_tables'
[2023-12-11T01:05:41.428+0000] {processor.py:841} WARNING - No viable dags retrieved from /opt/airflow/dags/main_de_project_1_dag.py
[2023-12-11T01:05:41.937+0000] {processor.py:179} INFO - Processing /opt/airflow/dags/main_de_project_1_dag.py took 1.166 seconds
[2023-12-11T01:06:12.911+0000] {processor.py:157} INFO - Started process (PID=4166) to work on /opt/airflow/dags/main_de_project_1_dag.py
[2023-12-11T01:06:12.925+0000] {processor.py:829} INFO - Processing file /opt/airflow/dags/main_de_project_1_dag.py for tasks to queue
[2023-12-11T01:06:12.945+0000] {logging_mixin.py:154} INFO - [2023-12-11T01:06:12.940+0000] {dagbag.py:536} INFO - Filling up the DagBag from /opt/airflow/dags/main_de_project_1_dag.py
[2023-12-11T01:06:12.985+0000] {logging_mixin.py:154} INFO - [2023-12-11T01:06:12.971+0000] {dagbag.py:346} ERROR - Failed to import: /opt/airflow/dags/main_de_project_1_dag.py
Traceback (most recent call last):
  File "/home/airflow/.local/lib/python3.8/site-packages/airflow/models/dagbag.py", line 342, in parse
    loader.exec_module(new_module)
  File "<frozen importlib._bootstrap_external>", line 843, in exec_module
  File "<frozen importlib._bootstrap>", line 219, in _call_with_frames_removed
  File "/opt/airflow/dags/main_de_project_1_dag.py", line 11, in <module>
    import create_tables
ModuleNotFoundError: No module named 'create_tables'
[2023-12-11T01:06:12.992+0000] {processor.py:841} WARNING - No viable dags retrieved from /opt/airflow/dags/main_de_project_1_dag.py
[2023-12-11T01:06:13.388+0000] {processor.py:179} INFO - Processing /opt/airflow/dags/main_de_project_1_dag.py took 0.501 seconds
[2023-12-11T01:06:44.631+0000] {processor.py:157} INFO - Started process (PID=4174) to work on /opt/airflow/dags/main_de_project_1_dag.py
[2023-12-11T01:06:44.744+0000] {processor.py:829} INFO - Processing file /opt/airflow/dags/main_de_project_1_dag.py for tasks to queue
[2023-12-11T01:06:44.840+0000] {logging_mixin.py:154} INFO - [2023-12-11T01:06:44.838+0000] {dagbag.py:536} INFO - Filling up the DagBag from /opt/airflow/dags/main_de_project_1_dag.py
[2023-12-11T01:06:44.966+0000] {logging_mixin.py:154} INFO - [2023-12-11T01:06:44.934+0000] {dagbag.py:346} ERROR - Failed to import: /opt/airflow/dags/main_de_project_1_dag.py
Traceback (most recent call last):
  File "/home/airflow/.local/lib/python3.8/site-packages/airflow/models/dagbag.py", line 342, in parse
    loader.exec_module(new_module)
  File "<frozen importlib._bootstrap_external>", line 843, in exec_module
  File "<frozen importlib._bootstrap>", line 219, in _call_with_frames_removed
  File "/opt/airflow/dags/main_de_project_1_dag.py", line 11, in <module>
    import create_tables
ModuleNotFoundError: No module named 'create_tables'
[2023-12-11T01:06:44.971+0000] {processor.py:841} WARNING - No viable dags retrieved from /opt/airflow/dags/main_de_project_1_dag.py
[2023-12-11T01:06:45.385+0000] {processor.py:179} INFO - Processing /opt/airflow/dags/main_de_project_1_dag.py took 1.082 seconds
[2023-12-11T01:07:16.503+0000] {processor.py:157} INFO - Started process (PID=4182) to work on /opt/airflow/dags/main_de_project_1_dag.py
[2023-12-11T01:07:16.508+0000] {processor.py:829} INFO - Processing file /opt/airflow/dags/main_de_project_1_dag.py for tasks to queue
[2023-12-11T01:07:16.559+0000] {logging_mixin.py:154} INFO - [2023-12-11T01:07:16.557+0000] {dagbag.py:536} INFO - Filling up the DagBag from /opt/airflow/dags/main_de_project_1_dag.py
[2023-12-11T01:07:16.733+0000] {logging_mixin.py:154} INFO - [2023-12-11T01:07:16.701+0000] {dagbag.py:346} ERROR - Failed to import: /opt/airflow/dags/main_de_project_1_dag.py
Traceback (most recent call last):
  File "/home/airflow/.local/lib/python3.8/site-packages/airflow/models/dagbag.py", line 342, in parse
    loader.exec_module(new_module)
  File "<frozen importlib._bootstrap_external>", line 843, in exec_module
  File "<frozen importlib._bootstrap>", line 219, in _call_with_frames_removed
  File "/opt/airflow/dags/main_de_project_1_dag.py", line 11, in <module>
    import create_tables
ModuleNotFoundError: No module named 'create_tables'
[2023-12-11T01:07:16.760+0000] {processor.py:841} WARNING - No viable dags retrieved from /opt/airflow/dags/main_de_project_1_dag.py
[2023-12-11T01:07:17.482+0000] {processor.py:179} INFO - Processing /opt/airflow/dags/main_de_project_1_dag.py took 1.166 seconds
[2023-12-11T01:08:31.387+0000] {processor.py:157} INFO - Started process (PID=4183) to work on /opt/airflow/dags/main_de_project_1_dag.py
[2023-12-11T01:08:31.604+0000] {processor.py:829} INFO - Processing file /opt/airflow/dags/main_de_project_1_dag.py for tasks to queue
[2023-12-11T01:08:32.192+0000] {logging_mixin.py:154} INFO - [2023-12-11T01:08:32.191+0000] {dagbag.py:536} INFO - Filling up the DagBag from /opt/airflow/dags/main_de_project_1_dag.py
[2023-12-11T01:08:32.662+0000] {logging_mixin.py:154} INFO - [2023-12-11T01:08:32.609+0000] {dagbag.py:346} ERROR - Failed to import: /opt/airflow/dags/main_de_project_1_dag.py
Traceback (most recent call last):
  File "/home/airflow/.local/lib/python3.8/site-packages/airflow/models/dagbag.py", line 342, in parse
    loader.exec_module(new_module)
  File "<frozen importlib._bootstrap_external>", line 843, in exec_module
  File "<frozen importlib._bootstrap>", line 219, in _call_with_frames_removed
  File "/opt/airflow/dags/main_de_project_1_dag.py", line 11, in <module>
    import create_tables
ModuleNotFoundError: No module named 'create_tables'
[2023-12-11T01:08:32.691+0000] {processor.py:841} WARNING - No viable dags retrieved from /opt/airflow/dags/main_de_project_1_dag.py
[2023-12-11T01:08:33.613+0000] {processor.py:179} INFO - Processing /opt/airflow/dags/main_de_project_1_dag.py took 2.856 seconds
[2023-12-11T01:10:56.371+0000] {processor.py:157} INFO - Started process (PID=4184) to work on /opt/airflow/dags/main_de_project_1_dag.py
[2023-12-11T01:10:56.443+0000] {processor.py:829} INFO - Processing file /opt/airflow/dags/main_de_project_1_dag.py for tasks to queue
[2023-12-11T01:10:56.860+0000] {logging_mixin.py:154} INFO - [2023-12-11T01:10:56.653+0000] {dagbag.py:536} INFO - Filling up the DagBag from /opt/airflow/dags/main_de_project_1_dag.py
[2023-12-11T01:11:29.051+0000] {logging_mixin.py:154} INFO - [2023-12-11T01:11:21.765+0000] {dagbag.py:346} ERROR - Failed to import: /opt/airflow/dags/main_de_project_1_dag.py
Traceback (most recent call last):
  File "/home/airflow/.local/lib/python3.8/site-packages/airflow/models/dagbag.py", line 342, in parse
    loader.exec_module(new_module)
  File "<frozen importlib._bootstrap_external>", line 843, in exec_module
  File "<frozen importlib._bootstrap>", line 219, in _call_with_frames_removed
  File "/opt/airflow/dags/main_de_project_1_dag.py", line 11, in <module>
    import create_tables
ModuleNotFoundError: No module named 'create_tables'
[2023-12-11T01:11:29.335+0000] {processor.py:841} WARNING - No viable dags retrieved from /opt/airflow/dags/main_de_project_1_dag.py
[2023-12-11T01:27:12.121+0000] {processor.py:182} ERROR - Got an exception! Propagating...
Traceback (most recent call last):
  File "/home/airflow/.local/lib/python3.8/site-packages/sqlalchemy/engine/base.py", line 3371, in _wrap_pool_connect
    return fn()
  File "/home/airflow/.local/lib/python3.8/site-packages/sqlalchemy/pool/base.py", line 327, in connect
    return _ConnectionFairy._checkout(self)
  File "/home/airflow/.local/lib/python3.8/site-packages/sqlalchemy/pool/base.py", line 894, in _checkout
    fairy = _ConnectionRecord.checkout(pool)
  File "/home/airflow/.local/lib/python3.8/site-packages/sqlalchemy/pool/base.py", line 493, in checkout
    rec = pool._do_get()
  File "/home/airflow/.local/lib/python3.8/site-packages/sqlalchemy/pool/impl.py", line 146, in _do_get
    self._dec_overflow()
  File "/home/airflow/.local/lib/python3.8/site-packages/sqlalchemy/util/langhelpers.py", line 70, in __exit__
    compat.raise_(
  File "/home/airflow/.local/lib/python3.8/site-packages/sqlalchemy/util/compat.py", line 211, in raise_
    raise exception
  File "/home/airflow/.local/lib/python3.8/site-packages/sqlalchemy/pool/impl.py", line 143, in _do_get
    return self._create_connection()
  File "/home/airflow/.local/lib/python3.8/site-packages/sqlalchemy/pool/base.py", line 273, in _create_connection
    return _ConnectionRecord(self)
  File "/home/airflow/.local/lib/python3.8/site-packages/sqlalchemy/pool/base.py", line 388, in __init__
    self.__connect()
  File "/home/airflow/.local/lib/python3.8/site-packages/sqlalchemy/pool/base.py", line 691, in __connect
    pool.logger.debug("Error on connect(): %s", e)
  File "/home/airflow/.local/lib/python3.8/site-packages/sqlalchemy/util/langhelpers.py", line 70, in __exit__
    compat.raise_(
  File "/home/airflow/.local/lib/python3.8/site-packages/sqlalchemy/util/compat.py", line 211, in raise_
    raise exception
  File "/home/airflow/.local/lib/python3.8/site-packages/sqlalchemy/pool/base.py", line 686, in __connect
    self.dbapi_connection = connection = pool._invoke_creator(self)
  File "/home/airflow/.local/lib/python3.8/site-packages/sqlalchemy/engine/create.py", line 574, in connect
    return dialect.connect(*cargs, **cparams)
  File "/home/airflow/.local/lib/python3.8/site-packages/sqlalchemy/engine/default.py", line 598, in connect
    return self.dbapi.connect(*cargs, **cparams)
  File "/home/airflow/.local/lib/python3.8/site-packages/psycopg2/__init__.py", line 122, in connect
    conn = _connect(dsn, connection_factory=connection_factory, **kwasync)
psycopg2.OperationalError: could not translate host name "postgres" to address: Temporary failure in name resolution


The above exception was the direct cause of the following exception:

Traceback (most recent call last):
  File "/home/airflow/.local/lib/python3.8/site-packages/airflow/dag_processing/processor.py", line 178, in _run_file_processor
    _handle_dag_file_processing()
  File "/home/airflow/.local/lib/python3.8/site-packages/airflow/dag_processing/processor.py", line 159, in _handle_dag_file_processing
    result: tuple[int, int] = dag_file_processor.process_file(
  File "/home/airflow/.local/lib/python3.8/site-packages/airflow/utils/session.py", line 79, in wrapper
    return func(*args, session=session, **kwargs)
  File "/home/airflow/.local/lib/python3.8/site-packages/airflow/dag_processing/processor.py", line 842, in process_file
    DagFileProcessor.update_import_errors(
  File "/home/airflow/.local/lib/python3.8/site-packages/airflow/api_internal/internal_api_call.py", line 114, in wrapper
    return func(*args, **kwargs)
  File "/home/airflow/.local/lib/python3.8/site-packages/airflow/utils/session.py", line 76, in wrapper
    return func(*args, **kwargs)
  File "/home/airflow/.local/lib/python3.8/site-packages/airflow/dag_processing/processor.py", line 625, in update_import_errors
    existing_import_error_files = [x.filename for x in session.query(errors.ImportError.filename).all()]
  File "/home/airflow/.local/lib/python3.8/site-packages/sqlalchemy/orm/query.py", line 2773, in all
    return self._iter().all()
  File "/home/airflow/.local/lib/python3.8/site-packages/sqlalchemy/orm/query.py", line 2916, in _iter
    result = self.session.execute(
  File "/home/airflow/.local/lib/python3.8/site-packages/sqlalchemy/orm/session.py", line 1716, in execute
    conn = self._connection_for_bind(bind)
  File "/home/airflow/.local/lib/python3.8/site-packages/sqlalchemy/orm/session.py", line 1555, in _connection_for_bind
    return self._transaction._connection_for_bind(
  File "/home/airflow/.local/lib/python3.8/site-packages/sqlalchemy/orm/session.py", line 750, in _connection_for_bind
    conn = bind.connect()
  File "/home/airflow/.local/lib/python3.8/site-packages/sqlalchemy/future/engine.py", line 406, in connect
    return super(Engine, self).connect()
  File "/home/airflow/.local/lib/python3.8/site-packages/sqlalchemy/engine/base.py", line 3325, in connect
    return self._connection_cls(self, close_with_result=close_with_result)
  File "/home/airflow/.local/lib/python3.8/site-packages/sqlalchemy/engine/base.py", line 96, in __init__
    else engine.raw_connection()
  File "/home/airflow/.local/lib/python3.8/site-packages/sqlalchemy/engine/base.py", line 3404, in raw_connection
    return self._wrap_pool_connect(self.pool.connect, _connection)
  File "/home/airflow/.local/lib/python3.8/site-packages/sqlalchemy/engine/base.py", line 3374, in _wrap_pool_connect
    Connection._handle_dbapi_exception_noconnection(
  File "/home/airflow/.local/lib/python3.8/site-packages/sqlalchemy/engine/base.py", line 2208, in _handle_dbapi_exception_noconnection
    util.raise_(
  File "/home/airflow/.local/lib/python3.8/site-packages/sqlalchemy/util/compat.py", line 211, in raise_
    raise exception
  File "/home/airflow/.local/lib/python3.8/site-packages/sqlalchemy/engine/base.py", line 3371, in _wrap_pool_connect
    return fn()
  File "/home/airflow/.local/lib/python3.8/site-packages/sqlalchemy/pool/base.py", line 327, in connect
    return _ConnectionFairy._checkout(self)
  File "/home/airflow/.local/lib/python3.8/site-packages/sqlalchemy/pool/base.py", line 894, in _checkout
    fairy = _ConnectionRecord.checkout(pool)
  File "/home/airflow/.local/lib/python3.8/site-packages/sqlalchemy/pool/base.py", line 493, in checkout
    rec = pool._do_get()
  File "/home/airflow/.local/lib/python3.8/site-packages/sqlalchemy/pool/impl.py", line 146, in _do_get
    self._dec_overflow()
  File "/home/airflow/.local/lib/python3.8/site-packages/sqlalchemy/util/langhelpers.py", line 70, in __exit__
    compat.raise_(
  File "/home/airflow/.local/lib/python3.8/site-packages/sqlalchemy/util/compat.py", line 211, in raise_
    raise exception
  File "/home/airflow/.local/lib/python3.8/site-packages/sqlalchemy/pool/impl.py", line 143, in _do_get
    return self._create_connection()
  File "/home/airflow/.local/lib/python3.8/site-packages/sqlalchemy/pool/base.py", line 273, in _create_connection
    return _ConnectionRecord(self)
  File "/home/airflow/.local/lib/python3.8/site-packages/sqlalchemy/pool/base.py", line 388, in __init__
    self.__connect()
  File "/home/airflow/.local/lib/python3.8/site-packages/sqlalchemy/pool/base.py", line 691, in __connect
    pool.logger.debug("Error on connect(): %s", e)
  File "/home/airflow/.local/lib/python3.8/site-packages/sqlalchemy/util/langhelpers.py", line 70, in __exit__
    compat.raise_(
  File "/home/airflow/.local/lib/python3.8/site-packages/sqlalchemy/util/compat.py", line 211, in raise_
    raise exception
  File "/home/airflow/.local/lib/python3.8/site-packages/sqlalchemy/pool/base.py", line 686, in __connect
    self.dbapi_connection = connection = pool._invoke_creator(self)
  File "/home/airflow/.local/lib/python3.8/site-packages/sqlalchemy/engine/create.py", line 574, in connect
    return dialect.connect(*cargs, **cparams)
  File "/home/airflow/.local/lib/python3.8/site-packages/sqlalchemy/engine/default.py", line 598, in connect
    return self.dbapi.connect(*cargs, **cparams)
  File "/home/airflow/.local/lib/python3.8/site-packages/psycopg2/__init__.py", line 122, in connect
    conn = _connect(dsn, connection_factory=connection_factory, **kwasync)
sqlalchemy.exc.OperationalError: (psycopg2.OperationalError) could not translate host name "postgres" to address: Temporary failure in name resolution

(Background on this error at: https://sqlalche.me/e/14/e3q8)
[2023-12-11T01:28:39.966+0000] {processor.py:157} INFO - Started process (PID=4185) to work on /opt/airflow/dags/main_de_project_1_dag.py
[2023-12-11T01:28:40.032+0000] {processor.py:829} INFO - Processing file /opt/airflow/dags/main_de_project_1_dag.py for tasks to queue
[2023-12-11T01:28:40.729+0000] {logging_mixin.py:154} INFO - [2023-12-11T01:28:40.656+0000] {dagbag.py:536} INFO - Filling up the DagBag from /opt/airflow/dags/main_de_project_1_dag.py
[2023-12-11T01:28:41.675+0000] {logging_mixin.py:154} INFO - [2023-12-11T01:28:41.146+0000] {dagbag.py:346} ERROR - Failed to import: /opt/airflow/dags/main_de_project_1_dag.py
Traceback (most recent call last):
  File "/home/airflow/.local/lib/python3.8/site-packages/airflow/models/dagbag.py", line 342, in parse
    loader.exec_module(new_module)
  File "<frozen importlib._bootstrap_external>", line 843, in exec_module
  File "<frozen importlib._bootstrap>", line 219, in _call_with_frames_removed
  File "/opt/airflow/dags/main_de_project_1_dag.py", line 11, in <module>
    import create_tables
ModuleNotFoundError: No module named 'create_tables'
[2023-12-11T01:28:42.124+0000] {processor.py:841} WARNING - No viable dags retrieved from /opt/airflow/dags/main_de_project_1_dag.py
[2023-12-11T01:28:46.203+0000] {processor.py:179} INFO - Processing /opt/airflow/dags/main_de_project_1_dag.py took 7.467 seconds
[2023-12-11T01:29:26.204+0000] {processor.py:157} INFO - Started process (PID=4192) to work on /opt/airflow/dags/main_de_project_1_dag.py
[2023-12-11T01:29:26.294+0000] {processor.py:829} INFO - Processing file /opt/airflow/dags/main_de_project_1_dag.py for tasks to queue
[2023-12-11T01:29:26.984+0000] {logging_mixin.py:154} INFO - [2023-12-11T01:29:26.799+0000] {dagbag.py:536} INFO - Filling up the DagBag from /opt/airflow/dags/main_de_project_1_dag.py
[2023-12-11T01:29:27.521+0000] {logging_mixin.py:154} INFO - [2023-12-11T01:29:27.443+0000] {dagbag.py:346} ERROR - Failed to import: /opt/airflow/dags/main_de_project_1_dag.py
Traceback (most recent call last):
  File "/home/airflow/.local/lib/python3.8/site-packages/airflow/models/dagbag.py", line 342, in parse
    loader.exec_module(new_module)
  File "<frozen importlib._bootstrap_external>", line 843, in exec_module
  File "<frozen importlib._bootstrap>", line 219, in _call_with_frames_removed
  File "/opt/airflow/dags/main_de_project_1_dag.py", line 11, in <module>
    import create_tables
ModuleNotFoundError: No module named 'create_tables'
[2023-12-11T01:29:27.544+0000] {processor.py:841} WARNING - No viable dags retrieved from /opt/airflow/dags/main_de_project_1_dag.py
[2023-12-11T01:29:35.085+0000] {processor.py:179} INFO - Processing /opt/airflow/dags/main_de_project_1_dag.py took 13.340 seconds
[2023-12-11T01:30:07.695+0000] {processor.py:157} INFO - Started process (PID=4201) to work on /opt/airflow/dags/main_de_project_1_dag.py
[2023-12-11T01:30:07.831+0000] {processor.py:829} INFO - Processing file /opt/airflow/dags/main_de_project_1_dag.py for tasks to queue
[2023-12-11T01:30:08.007+0000] {logging_mixin.py:154} INFO - [2023-12-11T01:30:08.006+0000] {dagbag.py:536} INFO - Filling up the DagBag from /opt/airflow/dags/main_de_project_1_dag.py
[2023-12-11T01:30:08.358+0000] {logging_mixin.py:154} INFO - [2023-12-11T01:30:08.327+0000] {dagbag.py:346} ERROR - Failed to import: /opt/airflow/dags/main_de_project_1_dag.py
Traceback (most recent call last):
  File "/home/airflow/.local/lib/python3.8/site-packages/airflow/models/dagbag.py", line 342, in parse
    loader.exec_module(new_module)
  File "<frozen importlib._bootstrap_external>", line 843, in exec_module
  File "<frozen importlib._bootstrap>", line 219, in _call_with_frames_removed
  File "/opt/airflow/dags/main_de_project_1_dag.py", line 11, in <module>
    import create_tables
ModuleNotFoundError: No module named 'create_tables'
[2023-12-11T01:30:08.367+0000] {processor.py:841} WARNING - No viable dags retrieved from /opt/airflow/dags/main_de_project_1_dag.py
[2023-12-11T01:30:09.213+0000] {processor.py:179} INFO - Processing /opt/airflow/dags/main_de_project_1_dag.py took 2.027 seconds
[2023-12-11T01:31:21.348+0000] {processor.py:157} INFO - Started process (PID=4202) to work on /opt/airflow/dags/main_de_project_1_dag.py
[2023-12-11T01:31:21.407+0000] {processor.py:829} INFO - Processing file /opt/airflow/dags/main_de_project_1_dag.py for tasks to queue
[2023-12-11T01:31:21.559+0000] {logging_mixin.py:154} INFO - [2023-12-11T01:31:21.491+0000] {dagbag.py:536} INFO - Filling up the DagBag from /opt/airflow/dags/main_de_project_1_dag.py
[2023-12-11T01:31:24.431+0000] {logging_mixin.py:154} INFO - [2023-12-11T01:31:23.618+0000] {dagbag.py:346} ERROR - Failed to import: /opt/airflow/dags/main_de_project_1_dag.py
Traceback (most recent call last):
  File "/home/airflow/.local/lib/python3.8/site-packages/airflow/models/dagbag.py", line 342, in parse
    loader.exec_module(new_module)
  File "<frozen importlib._bootstrap_external>", line 843, in exec_module
  File "<frozen importlib._bootstrap>", line 219, in _call_with_frames_removed
  File "/opt/airflow/dags/main_de_project_1_dag.py", line 11, in <module>
    import create_tables
ModuleNotFoundError: No module named 'create_tables'
[2023-12-11T01:31:24.454+0000] {processor.py:841} WARNING - No viable dags retrieved from /opt/airflow/dags/main_de_project_1_dag.py
[2023-12-11T01:31:25.622+0000] {processor.py:179} INFO - Processing /opt/airflow/dags/main_de_project_1_dag.py took 4.328 seconds
[2023-12-11T01:32:39.559+0000] {processor.py:157} INFO - Started process (PID=4211) to work on /opt/airflow/dags/main_de_project_1_dag.py
[2023-12-11T01:32:39.606+0000] {processor.py:829} INFO - Processing file /opt/airflow/dags/main_de_project_1_dag.py for tasks to queue
[2023-12-11T01:32:39.770+0000] {logging_mixin.py:154} INFO - [2023-12-11T01:32:39.750+0000] {dagbag.py:536} INFO - Filling up the DagBag from /opt/airflow/dags/main_de_project_1_dag.py
[2023-12-11T01:32:40.092+0000] {logging_mixin.py:154} INFO - [2023-12-11T01:32:40.023+0000] {dagbag.py:346} ERROR - Failed to import: /opt/airflow/dags/main_de_project_1_dag.py
Traceback (most recent call last):
  File "/home/airflow/.local/lib/python3.8/site-packages/airflow/models/dagbag.py", line 342, in parse
    loader.exec_module(new_module)
  File "<frozen importlib._bootstrap_external>", line 843, in exec_module
  File "<frozen importlib._bootstrap>", line 219, in _call_with_frames_removed
  File "/opt/airflow/dags/main_de_project_1_dag.py", line 11, in <module>
    import create_tables
ModuleNotFoundError: No module named 'create_tables'
[2023-12-11T01:32:40.100+0000] {processor.py:841} WARNING - No viable dags retrieved from /opt/airflow/dags/main_de_project_1_dag.py
[2023-12-11T01:32:40.736+0000] {processor.py:179} INFO - Processing /opt/airflow/dags/main_de_project_1_dag.py took 1.702 seconds
[2023-12-11T01:33:12.559+0000] {processor.py:157} INFO - Started process (PID=4225) to work on /opt/airflow/dags/main_de_project_1_dag.py
[2023-12-11T01:33:12.597+0000] {processor.py:829} INFO - Processing file /opt/airflow/dags/main_de_project_1_dag.py for tasks to queue
[2023-12-11T01:33:12.664+0000] {logging_mixin.py:154} INFO - [2023-12-11T01:33:12.657+0000] {dagbag.py:536} INFO - Filling up the DagBag from /opt/airflow/dags/main_de_project_1_dag.py
[2023-12-11T01:33:12.757+0000] {logging_mixin.py:154} INFO - [2023-12-11T01:33:12.723+0000] {dagbag.py:346} ERROR - Failed to import: /opt/airflow/dags/main_de_project_1_dag.py
Traceback (most recent call last):
  File "/home/airflow/.local/lib/python3.8/site-packages/airflow/models/dagbag.py", line 342, in parse
    loader.exec_module(new_module)
  File "<frozen importlib._bootstrap_external>", line 843, in exec_module
  File "<frozen importlib._bootstrap>", line 219, in _call_with_frames_removed
  File "/opt/airflow/dags/main_de_project_1_dag.py", line 11, in <module>
    import create_tables
ModuleNotFoundError: No module named 'create_tables'
[2023-12-11T01:33:12.783+0000] {processor.py:841} WARNING - No viable dags retrieved from /opt/airflow/dags/main_de_project_1_dag.py
[2023-12-11T01:33:13.135+0000] {processor.py:179} INFO - Processing /opt/airflow/dags/main_de_project_1_dag.py took 0.737 seconds
[2023-12-11T02:05:09.084+0000] {processor.py:157} INFO - Started process (PID=4226) to work on /opt/airflow/dags/main_de_project_1_dag.py
[2023-12-11T02:05:17.393+0000] {processor.py:829} INFO - Processing file /opt/airflow/dags/main_de_project_1_dag.py for tasks to queue
[2023-12-11T02:05:26.388+0000] {logging_mixin.py:154} INFO - [2023-12-11T02:05:25.251+0000] {dagbag.py:536} INFO - Filling up the DagBag from /opt/airflow/dags/main_de_project_1_dag.py
[2023-12-11T02:06:41.366+0000] {logging_mixin.py:154} INFO - [2023-12-11T02:06:12.766+0000] {timeout.py:68} ERROR - Process timed out, PID: 4226
[2023-12-11T02:07:05.245+0000] {logging_mixin.py:154} WARNING - --- Logging error ---
[2023-12-11T02:07:17.988+0000] {logging_mixin.py:154} WARNING - Traceback (most recent call last):
[2023-12-11T02:07:27.359+0000] {logging_mixin.py:154} WARNING -   File "/home/airflow/.local/lib/python3.8/site-packages/airflow/models/dagbag.py", line 342, in parse
    loader.exec_module(new_module)
[2023-12-11T02:07:39.051+0000] {logging_mixin.py:154} WARNING -   File "<frozen importlib._bootstrap_external>", line 843, in exec_module
[2023-12-11T02:07:41.861+0000] {logging_mixin.py:154} WARNING -   File "<frozen importlib._bootstrap>", line 219, in _call_with_frames_removed
[2023-12-11T02:07:41.960+0000] {logging_mixin.py:154} WARNING -   File "/opt/airflow/dags/main_de_project_1_dag.py", line 11, in <module>
    import create_tables
[2023-12-11T02:07:41.976+0000] {logging_mixin.py:154} WARNING - ModuleNotFoundError: No module named 'create_tables'
[2023-12-11T02:07:41.980+0000] {logging_mixin.py:154} WARNING - 
During handling of the above exception, another exception occurred:
[2023-12-11T02:07:41.999+0000] {logging_mixin.py:154} WARNING - Traceback (most recent call last):
[2023-12-11T02:07:42.006+0000] {logging_mixin.py:154} WARNING -   File "/usr/local/lib/python3.8/logging/__init__.py", line 1085, in emit
    msg = self.format(record)
[2023-12-11T02:07:42.028+0000] {logging_mixin.py:154} WARNING -   File "/usr/local/lib/python3.8/logging/__init__.py", line 929, in format
    return fmt.format(record)
[2023-12-11T02:07:42.051+0000] {logging_mixin.py:154} WARNING -   File "/usr/local/lib/python3.8/logging/__init__.py", line 670, in format
    record.asctime = self.formatTime(record, self.datefmt)
[2023-12-11T02:07:42.097+0000] {logging_mixin.py:154} WARNING -   File "/home/airflow/.local/lib/python3.8/site-packages/airflow/utils/log/timezone_aware.py", line 42, in formatTime
    dt = pendulum.from_timestamp(record.created, tz=pendulum.local_timezone())
[2023-12-11T02:07:42.101+0000] {logging_mixin.py:154} WARNING -   File "/home/airflow/.local/lib/python3.8/site-packages/pendulum/__init__.py", line 272, in from_timestamp
    dt = _datetime.datetime.utcfromtimestamp(timestamp)
[2023-12-11T02:07:42.109+0000] {logging_mixin.py:154} WARNING -   File "/home/airflow/.local/lib/python3.8/site-packages/airflow/utils/timeout.py", line 69, in handle_timeout
    raise AirflowTaskTimeout(self.error_message)
[2023-12-11T02:07:42.121+0000] {logging_mixin.py:154} WARNING - airflow.exceptions.AirflowTaskTimeout: DagBag import timeout for /opt/airflow/dags/main_de_project_1_dag.py after 30.0s.
Please take a look at these docs to improve your DAG import time:
* https://airflow.apache.org/docs/apache-airflow/2.7.3/best-practices.html#top-level-python-code
* https://airflow.apache.org/docs/apache-airflow/2.7.3/best-practices.html#reducing-dag-complexity, PID: 4226
[2023-12-11T02:07:42.126+0000] {logging_mixin.py:154} WARNING - Call stack:
[2023-12-11T02:07:42.255+0000] {logging_mixin.py:154} WARNING -   File "/home/airflow/.local/bin/airflow", line 8, in <module>
    sys.exit(main())
[2023-12-11T02:07:42.259+0000] {logging_mixin.py:154} WARNING -   File "/home/airflow/.local/lib/python3.8/site-packages/airflow/__main__.py", line 57, in main
    args.func(args)
[2023-12-11T02:07:42.272+0000] {logging_mixin.py:154} WARNING -   File "/home/airflow/.local/lib/python3.8/site-packages/airflow/cli/cli_config.py", line 49, in command
    return func(*args, **kwargs)
[2023-12-11T02:07:42.278+0000] {logging_mixin.py:154} WARNING -   File "/home/airflow/.local/lib/python3.8/site-packages/airflow/utils/cli.py", line 114, in wrapper
    return f(*args, **kwargs)
[2023-12-11T02:07:42.282+0000] {logging_mixin.py:154} WARNING -   File "/home/airflow/.local/lib/python3.8/site-packages/airflow/utils/providers_configuration_loader.py", line 55, in wrapped_function
    return func(*args, **kwargs)
[2023-12-11T02:07:42.283+0000] {logging_mixin.py:154} WARNING -   File "/home/airflow/.local/lib/python3.8/site-packages/airflow/cli/commands/scheduler_command.py", line 85, in scheduler
    _run_scheduler_job(job_runner, skip_serve_logs=args.skip_serve_logs)
[2023-12-11T02:07:42.288+0000] {logging_mixin.py:154} WARNING -   File "/home/airflow/.local/lib/python3.8/site-packages/airflow/cli/commands/scheduler_command.py", line 47, in _run_scheduler_job
    run_job(job=job_runner.job, execute_callable=job_runner._execute)
[2023-12-11T02:07:42.295+0000] {logging_mixin.py:154} WARNING -   File "/home/airflow/.local/lib/python3.8/site-packages/airflow/utils/session.py", line 79, in wrapper
    return func(*args, session=session, **kwargs)
[2023-12-11T02:07:42.302+0000] {logging_mixin.py:154} WARNING -   File "/home/airflow/.local/lib/python3.8/site-packages/airflow/jobs/job.py", line 289, in run_job
    return execute_job(job, execute_callable=execute_callable)
[2023-12-11T02:07:42.318+0000] {logging_mixin.py:154} WARNING -   File "/home/airflow/.local/lib/python3.8/site-packages/airflow/jobs/job.py", line 318, in execute_job
    ret = execute_callable()
[2023-12-11T02:07:42.329+0000] {logging_mixin.py:154} WARNING -   File "/home/airflow/.local/lib/python3.8/site-packages/airflow/jobs/scheduler_job_runner.py", line 844, in _execute
    self._run_scheduler_loop()
[2023-12-11T02:07:42.338+0000] {logging_mixin.py:154} WARNING -   File "/home/airflow/.local/lib/python3.8/site-packages/airflow/jobs/scheduler_job_runner.py", line 982, in _run_scheduler_loop
    self.processor_agent.heartbeat()
[2023-12-11T02:07:42.348+0000] {logging_mixin.py:154} WARNING -   File "/home/airflow/.local/lib/python3.8/site-packages/airflow/dag_processing/manager.py", line 273, in heartbeat
    self._heartbeat_manager()
[2023-12-11T02:07:42.352+0000] {logging_mixin.py:154} WARNING -   File "/home/airflow/.local/lib/python3.8/site-packages/airflow/dag_processing/manager.py", line 308, in _heartbeat_manager
    self.start()
[2023-12-11T02:07:42.360+0000] {logging_mixin.py:154} WARNING -   File "/home/airflow/.local/lib/python3.8/site-packages/airflow/dag_processing/manager.py", line 164, in start
    process.start()
[2023-12-11T02:07:42.362+0000] {logging_mixin.py:154} WARNING -   File "/usr/local/lib/python3.8/multiprocessing/process.py", line 121, in start
    self._popen = self._Popen(self)
[2023-12-11T02:07:42.384+0000] {logging_mixin.py:154} WARNING -   File "/usr/local/lib/python3.8/multiprocessing/context.py", line 277, in _Popen
    return Popen(process_obj)
[2023-12-11T02:07:42.410+0000] {logging_mixin.py:154} WARNING -   File "/usr/local/lib/python3.8/multiprocessing/popen_fork.py", line 19, in __init__
    self._launch(process_obj)
[2023-12-11T02:07:42.413+0000] {logging_mixin.py:154} WARNING -   File "/usr/local/lib/python3.8/multiprocessing/popen_fork.py", line 75, in _launch
    code = process_obj._bootstrap(parent_sentinel=child_r)
[2023-12-11T02:07:42.424+0000] {logging_mixin.py:154} WARNING -   File "/usr/local/lib/python3.8/multiprocessing/process.py", line 315, in _bootstrap
    self.run()
[2023-12-11T02:07:42.437+0000] {logging_mixin.py:154} WARNING -   File "/usr/local/lib/python3.8/multiprocessing/process.py", line 108, in run
    self._target(*self._args, **self._kwargs)
[2023-12-11T02:07:42.463+0000] {logging_mixin.py:154} WARNING -   File "/home/airflow/.local/lib/python3.8/site-packages/airflow/dag_processing/manager.py", line 258, in _run_processor_manager
    processor_manager.start()
[2023-12-11T02:07:42.493+0000] {logging_mixin.py:154} WARNING -   File "/home/airflow/.local/lib/python3.8/site-packages/airflow/dag_processing/manager.py", line 493, in start
    return self._run_parsing_loop()
[2023-12-11T02:07:42.494+0000] {logging_mixin.py:154} WARNING -   File "/home/airflow/.local/lib/python3.8/site-packages/airflow/dag_processing/manager.py", line 636, in _run_parsing_loop
    self.start_new_processes()
[2023-12-11T02:07:42.502+0000] {logging_mixin.py:154} WARNING -   File "/home/airflow/.local/lib/python3.8/site-packages/airflow/dag_processing/manager.py", line 1096, in start_new_processes
    processor.start()
[2023-12-11T02:07:42.506+0000] {logging_mixin.py:154} WARNING -   File "/home/airflow/.local/lib/python3.8/site-packages/airflow/dag_processing/processor.py", line 234, in start
    process.start()
[2023-12-11T02:07:42.507+0000] {logging_mixin.py:154} WARNING -   File "/usr/local/lib/python3.8/multiprocessing/process.py", line 121, in start
    self._popen = self._Popen(self)
[2023-12-11T02:07:42.509+0000] {logging_mixin.py:154} WARNING -   File "/usr/local/lib/python3.8/multiprocessing/context.py", line 277, in _Popen
    return Popen(process_obj)
[2023-12-11T02:07:42.542+0000] {logging_mixin.py:154} WARNING -   File "/usr/local/lib/python3.8/multiprocessing/popen_fork.py", line 19, in __init__
    self._launch(process_obj)
[2023-12-11T02:07:42.553+0000] {logging_mixin.py:154} WARNING -   File "/usr/local/lib/python3.8/multiprocessing/popen_fork.py", line 75, in _launch
    code = process_obj._bootstrap(parent_sentinel=child_r)
[2023-12-11T02:07:42.557+0000] {logging_mixin.py:154} WARNING -   File "/usr/local/lib/python3.8/multiprocessing/process.py", line 315, in _bootstrap
    self.run()
[2023-12-11T02:07:42.572+0000] {logging_mixin.py:154} WARNING -   File "/usr/local/lib/python3.8/multiprocessing/process.py", line 108, in run
    self._target(*self._args, **self._kwargs)
[2023-12-11T02:07:42.576+0000] {logging_mixin.py:154} WARNING -   File "/home/airflow/.local/lib/python3.8/site-packages/airflow/dag_processing/processor.py", line 178, in _run_file_processor
    _handle_dag_file_processing()
[2023-12-11T02:07:42.594+0000] {logging_mixin.py:154} WARNING -   File "/home/airflow/.local/lib/python3.8/site-packages/airflow/dag_processing/processor.py", line 159, in _handle_dag_file_processing
    result: tuple[int, int] = dag_file_processor.process_file(
[2023-12-11T02:07:42.606+0000] {logging_mixin.py:154} WARNING -   File "/home/airflow/.local/lib/python3.8/site-packages/airflow/utils/session.py", line 79, in wrapper
    return func(*args, session=session, **kwargs)
[2023-12-11T02:07:42.608+0000] {logging_mixin.py:154} WARNING -   File "/home/airflow/.local/lib/python3.8/site-packages/airflow/dag_processing/processor.py", line 832, in process_file
    dagbag = DagFileProcessor._get_dagbag(file_path)
[2023-12-11T02:07:42.611+0000] {logging_mixin.py:154} WARNING -   File "/home/airflow/.local/lib/python3.8/site-packages/airflow/dag_processing/processor.py", line 796, in _get_dagbag
    return DagBag(file_path, include_examples=False)
[2023-12-11T02:07:42.629+0000] {logging_mixin.py:154} WARNING -   File "/home/airflow/.local/lib/python3.8/site-packages/airflow/models/dagbag.py", line 141, in __init__
    self.collect_dags(
[2023-12-11T02:07:42.641+0000] {logging_mixin.py:154} WARNING -   File "/home/airflow/.local/lib/python3.8/site-packages/airflow/models/dagbag.py", line 550, in collect_dags
    found_dags = self.process_file(filepath, only_if_updated=only_if_updated, safe_mode=safe_mode)
[2023-12-11T02:07:42.655+0000] {logging_mixin.py:154} WARNING -   File "/home/airflow/.local/lib/python3.8/site-packages/airflow/models/dagbag.py", line 307, in process_file
    mods = self._load_modules_from_file(filepath, safe_mode)
[2023-12-11T02:07:42.679+0000] {logging_mixin.py:154} WARNING -   File "/home/airflow/.local/lib/python3.8/site-packages/airflow/models/dagbag.py", line 372, in _load_modules_from_file
    return parse(mod_name, filepath)
[2023-12-11T02:07:42.682+0000] {logging_mixin.py:154} WARNING -   File "/home/airflow/.local/lib/python3.8/site-packages/airflow/models/dagbag.py", line 346, in parse
    self.log.exception("Failed to import: %s", filepath)
[2023-12-11T02:07:42.684+0000] {logging_mixin.py:154} WARNING -   File "/usr/local/lib/python3.8/logging/__init__.py", line 1481, in exception
    self.error(msg, *args, exc_info=exc_info, **kwargs)
[2023-12-11T02:07:42.691+0000] {logging_mixin.py:154} WARNING -   File "/usr/local/lib/python3.8/logging/__init__.py", line 1475, in error
    self._log(ERROR, msg, args, **kwargs)
[2023-12-11T02:07:42.693+0000] {logging_mixin.py:154} WARNING -   File "/usr/local/lib/python3.8/logging/__init__.py", line 1589, in _log
    self.handle(record)
[2023-12-11T02:07:42.694+0000] {logging_mixin.py:154} WARNING -   File "/usr/local/lib/python3.8/logging/__init__.py", line 1599, in handle
    self.callHandlers(record)
[2023-12-11T02:07:42.699+0000] {logging_mixin.py:154} WARNING -   File "/usr/local/lib/python3.8/logging/__init__.py", line 1661, in callHandlers
    hdlr.handle(record)
[2023-12-11T02:07:42.707+0000] {logging_mixin.py:154} WARNING -   File "/usr/local/lib/python3.8/logging/__init__.py", line 954, in handle
    self.emit(record)
[2023-12-11T02:07:42.712+0000] {logging_mixin.py:154} WARNING -   File "/usr/local/lib/python3.8/logging/__init__.py", line 1088, in emit
    stream.write(msg + self.terminator)
[2023-12-11T02:07:42.719+0000] {logging_mixin.py:154} WARNING -   File "/home/airflow/.local/lib/python3.8/site-packages/airflow/utils/log/logging_mixin.py", line 166, in write
    self.flush()
[2023-12-11T02:07:42.722+0000] {logging_mixin.py:154} WARNING -   File "/home/airflow/.local/lib/python3.8/site-packages/airflow/utils/log/logging_mixin.py", line 173, in flush
    self._propagate_log(buf)
[2023-12-11T02:07:42.724+0000] {logging_mixin.py:154} WARNING -   File "/home/airflow/.local/lib/python3.8/site-packages/airflow/utils/log/logging_mixin.py", line 154, in _propagate_log
    self.logger.log(self.level, remove_escape_codes(message))
[2023-12-11T02:07:42.731+0000] {logging_mixin.py:154} WARNING -   File "/usr/local/lib/python3.8/logging/__init__.py", line 1512, in log
    self._log(level, msg, args, **kwargs)
[2023-12-11T02:07:42.737+0000] {logging_mixin.py:154} WARNING -   File "/usr/local/lib/python3.8/logging/__init__.py", line 1589, in _log
    self.handle(record)
[2023-12-11T02:07:42.765+0000] {logging_mixin.py:154} WARNING -   File "/usr/local/lib/python3.8/logging/__init__.py", line 1599, in handle
    self.callHandlers(record)
[2023-12-11T02:07:42.785+0000] {logging_mixin.py:154} WARNING -   File "/usr/local/lib/python3.8/logging/__init__.py", line 1661, in callHandlers
    hdlr.handle(record)
[2023-12-11T02:07:42.793+0000] {logging_mixin.py:154} WARNING -   File "/usr/local/lib/python3.8/logging/__init__.py", line 954, in handle
    self.emit(record)
[2023-12-11T02:07:42.802+0000] {logging_mixin.py:154} WARNING -   File "/home/airflow/.local/lib/python3.8/site-packages/airflow/utils/log/file_processor_handler.py", line 73, in emit
    self.handler.emit(record)
[2023-12-11T02:07:42.824+0000] {logging_mixin.py:154} WARNING - Message: '[2023-12-11T02:05:34.420+0000] {dagbag.py:346} ERROR - Failed to import: /opt/airflow/dags/main_de_project_1_dag.py\nTraceback (most recent call last):\n  File "/home/airflow/.local/lib/python3.8/site-packages/airflow/models/dagbag.py", line 342, in parse\n    loader.exec_module(new_module)\n  File "<frozen importlib._bootstrap_external>", line 843, in exec_module\n  File "<frozen importlib._bootstrap>", line 219, in _call_with_frames_removed\n  File "/opt/airflow/dags/main_de_project_1_dag.py", line 11, in <module>\n    import create_tables\nModuleNotFoundError: No module named \'create_tables\''
Arguments: ()
[2023-12-11T02:07:42.878+0000] {processor.py:841} WARNING - No viable dags retrieved from /opt/airflow/dags/main_de_project_1_dag.py
[2023-12-11T02:07:45.253+0000] {processor.py:179} INFO - Processing /opt/airflow/dags/main_de_project_1_dag.py took 167.782 seconds
[2023-12-11T02:25:25.718+0000] {processor.py:157} INFO - Started process (PID=4235) to work on /opt/airflow/dags/main_de_project_1_dag.py
[2023-12-11T02:25:25.721+0000] {processor.py:829} INFO - Processing file /opt/airflow/dags/main_de_project_1_dag.py for tasks to queue
[2023-12-11T02:25:25.726+0000] {logging_mixin.py:154} INFO - [2023-12-11T02:25:25.726+0000] {dagbag.py:536} INFO - Filling up the DagBag from /opt/airflow/dags/main_de_project_1_dag.py
[2023-12-11T02:26:53.095+0000] {processor.py:157} INFO - Started process (PID=4244) to work on /opt/airflow/dags/main_de_project_1_dag.py
[2023-12-11T02:26:53.136+0000] {processor.py:829} INFO - Processing file /opt/airflow/dags/main_de_project_1_dag.py for tasks to queue
[2023-12-11T02:26:53.343+0000] {logging_mixin.py:154} INFO - [2023-12-11T02:26:53.313+0000] {dagbag.py:536} INFO - Filling up the DagBag from /opt/airflow/dags/main_de_project_1_dag.py
[2023-12-11T02:26:54.774+0000] {logging_mixin.py:154} INFO - [2023-12-11T02:26:54.388+0000] {dagbag.py:346} ERROR - Failed to import: /opt/airflow/dags/main_de_project_1_dag.py
Traceback (most recent call last):
  File "/home/airflow/.local/lib/python3.8/site-packages/airflow/models/dagbag.py", line 342, in parse
    loader.exec_module(new_module)
  File "<frozen importlib._bootstrap_external>", line 843, in exec_module
  File "<frozen importlib._bootstrap>", line 219, in _call_with_frames_removed
  File "/opt/airflow/dags/main_de_project_1_dag.py", line 11, in <module>
    import create_tables
ModuleNotFoundError: No module named 'create_tables'
[2023-12-11T02:26:54.837+0000] {processor.py:841} WARNING - No viable dags retrieved from /opt/airflow/dags/main_de_project_1_dag.py
[2023-12-11T03:29:48.052+0000] {processor.py:157} INFO - Started process (PID=4260) to work on /opt/airflow/dags/main_de_project_1_dag.py
[2023-12-11T03:29:48.083+0000] {processor.py:829} INFO - Processing file /opt/airflow/dags/main_de_project_1_dag.py for tasks to queue
[2023-12-11T03:29:48.258+0000] {logging_mixin.py:154} INFO - [2023-12-11T03:29:48.257+0000] {dagbag.py:536} INFO - Filling up the DagBag from /opt/airflow/dags/main_de_project_1_dag.py
[2023-12-11T03:29:48.497+0000] {logging_mixin.py:154} INFO - [2023-12-11T03:29:48.444+0000] {dagbag.py:346} ERROR - Failed to import: /opt/airflow/dags/main_de_project_1_dag.py
Traceback (most recent call last):
  File "/home/airflow/.local/lib/python3.8/site-packages/airflow/models/dagbag.py", line 342, in parse
    loader.exec_module(new_module)
  File "<frozen importlib._bootstrap_external>", line 843, in exec_module
  File "<frozen importlib._bootstrap>", line 219, in _call_with_frames_removed
  File "/opt/airflow/dags/main_de_project_1_dag.py", line 11, in <module>
    import create_tables
ModuleNotFoundError: No module named 'create_tables'
[2023-12-11T03:29:48.503+0000] {processor.py:841} WARNING - No viable dags retrieved from /opt/airflow/dags/main_de_project_1_dag.py
[2023-12-11T03:29:48.778+0000] {processor.py:179} INFO - Processing /opt/airflow/dags/main_de_project_1_dag.py took 0.901 seconds
[2023-12-11T03:30:29.153+0000] {processor.py:157} INFO - Started process (PID=4261) to work on /opt/airflow/dags/main_de_project_1_dag.py
[2023-12-11T03:30:29.327+0000] {processor.py:829} INFO - Processing file /opt/airflow/dags/main_de_project_1_dag.py for tasks to queue
[2023-12-11T03:30:29.877+0000] {logging_mixin.py:154} INFO - [2023-12-11T03:30:29.381+0000] {dagbag.py:536} INFO - Filling up the DagBag from /opt/airflow/dags/main_de_project_1_dag.py
[2023-12-11T03:30:55.629+0000] {logging_mixin.py:154} INFO - [2023-12-11T03:30:32.452+0000] {dagbag.py:346} ERROR - Failed to import: /opt/airflow/dags/main_de_project_1_dag.py
Traceback (most recent call last):
  File "/home/airflow/.local/lib/python3.8/site-packages/airflow/models/dagbag.py", line 342, in parse
    loader.exec_module(new_module)
  File "<frozen importlib._bootstrap_external>", line 843, in exec_module
  File "<frozen importlib._bootstrap>", line 219, in _call_with_frames_removed
  File "/opt/airflow/dags/main_de_project_1_dag.py", line 11, in <module>
    import create_tables
ModuleNotFoundError: No module named 'create_tables'
[2023-12-11T03:30:56.256+0000] {processor.py:841} WARNING - No viable dags retrieved from /opt/airflow/dags/main_de_project_1_dag.py
[2023-12-11T03:30:57.889+0000] {processor.py:179} INFO - Processing /opt/airflow/dags/main_de_project_1_dag.py took 29.532 seconds
[2023-12-11T03:32:11.873+0000] {processor.py:157} INFO - Started process (PID=4269) to work on /opt/airflow/dags/main_de_project_1_dag.py
[2023-12-11T03:32:11.876+0000] {processor.py:829} INFO - Processing file /opt/airflow/dags/main_de_project_1_dag.py for tasks to queue
[2023-12-11T03:32:12.406+0000] {logging_mixin.py:154} INFO - [2023-12-11T03:32:12.351+0000] {dagbag.py:536} INFO - Filling up the DagBag from /opt/airflow/dags/main_de_project_1_dag.py
[2023-12-11T03:32:12.910+0000] {logging_mixin.py:154} INFO - [2023-12-11T03:32:12.820+0000] {dagbag.py:346} ERROR - Failed to import: /opt/airflow/dags/main_de_project_1_dag.py
Traceback (most recent call last):
  File "/home/airflow/.local/lib/python3.8/site-packages/airflow/models/dagbag.py", line 342, in parse
    loader.exec_module(new_module)
  File "<frozen importlib._bootstrap_external>", line 843, in exec_module
  File "<frozen importlib._bootstrap>", line 219, in _call_with_frames_removed
  File "/opt/airflow/dags/main_de_project_1_dag.py", line 11, in <module>
    import create_tables
ModuleNotFoundError: No module named 'create_tables'
[2023-12-11T03:32:12.994+0000] {processor.py:841} WARNING - No viable dags retrieved from /opt/airflow/dags/main_de_project_1_dag.py
[2023-12-11T03:32:13.488+0000] {processor.py:179} INFO - Processing /opt/airflow/dags/main_de_project_1_dag.py took 1.683 seconds
[2023-12-11T03:32:53.708+0000] {processor.py:157} INFO - Started process (PID=4277) to work on /opt/airflow/dags/main_de_project_1_dag.py
[2023-12-11T03:32:53.917+0000] {processor.py:829} INFO - Processing file /opt/airflow/dags/main_de_project_1_dag.py for tasks to queue
[2023-12-11T03:32:54.336+0000] {logging_mixin.py:154} INFO - [2023-12-11T03:32:54.157+0000] {dagbag.py:536} INFO - Filling up the DagBag from /opt/airflow/dags/main_de_project_1_dag.py
[2023-12-11T03:33:28.143+0000] {logging_mixin.py:154} INFO - [2023-12-11T03:33:27.897+0000] {timeout.py:68} ERROR - Process timed out, PID: 4277
[2023-12-11T03:33:28.149+0000] {logging_mixin.py:154} WARNING - --- Logging error ---
[2023-12-11T03:33:28.357+0000] {logging_mixin.py:154} WARNING - Traceback (most recent call last):
[2023-12-11T03:33:28.392+0000] {logging_mixin.py:154} WARNING -   File "/home/airflow/.local/lib/python3.8/site-packages/airflow/models/dagbag.py", line 342, in parse
    loader.exec_module(new_module)
[2023-12-11T03:33:28.405+0000] {logging_mixin.py:154} WARNING -   File "<frozen importlib._bootstrap_external>", line 843, in exec_module
[2023-12-11T03:33:28.406+0000] {logging_mixin.py:154} WARNING -   File "<frozen importlib._bootstrap>", line 219, in _call_with_frames_removed
[2023-12-11T03:33:28.434+0000] {logging_mixin.py:154} WARNING -   File "/opt/airflow/dags/main_de_project_1_dag.py", line 11, in <module>
    import create_tables
[2023-12-11T03:33:28.435+0000] {logging_mixin.py:154} WARNING - ModuleNotFoundError: No module named 'create_tables'
[2023-12-11T03:33:28.452+0000] {logging_mixin.py:154} WARNING - 
During handling of the above exception, another exception occurred:
[2023-12-11T03:33:28.542+0000] {logging_mixin.py:154} WARNING - Traceback (most recent call last):
[2023-12-11T03:33:28.605+0000] {logging_mixin.py:154} WARNING -   File "/usr/local/lib/python3.8/logging/__init__.py", line 1088, in emit
    stream.write(msg + self.terminator)
[2023-12-11T03:33:28.607+0000] {logging_mixin.py:154} WARNING -   File "/home/airflow/.local/lib/python3.8/site-packages/airflow/utils/log/logging_mixin.py", line 166, in write
    self.flush()
[2023-12-11T03:33:28.608+0000] {logging_mixin.py:154} WARNING -   File "/home/airflow/.local/lib/python3.8/site-packages/airflow/utils/log/logging_mixin.py", line 173, in flush
    self._propagate_log(buf)
[2023-12-11T03:33:28.632+0000] {logging_mixin.py:154} WARNING -   File "/home/airflow/.local/lib/python3.8/site-packages/airflow/utils/log/logging_mixin.py", line 154, in _propagate_log
    self.logger.log(self.level, remove_escape_codes(message))
[2023-12-11T03:33:28.641+0000] {logging_mixin.py:154} WARNING -   File "/usr/local/lib/python3.8/logging/__init__.py", line 1512, in log
    self._log(level, msg, args, **kwargs)
[2023-12-11T03:33:28.643+0000] {logging_mixin.py:154} WARNING -   File "/usr/local/lib/python3.8/logging/__init__.py", line 1587, in _log
    record = self.makeRecord(self.name, level, fn, lno, msg, args,
[2023-12-11T03:33:28.696+0000] {logging_mixin.py:154} WARNING -   File "/usr/local/lib/python3.8/logging/__init__.py", line 1556, in makeRecord
    rv = _logRecordFactory(name, level, fn, lno, msg, args, exc_info, func,
[2023-12-11T03:33:28.705+0000] {logging_mixin.py:154} WARNING -   File "/usr/local/lib/python3.8/logging/__init__.py", line 293, in __init__
    ct = time.time()
[2023-12-11T03:33:28.743+0000] {logging_mixin.py:154} WARNING -   File "/home/airflow/.local/lib/python3.8/site-packages/airflow/utils/timeout.py", line 69, in handle_timeout
    raise AirflowTaskTimeout(self.error_message)
[2023-12-11T03:33:28.772+0000] {logging_mixin.py:154} WARNING - airflow.exceptions.AirflowTaskTimeout: DagBag import timeout for /opt/airflow/dags/main_de_project_1_dag.py after 30.0s.
Please take a look at these docs to improve your DAG import time:
* https://airflow.apache.org/docs/apache-airflow/2.7.3/best-practices.html#top-level-python-code
* https://airflow.apache.org/docs/apache-airflow/2.7.3/best-practices.html#reducing-dag-complexity, PID: 4277
[2023-12-11T03:33:28.808+0000] {logging_mixin.py:154} WARNING - Call stack:
[2023-12-11T03:33:29.735+0000] {logging_mixin.py:154} WARNING -   File "/home/airflow/.local/bin/airflow", line 8, in <module>
    sys.exit(main())
[2023-12-11T03:33:29.755+0000] {logging_mixin.py:154} WARNING -   File "/home/airflow/.local/lib/python3.8/site-packages/airflow/__main__.py", line 57, in main
    args.func(args)
[2023-12-11T03:33:29.761+0000] {logging_mixin.py:154} WARNING -   File "/home/airflow/.local/lib/python3.8/site-packages/airflow/cli/cli_config.py", line 49, in command
    return func(*args, **kwargs)
[2023-12-11T03:33:29.763+0000] {logging_mixin.py:154} WARNING -   File "/home/airflow/.local/lib/python3.8/site-packages/airflow/utils/cli.py", line 114, in wrapper
    return f(*args, **kwargs)
[2023-12-11T03:33:29.764+0000] {logging_mixin.py:154} WARNING -   File "/home/airflow/.local/lib/python3.8/site-packages/airflow/utils/providers_configuration_loader.py", line 55, in wrapped_function
    return func(*args, **kwargs)
[2023-12-11T03:33:29.765+0000] {logging_mixin.py:154} WARNING -   File "/home/airflow/.local/lib/python3.8/site-packages/airflow/cli/commands/scheduler_command.py", line 85, in scheduler
    _run_scheduler_job(job_runner, skip_serve_logs=args.skip_serve_logs)
[2023-12-11T03:33:29.767+0000] {logging_mixin.py:154} WARNING -   File "/home/airflow/.local/lib/python3.8/site-packages/airflow/cli/commands/scheduler_command.py", line 47, in _run_scheduler_job
    run_job(job=job_runner.job, execute_callable=job_runner._execute)
[2023-12-11T03:33:29.770+0000] {logging_mixin.py:154} WARNING -   File "/home/airflow/.local/lib/python3.8/site-packages/airflow/utils/session.py", line 79, in wrapper
    return func(*args, session=session, **kwargs)
[2023-12-11T03:33:29.777+0000] {logging_mixin.py:154} WARNING -   File "/home/airflow/.local/lib/python3.8/site-packages/airflow/jobs/job.py", line 289, in run_job
    return execute_job(job, execute_callable=execute_callable)
[2023-12-11T03:33:29.779+0000] {logging_mixin.py:154} WARNING -   File "/home/airflow/.local/lib/python3.8/site-packages/airflow/jobs/job.py", line 318, in execute_job
    ret = execute_callable()
[2023-12-11T03:33:29.780+0000] {logging_mixin.py:154} WARNING -   File "/home/airflow/.local/lib/python3.8/site-packages/airflow/jobs/scheduler_job_runner.py", line 844, in _execute
    self._run_scheduler_loop()
[2023-12-11T03:33:29.781+0000] {logging_mixin.py:154} WARNING -   File "/home/airflow/.local/lib/python3.8/site-packages/airflow/jobs/scheduler_job_runner.py", line 982, in _run_scheduler_loop
    self.processor_agent.heartbeat()
[2023-12-11T03:33:29.783+0000] {logging_mixin.py:154} WARNING -   File "/home/airflow/.local/lib/python3.8/site-packages/airflow/dag_processing/manager.py", line 273, in heartbeat
    self._heartbeat_manager()
[2023-12-11T03:33:29.785+0000] {logging_mixin.py:154} WARNING -   File "/home/airflow/.local/lib/python3.8/site-packages/airflow/dag_processing/manager.py", line 308, in _heartbeat_manager
    self.start()
[2023-12-11T03:33:29.787+0000] {logging_mixin.py:154} WARNING -   File "/home/airflow/.local/lib/python3.8/site-packages/airflow/dag_processing/manager.py", line 164, in start
    process.start()
[2023-12-11T03:33:29.788+0000] {logging_mixin.py:154} WARNING -   File "/usr/local/lib/python3.8/multiprocessing/process.py", line 121, in start
    self._popen = self._Popen(self)
[2023-12-11T03:33:29.789+0000] {logging_mixin.py:154} WARNING -   File "/usr/local/lib/python3.8/multiprocessing/context.py", line 277, in _Popen
    return Popen(process_obj)
[2023-12-11T03:33:29.791+0000] {logging_mixin.py:154} WARNING -   File "/usr/local/lib/python3.8/multiprocessing/popen_fork.py", line 19, in __init__
    self._launch(process_obj)
[2023-12-11T03:33:29.792+0000] {logging_mixin.py:154} WARNING -   File "/usr/local/lib/python3.8/multiprocessing/popen_fork.py", line 75, in _launch
    code = process_obj._bootstrap(parent_sentinel=child_r)
[2023-12-11T03:33:29.793+0000] {logging_mixin.py:154} WARNING -   File "/usr/local/lib/python3.8/multiprocessing/process.py", line 315, in _bootstrap
    self.run()
[2023-12-11T03:33:29.793+0000] {logging_mixin.py:154} WARNING -   File "/usr/local/lib/python3.8/multiprocessing/process.py", line 108, in run
    self._target(*self._args, **self._kwargs)
[2023-12-11T03:33:29.794+0000] {logging_mixin.py:154} WARNING -   File "/home/airflow/.local/lib/python3.8/site-packages/airflow/dag_processing/manager.py", line 258, in _run_processor_manager
    processor_manager.start()
[2023-12-11T03:33:29.795+0000] {logging_mixin.py:154} WARNING -   File "/home/airflow/.local/lib/python3.8/site-packages/airflow/dag_processing/manager.py", line 493, in start
    return self._run_parsing_loop()
[2023-12-11T03:33:29.796+0000] {logging_mixin.py:154} WARNING -   File "/home/airflow/.local/lib/python3.8/site-packages/airflow/dag_processing/manager.py", line 636, in _run_parsing_loop
    self.start_new_processes()
[2023-12-11T03:33:29.797+0000] {logging_mixin.py:154} WARNING -   File "/home/airflow/.local/lib/python3.8/site-packages/airflow/dag_processing/manager.py", line 1096, in start_new_processes
    processor.start()
[2023-12-11T03:33:29.799+0000] {logging_mixin.py:154} WARNING -   File "/home/airflow/.local/lib/python3.8/site-packages/airflow/dag_processing/processor.py", line 234, in start
    process.start()
[2023-12-11T03:33:29.801+0000] {logging_mixin.py:154} WARNING -   File "/usr/local/lib/python3.8/multiprocessing/process.py", line 121, in start
    self._popen = self._Popen(self)
[2023-12-11T03:33:29.804+0000] {logging_mixin.py:154} WARNING -   File "/usr/local/lib/python3.8/multiprocessing/context.py", line 277, in _Popen
    return Popen(process_obj)
[2023-12-11T03:33:29.805+0000] {logging_mixin.py:154} WARNING -   File "/usr/local/lib/python3.8/multiprocessing/popen_fork.py", line 19, in __init__
    self._launch(process_obj)
[2023-12-11T03:33:29.806+0000] {logging_mixin.py:154} WARNING -   File "/usr/local/lib/python3.8/multiprocessing/popen_fork.py", line 75, in _launch
    code = process_obj._bootstrap(parent_sentinel=child_r)
[2023-12-11T03:33:29.808+0000] {logging_mixin.py:154} WARNING -   File "/usr/local/lib/python3.8/multiprocessing/process.py", line 315, in _bootstrap
    self.run()
[2023-12-11T03:33:29.811+0000] {logging_mixin.py:154} WARNING -   File "/usr/local/lib/python3.8/multiprocessing/process.py", line 108, in run
    self._target(*self._args, **self._kwargs)
[2023-12-11T03:33:29.817+0000] {logging_mixin.py:154} WARNING -   File "/home/airflow/.local/lib/python3.8/site-packages/airflow/dag_processing/processor.py", line 178, in _run_file_processor
    _handle_dag_file_processing()
[2023-12-11T03:33:29.821+0000] {logging_mixin.py:154} WARNING -   File "/home/airflow/.local/lib/python3.8/site-packages/airflow/dag_processing/processor.py", line 159, in _handle_dag_file_processing
    result: tuple[int, int] = dag_file_processor.process_file(
[2023-12-11T03:33:29.825+0000] {logging_mixin.py:154} WARNING -   File "/home/airflow/.local/lib/python3.8/site-packages/airflow/utils/session.py", line 79, in wrapper
    return func(*args, session=session, **kwargs)
[2023-12-11T03:33:29.830+0000] {logging_mixin.py:154} WARNING -   File "/home/airflow/.local/lib/python3.8/site-packages/airflow/dag_processing/processor.py", line 832, in process_file
    dagbag = DagFileProcessor._get_dagbag(file_path)
[2023-12-11T03:33:29.831+0000] {logging_mixin.py:154} WARNING -   File "/home/airflow/.local/lib/python3.8/site-packages/airflow/dag_processing/processor.py", line 796, in _get_dagbag
    return DagBag(file_path, include_examples=False)
[2023-12-11T03:33:29.835+0000] {logging_mixin.py:154} WARNING -   File "/home/airflow/.local/lib/python3.8/site-packages/airflow/models/dagbag.py", line 141, in __init__
    self.collect_dags(
[2023-12-11T03:33:29.837+0000] {logging_mixin.py:154} WARNING -   File "/home/airflow/.local/lib/python3.8/site-packages/airflow/models/dagbag.py", line 550, in collect_dags
    found_dags = self.process_file(filepath, only_if_updated=only_if_updated, safe_mode=safe_mode)
[2023-12-11T03:33:29.841+0000] {logging_mixin.py:154} WARNING -   File "/home/airflow/.local/lib/python3.8/site-packages/airflow/models/dagbag.py", line 307, in process_file
    mods = self._load_modules_from_file(filepath, safe_mode)
[2023-12-11T03:33:29.844+0000] {logging_mixin.py:154} WARNING -   File "/home/airflow/.local/lib/python3.8/site-packages/airflow/models/dagbag.py", line 372, in _load_modules_from_file
    return parse(mod_name, filepath)
[2023-12-11T03:33:29.847+0000] {logging_mixin.py:154} WARNING -   File "/home/airflow/.local/lib/python3.8/site-packages/airflow/models/dagbag.py", line 346, in parse
    self.log.exception("Failed to import: %s", filepath)
[2023-12-11T03:33:29.852+0000] {logging_mixin.py:154} WARNING - Message: 'Failed to import: %s'
Arguments: ('/opt/airflow/dags/main_de_project_1_dag.py',)
[2023-12-11T03:33:29.856+0000] {processor.py:841} WARNING - No viable dags retrieved from /opt/airflow/dags/main_de_project_1_dag.py
[2023-12-11T03:33:30.390+0000] {processor.py:179} INFO - Processing /opt/airflow/dags/main_de_project_1_dag.py took 37.282 seconds
[2023-12-11T03:34:10.622+0000] {processor.py:157} INFO - Started process (PID=4285) to work on /opt/airflow/dags/main_de_project_1_dag.py
[2023-12-11T03:34:10.715+0000] {processor.py:829} INFO - Processing file /opt/airflow/dags/main_de_project_1_dag.py for tasks to queue
[2023-12-11T03:34:11.360+0000] {logging_mixin.py:154} INFO - [2023-12-11T03:34:11.277+0000] {dagbag.py:536} INFO - Filling up the DagBag from /opt/airflow/dags/main_de_project_1_dag.py
[2023-12-11T03:37:23.532+0000] {logging_mixin.py:154} INFO - [2023-12-11T03:35:41.373+0000] {timeout.py:68} ERROR - Process timed out, PID: 4285
[2023-12-11T03:38:33.530+0000] {logging_mixin.py:154} WARNING - --- Logging error ---
[2023-12-11T03:38:38.720+0000] {logging_mixin.py:154} WARNING - Traceback (most recent call last):
[2023-12-11T03:38:40.126+0000] {logging_mixin.py:154} WARNING -   File "/home/airflow/.local/lib/python3.8/site-packages/airflow/models/dagbag.py", line 342, in parse
    loader.exec_module(new_module)
[2023-12-11T03:38:45.500+0000] {logging_mixin.py:154} WARNING -   File "<frozen importlib._bootstrap_external>", line 843, in exec_module
[2023-12-11T03:38:47.817+0000] {logging_mixin.py:154} WARNING -   File "<frozen importlib._bootstrap>", line 219, in _call_with_frames_removed
[2023-12-11T03:38:51.177+0000] {logging_mixin.py:154} WARNING -   File "/opt/airflow/dags/main_de_project_1_dag.py", line 11, in <module>
    import create_tables
[2023-12-11T03:38:52.301+0000] {logging_mixin.py:154} WARNING - ModuleNotFoundError: No module named 'create_tables'
[2023-12-11T03:38:57.313+0000] {logging_mixin.py:154} WARNING - 
During handling of the above exception, another exception occurred:
[2023-12-11T03:39:01.696+0000] {logging_mixin.py:154} WARNING - Traceback (most recent call last):
[2023-12-11T03:39:04.905+0000] {logging_mixin.py:154} WARNING -   File "/usr/local/lib/python3.8/logging/__init__.py", line 1085, in emit
    msg = self.format(record)
[2023-12-11T03:39:28.730+0000] {logging_mixin.py:154} WARNING -   File "/usr/local/lib/python3.8/logging/__init__.py", line 929, in format
    return fmt.format(record)
[2023-12-11T03:39:50.702+0000] {logging_mixin.py:154} WARNING -   File "/usr/local/lib/python3.8/logging/__init__.py", line 676, in format
    record.exc_text = self.formatException(record.exc_info)
[2023-12-11T03:39:50.788+0000] {logging_mixin.py:154} WARNING -   File "/usr/local/lib/python3.8/logging/__init__.py", line 626, in formatException
    traceback.print_exception(ei[0], ei[1], tb, None, sio)
[2023-12-11T03:39:50.868+0000] {logging_mixin.py:154} WARNING -   File "/usr/local/lib/python3.8/traceback.py", line 103, in print_exception
    for line in TracebackException(
[2023-12-11T03:39:50.943+0000] {logging_mixin.py:154} WARNING -   File "/home/airflow/.local/lib/python3.8/site-packages/exceptiongroup/_formatting.py", line 96, in __init__
    self.stack = traceback.StackSummary.extract(
[2023-12-11T03:39:51.019+0000] {logging_mixin.py:154} WARNING -   File "/usr/local/lib/python3.8/traceback.py", line 366, in extract
    f.line
[2023-12-11T03:40:38.914+0000] {processor.py:157} INFO - Started process (PID=4286) to work on /opt/airflow/dags/main_de_project_1_dag.py
[2023-12-11T03:41:35.445+0000] {processor.py:829} INFO - Processing file /opt/airflow/dags/main_de_project_1_dag.py for tasks to queue
[2023-12-11T03:42:28.635+0000] {logging_mixin.py:154} INFO - [2023-12-11T03:41:47.675+0000] {dagbag.py:536} INFO - Filling up the DagBag from /opt/airflow/dags/main_de_project_1_dag.py
[2023-12-11T03:43:47.899+0000] {processor.py:157} INFO - Started process (PID=4303) to work on /opt/airflow/dags/main_de_project_1_dag.py
[2023-12-11T03:43:48.018+0000] {processor.py:829} INFO - Processing file /opt/airflow/dags/main_de_project_1_dag.py for tasks to queue
[2023-12-11T03:43:48.456+0000] {logging_mixin.py:154} INFO - [2023-12-11T03:43:48.373+0000] {dagbag.py:536} INFO - Filling up the DagBag from /opt/airflow/dags/main_de_project_1_dag.py
[2023-12-11T03:44:34.286+0000] {logging_mixin.py:154} INFO - [2023-12-11T03:44:25.921+0000] {timeout.py:68} ERROR - Process timed out, PID: 4303
[2023-12-11T03:46:37.718+0000] {logging_mixin.py:154} INFO - [2023-12-11T03:46:30.644+0000] {dagbag.py:346} ERROR - Failed to import: /opt/airflow/dags/main_de_project_1_dag.py
Traceback (most recent call last):
  File "<frozen importlib._bootstrap_external>", line 1346, in _path_importer_cache
KeyError: '/Users/mady/Desktop/Data:/Users/mady/Desktop/Data Engineering/Projects/data_eng_project_1/airflow_project_1/data'

During handling of the above exception, another exception occurred:

Traceback (most recent call last):
  File "<frozen zipimport>", line 75, in __init__
  File "<frozen importlib._bootstrap_external>", line 142, in _path_stat
FileNotFoundError: [Errno 2] No such file or directory: '/Users/mady/Desktop/Data:/Users/mady'

During handling of the above exception, another exception occurred:

Traceback (most recent call last):
  File "/home/airflow/.local/lib/python3.8/site-packages/airflow/models/dagbag.py", line 342, in parse
    loader.exec_module(new_module)
  File "<frozen importlib._bootstrap_external>", line 843, in exec_module
  File "<frozen importlib._bootstrap>", line 219, in _call_with_frames_removed
  File "/opt/airflow/dags/main_de_project_1_dag.py", line 11, in <module>
    import create_tables
  File "<frozen importlib._bootstrap>", line 991, in _find_and_load
  File "<frozen importlib._bootstrap>", line 971, in _find_and_load_unlocked
  File "<frozen importlib._bootstrap>", line 914, in _find_spec
  File "<frozen importlib._bootstrap_external>", line 1407, in find_spec
  File "<frozen importlib._bootstrap_external>", line 1376, in _get_spec
  File "<frozen importlib._bootstrap_external>", line 1348, in _path_importer_cache
  File "<frozen importlib._bootstrap_external>", line 1324, in _path_hooks
  File "<frozen zipimport>", line 75, in __init__
  File "/home/airflow/.local/lib/python3.8/site-packages/airflow/utils/timeout.py", line 69, in handle_timeout
    raise AirflowTaskTimeout(self.error_message)
airflow.exceptions.AirflowTaskTimeout: DagBag import timeout for /opt/airflow/dags/main_de_project_1_dag.py after 30.0s.
Please take a look at these docs to improve your DAG import time:
* https://airflow.apache.org/docs/apache-airflow/2.7.3/best-practices.html#top-level-python-code
* https://airflow.apache.org/docs/apache-airflow/2.7.3/best-practices.html#reducing-dag-complexity, PID: 4303
[2023-12-11T03:46:42.718+0000] {processor.py:841} WARNING - No viable dags retrieved from /opt/airflow/dags/main_de_project_1_dag.py
[2023-12-11T03:48:17.223+0000] {processor.py:157} INFO - Started process (PID=4304) to work on /opt/airflow/dags/main_de_project_1_dag.py
[2023-12-11T03:48:17.267+0000] {processor.py:829} INFO - Processing file /opt/airflow/dags/main_de_project_1_dag.py for tasks to queue
[2023-12-11T03:48:18.415+0000] {logging_mixin.py:154} INFO - [2023-12-11T03:48:18.338+0000] {dagbag.py:536} INFO - Filling up the DagBag from /opt/airflow/dags/main_de_project_1_dag.py
[2023-12-11T03:49:35.741+0000] {logging_mixin.py:154} INFO - [2023-12-11T03:48:52.471+0000] {timeout.py:68} ERROR - Process timed out, PID: 4304
[2023-12-11T03:49:35.748+0000] {logging_mixin.py:154} WARNING - --- Logging error ---
[2023-12-11T03:49:36.240+0000] {logging_mixin.py:154} WARNING - Traceback (most recent call last):
[2023-12-11T03:52:49.457+0000] {processor.py:157} INFO - Started process (PID=4313) to work on /opt/airflow/dags/main_de_project_1_dag.py
[2023-12-11T03:52:49.555+0000] {processor.py:829} INFO - Processing file /opt/airflow/dags/main_de_project_1_dag.py for tasks to queue
[2023-12-11T03:52:49.592+0000] {logging_mixin.py:154} INFO - [2023-12-11T03:52:49.591+0000] {dagbag.py:536} INFO - Filling up the DagBag from /opt/airflow/dags/main_de_project_1_dag.py
[2023-12-11T03:52:49.678+0000] {logging_mixin.py:154} INFO - [2023-12-11T03:52:49.653+0000] {dagbag.py:346} ERROR - Failed to import: /opt/airflow/dags/main_de_project_1_dag.py
Traceback (most recent call last):
  File "/home/airflow/.local/lib/python3.8/site-packages/airflow/models/dagbag.py", line 342, in parse
    loader.exec_module(new_module)
  File "<frozen importlib._bootstrap_external>", line 843, in exec_module
  File "<frozen importlib._bootstrap>", line 219, in _call_with_frames_removed
  File "/opt/airflow/dags/main_de_project_1_dag.py", line 11, in <module>
    import create_tables
ModuleNotFoundError: No module named 'create_tables'
[2023-12-11T03:52:49.694+0000] {processor.py:841} WARNING - No viable dags retrieved from /opt/airflow/dags/main_de_project_1_dag.py
[2023-12-11T03:52:50.001+0000] {processor.py:179} INFO - Processing /opt/airflow/dags/main_de_project_1_dag.py took 0.651 seconds
[2023-12-11T03:54:06.069+0000] {processor.py:157} INFO - Started process (PID=4314) to work on /opt/airflow/dags/main_de_project_1_dag.py
[2023-12-11T03:54:06.077+0000] {processor.py:829} INFO - Processing file /opt/airflow/dags/main_de_project_1_dag.py for tasks to queue
[2023-12-11T03:54:06.128+0000] {logging_mixin.py:154} INFO - [2023-12-11T03:54:06.119+0000] {dagbag.py:536} INFO - Filling up the DagBag from /opt/airflow/dags/main_de_project_1_dag.py
[2023-12-11T03:54:07.526+0000] {logging_mixin.py:154} INFO - [2023-12-11T03:54:07.278+0000] {dagbag.py:346} ERROR - Failed to import: /opt/airflow/dags/main_de_project_1_dag.py
Traceback (most recent call last):
  File "/home/airflow/.local/lib/python3.8/site-packages/airflow/models/dagbag.py", line 342, in parse
    loader.exec_module(new_module)
  File "<frozen importlib._bootstrap_external>", line 843, in exec_module
  File "<frozen importlib._bootstrap>", line 219, in _call_with_frames_removed
  File "/opt/airflow/dags/main_de_project_1_dag.py", line 11, in <module>
    import create_tables
ModuleNotFoundError: No module named 'create_tables'
[2023-12-11T03:54:07.565+0000] {processor.py:841} WARNING - No viable dags retrieved from /opt/airflow/dags/main_de_project_1_dag.py
[2023-12-11T03:54:09.198+0000] {processor.py:179} INFO - Processing /opt/airflow/dags/main_de_project_1_dag.py took 3.203 seconds
[2023-12-11T03:55:34.483+0000] {processor.py:157} INFO - Started process (PID=4324) to work on /opt/airflow/dags/main_de_project_1_dag.py
[2023-12-11T03:55:34.607+0000] {processor.py:829} INFO - Processing file /opt/airflow/dags/main_de_project_1_dag.py for tasks to queue
[2023-12-11T03:55:35.212+0000] {logging_mixin.py:154} INFO - [2023-12-11T03:55:35.163+0000] {dagbag.py:536} INFO - Filling up the DagBag from /opt/airflow/dags/main_de_project_1_dag.py
[2023-12-11T03:55:36.092+0000] {logging_mixin.py:154} INFO - [2023-12-11T03:55:36.056+0000] {dagbag.py:346} ERROR - Failed to import: /opt/airflow/dags/main_de_project_1_dag.py
Traceback (most recent call last):
  File "/home/airflow/.local/lib/python3.8/site-packages/airflow/models/dagbag.py", line 342, in parse
    loader.exec_module(new_module)
  File "<frozen importlib._bootstrap_external>", line 843, in exec_module
  File "<frozen importlib._bootstrap>", line 219, in _call_with_frames_removed
  File "/opt/airflow/dags/main_de_project_1_dag.py", line 11, in <module>
    import create_tables
ModuleNotFoundError: No module named 'create_tables'
[2023-12-11T03:55:36.095+0000] {processor.py:841} WARNING - No viable dags retrieved from /opt/airflow/dags/main_de_project_1_dag.py
[2023-12-11T03:55:37.698+0000] {processor.py:179} INFO - Processing /opt/airflow/dags/main_de_project_1_dag.py took 3.446 seconds
[2023-12-11T03:57:09.393+0000] {processor.py:157} INFO - Started process (PID=4333) to work on /opt/airflow/dags/main_de_project_1_dag.py
[2023-12-11T03:57:09.574+0000] {processor.py:829} INFO - Processing file /opt/airflow/dags/main_de_project_1_dag.py for tasks to queue
[2023-12-11T03:57:10.606+0000] {logging_mixin.py:154} INFO - [2023-12-11T03:57:10.341+0000] {dagbag.py:536} INFO - Filling up the DagBag from /opt/airflow/dags/main_de_project_1_dag.py
[2023-12-11T03:57:12.479+0000] {logging_mixin.py:154} INFO - [2023-12-11T03:57:12.279+0000] {dagbag.py:346} ERROR - Failed to import: /opt/airflow/dags/main_de_project_1_dag.py
Traceback (most recent call last):
  File "/home/airflow/.local/lib/python3.8/site-packages/airflow/models/dagbag.py", line 342, in parse
    loader.exec_module(new_module)
  File "<frozen importlib._bootstrap_external>", line 843, in exec_module
  File "<frozen importlib._bootstrap>", line 219, in _call_with_frames_removed
  File "/opt/airflow/dags/main_de_project_1_dag.py", line 11, in <module>
    import create_tables
ModuleNotFoundError: No module named 'create_tables'
[2023-12-11T03:57:12.538+0000] {processor.py:841} WARNING - No viable dags retrieved from /opt/airflow/dags/main_de_project_1_dag.py
[2023-12-11T03:57:21.261+0000] {processor.py:179} INFO - Processing /opt/airflow/dags/main_de_project_1_dag.py took 13.386 seconds
[2023-12-11T08:53:31.946+0000] {processor.py:157} INFO - Started process (PID=4359) to work on /opt/airflow/dags/main_de_project_1_dag.py
[2023-12-11T08:53:32.032+0000] {processor.py:829} INFO - Processing file /opt/airflow/dags/main_de_project_1_dag.py for tasks to queue
[2023-12-11T08:53:32.848+0000] {logging_mixin.py:154} INFO - [2023-12-11T08:53:32.683+0000] {dagbag.py:536} INFO - Filling up the DagBag from /opt/airflow/dags/main_de_project_1_dag.py
[2023-12-11T08:53:36.402+0000] {logging_mixin.py:154} INFO - [2023-12-11T08:53:33.594+0000] {dagbag.py:346} ERROR - Failed to import: /opt/airflow/dags/main_de_project_1_dag.py
Traceback (most recent call last):
  File "/home/airflow/.local/lib/python3.8/site-packages/airflow/models/dagbag.py", line 342, in parse
    loader.exec_module(new_module)
  File "<frozen importlib._bootstrap_external>", line 843, in exec_module
  File "<frozen importlib._bootstrap>", line 219, in _call_with_frames_removed
  File "/opt/airflow/dags/main_de_project_1_dag.py", line 11, in <module>
    import create_tables
ModuleNotFoundError: No module named 'create_tables'
[2023-12-11T08:53:37.062+0000] {processor.py:841} WARNING - No viable dags retrieved from /opt/airflow/dags/main_de_project_1_dag.py
[2023-12-11T08:53:40.851+0000] {processor.py:179} INFO - Processing /opt/airflow/dags/main_de_project_1_dag.py took 9.146 seconds
[2023-12-11T08:54:46.905+0000] {processor.py:157} INFO - Started process (PID=4367) to work on /opt/airflow/dags/main_de_project_1_dag.py
[2023-12-11T08:54:46.919+0000] {processor.py:829} INFO - Processing file /opt/airflow/dags/main_de_project_1_dag.py for tasks to queue
[2023-12-11T08:54:46.947+0000] {logging_mixin.py:154} INFO - [2023-12-11T08:54:46.946+0000] {dagbag.py:536} INFO - Filling up the DagBag from /opt/airflow/dags/main_de_project_1_dag.py
[2023-12-11T08:54:47.106+0000] {logging_mixin.py:154} INFO - [2023-12-11T08:54:47.083+0000] {dagbag.py:346} ERROR - Failed to import: /opt/airflow/dags/main_de_project_1_dag.py
Traceback (most recent call last):
  File "/home/airflow/.local/lib/python3.8/site-packages/airflow/models/dagbag.py", line 342, in parse
    loader.exec_module(new_module)
  File "<frozen importlib._bootstrap_external>", line 843, in exec_module
  File "<frozen importlib._bootstrap>", line 219, in _call_with_frames_removed
  File "/opt/airflow/dags/main_de_project_1_dag.py", line 11, in <module>
    import create_tables
ModuleNotFoundError: No module named 'create_tables'
[2023-12-11T08:54:47.144+0000] {processor.py:841} WARNING - No viable dags retrieved from /opt/airflow/dags/main_de_project_1_dag.py
[2023-12-11T08:54:48.656+0000] {processor.py:179} INFO - Processing /opt/airflow/dags/main_de_project_1_dag.py took 1.978 seconds
[2023-12-11T08:56:17.423+0000] {processor.py:157} INFO - Started process (PID=4374) to work on /opt/airflow/dags/main_de_project_1_dag.py
[2023-12-11T08:56:17.466+0000] {processor.py:829} INFO - Processing file /opt/airflow/dags/main_de_project_1_dag.py for tasks to queue
[2023-12-11T08:56:17.513+0000] {logging_mixin.py:154} INFO - [2023-12-11T08:56:17.512+0000] {dagbag.py:536} INFO - Filling up the DagBag from /opt/airflow/dags/main_de_project_1_dag.py
[2023-12-11T08:56:17.625+0000] {logging_mixin.py:154} INFO - [2023-12-11T08:56:17.584+0000] {dagbag.py:346} ERROR - Failed to import: /opt/airflow/dags/main_de_project_1_dag.py
Traceback (most recent call last):
  File "/home/airflow/.local/lib/python3.8/site-packages/airflow/models/dagbag.py", line 342, in parse
    loader.exec_module(new_module)
  File "<frozen importlib._bootstrap_external>", line 843, in exec_module
  File "<frozen importlib._bootstrap>", line 219, in _call_with_frames_removed
  File "/opt/airflow/dags/main_de_project_1_dag.py", line 11, in <module>
    import create_tables
ModuleNotFoundError: No module named 'create_tables'
[2023-12-11T08:56:17.637+0000] {processor.py:841} WARNING - No viable dags retrieved from /opt/airflow/dags/main_de_project_1_dag.py
[2023-12-11T08:56:17.906+0000] {processor.py:179} INFO - Processing /opt/airflow/dags/main_de_project_1_dag.py took 0.871 seconds
[2023-12-11T08:58:01.095+0000] {processor.py:157} INFO - Started process (PID=4376) to work on /opt/airflow/dags/main_de_project_1_dag.py
[2023-12-11T08:58:01.141+0000] {processor.py:829} INFO - Processing file /opt/airflow/dags/main_de_project_1_dag.py for tasks to queue
[2023-12-11T08:58:01.777+0000] {logging_mixin.py:154} INFO - [2023-12-11T08:58:01.620+0000] {dagbag.py:536} INFO - Filling up the DagBag from /opt/airflow/dags/main_de_project_1_dag.py
[2023-12-11T08:58:02.462+0000] {logging_mixin.py:154} INFO - [2023-12-11T08:58:02.080+0000] {dagbag.py:346} ERROR - Failed to import: /opt/airflow/dags/main_de_project_1_dag.py
Traceback (most recent call last):
  File "/home/airflow/.local/lib/python3.8/site-packages/airflow/models/dagbag.py", line 342, in parse
    loader.exec_module(new_module)
  File "<frozen importlib._bootstrap_external>", line 843, in exec_module
  File "<frozen importlib._bootstrap>", line 219, in _call_with_frames_removed
  File "/opt/airflow/dags/main_de_project_1_dag.py", line 11, in <module>
    import create_tables
ModuleNotFoundError: No module named 'create_tables'
[2023-12-11T08:58:02.463+0000] {processor.py:841} WARNING - No viable dags retrieved from /opt/airflow/dags/main_de_project_1_dag.py
[2023-12-11T08:58:56.388+0000] {processor.py:157} INFO - Started process (PID=4385) to work on /opt/airflow/dags/main_de_project_1_dag.py
[2023-12-11T08:58:56.687+0000] {processor.py:829} INFO - Processing file /opt/airflow/dags/main_de_project_1_dag.py for tasks to queue
[2023-12-11T08:58:58.554+0000] {logging_mixin.py:154} INFO - [2023-12-11T08:58:58.028+0000] {dagbag.py:536} INFO - Filling up the DagBag from /opt/airflow/dags/main_de_project_1_dag.py
[2023-12-11T09:01:48.139+0000] {processor.py:157} INFO - Started process (PID=4398) to work on /opt/airflow/dags/main_de_project_1_dag.py
[2023-12-11T09:01:48.165+0000] {processor.py:829} INFO - Processing file /opt/airflow/dags/main_de_project_1_dag.py for tasks to queue
[2023-12-11T09:01:48.879+0000] {logging_mixin.py:154} INFO - [2023-12-11T09:01:48.694+0000] {dagbag.py:536} INFO - Filling up the DagBag from /opt/airflow/dags/main_de_project_1_dag.py
[2023-12-11T09:01:50.337+0000] {logging_mixin.py:154} INFO - [2023-12-11T09:01:50.248+0000] {dagbag.py:346} ERROR - Failed to import: /opt/airflow/dags/main_de_project_1_dag.py
Traceback (most recent call last):
  File "/home/airflow/.local/lib/python3.8/site-packages/airflow/models/dagbag.py", line 342, in parse
    loader.exec_module(new_module)
  File "<frozen importlib._bootstrap_external>", line 843, in exec_module
  File "<frozen importlib._bootstrap>", line 219, in _call_with_frames_removed
  File "/opt/airflow/dags/main_de_project_1_dag.py", line 11, in <module>
    import create_tables
ModuleNotFoundError: No module named 'create_tables'
[2023-12-11T09:01:50.343+0000] {processor.py:841} WARNING - No viable dags retrieved from /opt/airflow/dags/main_de_project_1_dag.py
[2023-12-11T09:02:00.672+0000] {processor.py:182} ERROR - Got an exception! Propagating...
Traceback (most recent call last):
  File "/home/airflow/.local/lib/python3.8/site-packages/sqlalchemy/engine/base.py", line 3371, in _wrap_pool_connect
    return fn()
  File "/home/airflow/.local/lib/python3.8/site-packages/sqlalchemy/pool/base.py", line 327, in connect
    return _ConnectionFairy._checkout(self)
  File "/home/airflow/.local/lib/python3.8/site-packages/sqlalchemy/pool/base.py", line 894, in _checkout
    fairy = _ConnectionRecord.checkout(pool)
  File "/home/airflow/.local/lib/python3.8/site-packages/sqlalchemy/pool/base.py", line 493, in checkout
    rec = pool._do_get()
  File "/home/airflow/.local/lib/python3.8/site-packages/sqlalchemy/pool/impl.py", line 146, in _do_get
    self._dec_overflow()
  File "/home/airflow/.local/lib/python3.8/site-packages/sqlalchemy/util/langhelpers.py", line 70, in __exit__
    compat.raise_(
  File "/home/airflow/.local/lib/python3.8/site-packages/sqlalchemy/util/compat.py", line 211, in raise_
    raise exception
  File "/home/airflow/.local/lib/python3.8/site-packages/sqlalchemy/pool/impl.py", line 143, in _do_get
    return self._create_connection()
  File "/home/airflow/.local/lib/python3.8/site-packages/sqlalchemy/pool/base.py", line 273, in _create_connection
    return _ConnectionRecord(self)
  File "/home/airflow/.local/lib/python3.8/site-packages/sqlalchemy/pool/base.py", line 388, in __init__
    self.__connect()
  File "/home/airflow/.local/lib/python3.8/site-packages/sqlalchemy/pool/base.py", line 691, in __connect
    pool.logger.debug("Error on connect(): %s", e)
  File "/home/airflow/.local/lib/python3.8/site-packages/sqlalchemy/util/langhelpers.py", line 70, in __exit__
    compat.raise_(
  File "/home/airflow/.local/lib/python3.8/site-packages/sqlalchemy/util/compat.py", line 211, in raise_
    raise exception
  File "/home/airflow/.local/lib/python3.8/site-packages/sqlalchemy/pool/base.py", line 686, in __connect
    self.dbapi_connection = connection = pool._invoke_creator(self)
  File "/home/airflow/.local/lib/python3.8/site-packages/sqlalchemy/engine/create.py", line 574, in connect
    return dialect.connect(*cargs, **cparams)
  File "/home/airflow/.local/lib/python3.8/site-packages/sqlalchemy/engine/default.py", line 598, in connect
    return self.dbapi.connect(*cargs, **cparams)
  File "/home/airflow/.local/lib/python3.8/site-packages/psycopg2/__init__.py", line 122, in connect
    conn = _connect(dsn, connection_factory=connection_factory, **kwasync)
psycopg2.OperationalError: could not translate host name "postgres" to address: Temporary failure in name resolution


The above exception was the direct cause of the following exception:

Traceback (most recent call last):
  File "/home/airflow/.local/lib/python3.8/site-packages/airflow/dag_processing/processor.py", line 178, in _run_file_processor
    _handle_dag_file_processing()
  File "/home/airflow/.local/lib/python3.8/site-packages/airflow/dag_processing/processor.py", line 159, in _handle_dag_file_processing
    result: tuple[int, int] = dag_file_processor.process_file(
  File "/home/airflow/.local/lib/python3.8/site-packages/airflow/utils/session.py", line 79, in wrapper
    return func(*args, session=session, **kwargs)
  File "/home/airflow/.local/lib/python3.8/site-packages/airflow/dag_processing/processor.py", line 842, in process_file
    DagFileProcessor.update_import_errors(
  File "/home/airflow/.local/lib/python3.8/site-packages/airflow/api_internal/internal_api_call.py", line 114, in wrapper
    return func(*args, **kwargs)
  File "/home/airflow/.local/lib/python3.8/site-packages/airflow/utils/session.py", line 76, in wrapper
    return func(*args, **kwargs)
  File "/home/airflow/.local/lib/python3.8/site-packages/airflow/dag_processing/processor.py", line 625, in update_import_errors
    existing_import_error_files = [x.filename for x in session.query(errors.ImportError.filename).all()]
  File "/home/airflow/.local/lib/python3.8/site-packages/sqlalchemy/orm/query.py", line 2773, in all
    return self._iter().all()
  File "/home/airflow/.local/lib/python3.8/site-packages/sqlalchemy/orm/query.py", line 2916, in _iter
    result = self.session.execute(
  File "/home/airflow/.local/lib/python3.8/site-packages/sqlalchemy/orm/session.py", line 1716, in execute
    conn = self._connection_for_bind(bind)
  File "/home/airflow/.local/lib/python3.8/site-packages/sqlalchemy/orm/session.py", line 1555, in _connection_for_bind
    return self._transaction._connection_for_bind(
  File "/home/airflow/.local/lib/python3.8/site-packages/sqlalchemy/orm/session.py", line 750, in _connection_for_bind
    conn = bind.connect()
  File "/home/airflow/.local/lib/python3.8/site-packages/sqlalchemy/future/engine.py", line 406, in connect
    return super(Engine, self).connect()
  File "/home/airflow/.local/lib/python3.8/site-packages/sqlalchemy/engine/base.py", line 3325, in connect
    return self._connection_cls(self, close_with_result=close_with_result)
  File "/home/airflow/.local/lib/python3.8/site-packages/sqlalchemy/engine/base.py", line 96, in __init__
    else engine.raw_connection()
  File "/home/airflow/.local/lib/python3.8/site-packages/sqlalchemy/engine/base.py", line 3404, in raw_connection
    return self._wrap_pool_connect(self.pool.connect, _connection)
  File "/home/airflow/.local/lib/python3.8/site-packages/sqlalchemy/engine/base.py", line 3374, in _wrap_pool_connect
    Connection._handle_dbapi_exception_noconnection(
  File "/home/airflow/.local/lib/python3.8/site-packages/sqlalchemy/engine/base.py", line 2208, in _handle_dbapi_exception_noconnection
    util.raise_(
  File "/home/airflow/.local/lib/python3.8/site-packages/sqlalchemy/util/compat.py", line 211, in raise_
    raise exception
  File "/home/airflow/.local/lib/python3.8/site-packages/sqlalchemy/engine/base.py", line 3371, in _wrap_pool_connect
    return fn()
  File "/home/airflow/.local/lib/python3.8/site-packages/sqlalchemy/pool/base.py", line 327, in connect
    return _ConnectionFairy._checkout(self)
  File "/home/airflow/.local/lib/python3.8/site-packages/sqlalchemy/pool/base.py", line 894, in _checkout
    fairy = _ConnectionRecord.checkout(pool)
  File "/home/airflow/.local/lib/python3.8/site-packages/sqlalchemy/pool/base.py", line 493, in checkout
    rec = pool._do_get()
  File "/home/airflow/.local/lib/python3.8/site-packages/sqlalchemy/pool/impl.py", line 146, in _do_get
    self._dec_overflow()
  File "/home/airflow/.local/lib/python3.8/site-packages/sqlalchemy/util/langhelpers.py", line 70, in __exit__
    compat.raise_(
  File "/home/airflow/.local/lib/python3.8/site-packages/sqlalchemy/util/compat.py", line 211, in raise_
    raise exception
  File "/home/airflow/.local/lib/python3.8/site-packages/sqlalchemy/pool/impl.py", line 143, in _do_get
    return self._create_connection()
  File "/home/airflow/.local/lib/python3.8/site-packages/sqlalchemy/pool/base.py", line 273, in _create_connection
    return _ConnectionRecord(self)
  File "/home/airflow/.local/lib/python3.8/site-packages/sqlalchemy/pool/base.py", line 388, in __init__
    self.__connect()
  File "/home/airflow/.local/lib/python3.8/site-packages/sqlalchemy/pool/base.py", line 691, in __connect
    pool.logger.debug("Error on connect(): %s", e)
  File "/home/airflow/.local/lib/python3.8/site-packages/sqlalchemy/util/langhelpers.py", line 70, in __exit__
    compat.raise_(
  File "/home/airflow/.local/lib/python3.8/site-packages/sqlalchemy/util/compat.py", line 211, in raise_
    raise exception
  File "/home/airflow/.local/lib/python3.8/site-packages/sqlalchemy/pool/base.py", line 686, in __connect
    self.dbapi_connection = connection = pool._invoke_creator(self)
  File "/home/airflow/.local/lib/python3.8/site-packages/sqlalchemy/engine/create.py", line 574, in connect
    return dialect.connect(*cargs, **cparams)
  File "/home/airflow/.local/lib/python3.8/site-packages/sqlalchemy/engine/default.py", line 598, in connect
    return self.dbapi.connect(*cargs, **cparams)
  File "/home/airflow/.local/lib/python3.8/site-packages/psycopg2/__init__.py", line 122, in connect
    conn = _connect(dsn, connection_factory=connection_factory, **kwasync)
sqlalchemy.exc.OperationalError: (psycopg2.OperationalError) could not translate host name "postgres" to address: Temporary failure in name resolution

(Background on this error at: https://sqlalche.me/e/14/e3q8)
[2023-12-11T09:03:32.788+0000] {processor.py:157} INFO - Started process (PID=4400) to work on /opt/airflow/dags/main_de_project_1_dag.py
[2023-12-11T09:03:33.598+0000] {processor.py:829} INFO - Processing file /opt/airflow/dags/main_de_project_1_dag.py for tasks to queue
[2023-12-11T09:03:34.050+0000] {logging_mixin.py:154} INFO - [2023-12-11T09:03:34.046+0000] {dagbag.py:536} INFO - Filling up the DagBag from /opt/airflow/dags/main_de_project_1_dag.py
[2023-12-11T09:03:36.394+0000] {logging_mixin.py:154} INFO - [2023-12-11T09:03:36.334+0000] {dagbag.py:346} ERROR - Failed to import: /opt/airflow/dags/main_de_project_1_dag.py
Traceback (most recent call last):
  File "/home/airflow/.local/lib/python3.8/site-packages/airflow/models/dagbag.py", line 342, in parse
    loader.exec_module(new_module)
  File "<frozen importlib._bootstrap_external>", line 843, in exec_module
  File "<frozen importlib._bootstrap>", line 219, in _call_with_frames_removed
  File "/opt/airflow/dags/main_de_project_1_dag.py", line 11, in <module>
    import create_tables
ModuleNotFoundError: No module named 'create_tables'
[2023-12-11T09:03:36.397+0000] {processor.py:841} WARNING - No viable dags retrieved from /opt/airflow/dags/main_de_project_1_dag.py
[2023-12-11T09:03:41.344+0000] {processor.py:179} INFO - Processing /opt/airflow/dags/main_de_project_1_dag.py took 9.283 seconds
[2023-12-11T09:04:49.467+0000] {processor.py:157} INFO - Started process (PID=4401) to work on /opt/airflow/dags/main_de_project_1_dag.py
[2023-12-11T09:04:49.473+0000] {processor.py:829} INFO - Processing file /opt/airflow/dags/main_de_project_1_dag.py for tasks to queue
[2023-12-11T09:04:49.492+0000] {logging_mixin.py:154} INFO - [2023-12-11T09:04:49.491+0000] {dagbag.py:536} INFO - Filling up the DagBag from /opt/airflow/dags/main_de_project_1_dag.py
[2023-12-11T09:04:49.702+0000] {logging_mixin.py:154} INFO - [2023-12-11T09:04:49.601+0000] {dagbag.py:346} ERROR - Failed to import: /opt/airflow/dags/main_de_project_1_dag.py
Traceback (most recent call last):
  File "/home/airflow/.local/lib/python3.8/site-packages/airflow/models/dagbag.py", line 342, in parse
    loader.exec_module(new_module)
  File "<frozen importlib._bootstrap_external>", line 843, in exec_module
  File "<frozen importlib._bootstrap>", line 219, in _call_with_frames_removed
  File "/opt/airflow/dags/main_de_project_1_dag.py", line 11, in <module>
    import create_tables
ModuleNotFoundError: No module named 'create_tables'
[2023-12-11T09:04:49.703+0000] {processor.py:841} WARNING - No viable dags retrieved from /opt/airflow/dags/main_de_project_1_dag.py
[2023-12-11T09:04:50.178+0000] {processor.py:179} INFO - Processing /opt/airflow/dags/main_de_project_1_dag.py took 1.037 seconds
[2023-12-11T09:08:21.060+0000] {processor.py:157} INFO - Started process (PID=4410) to work on /opt/airflow/dags/main_de_project_1_dag.py
[2023-12-11T09:08:21.634+0000] {processor.py:829} INFO - Processing file /opt/airflow/dags/main_de_project_1_dag.py for tasks to queue
[2023-12-11T09:08:26.589+0000] {logging_mixin.py:154} INFO - [2023-12-11T09:08:25.327+0000] {dagbag.py:536} INFO - Filling up the DagBag from /opt/airflow/dags/main_de_project_1_dag.py
[2023-12-11T09:31:25.011+0000] {processor.py:157} INFO - Started process (PID=79) to work on /opt/airflow/dags/main_de_project_1_dag.py
[2023-12-11T09:31:25.142+0000] {processor.py:829} INFO - Processing file /opt/airflow/dags/main_de_project_1_dag.py for tasks to queue
[2023-12-11T09:31:25.296+0000] {logging_mixin.py:154} INFO - [2023-12-11T09:31:25.235+0000] {dagbag.py:536} INFO - Filling up the DagBag from /opt/airflow/dags/main_de_project_1_dag.py
[2023-12-11T09:31:25.890+0000] {logging_mixin.py:154} INFO - [2023-12-11T09:31:25.499+0000] {dagbag.py:346} ERROR - Failed to import: /opt/airflow/dags/main_de_project_1_dag.py
Traceback (most recent call last):
  File "/home/airflow/.local/lib/python3.8/site-packages/airflow/models/dagbag.py", line 342, in parse
    loader.exec_module(new_module)
  File "<frozen importlib._bootstrap_external>", line 843, in exec_module
  File "<frozen importlib._bootstrap>", line 219, in _call_with_frames_removed
  File "/opt/airflow/dags/main_de_project_1_dag.py", line 11, in <module>
    import create_tables
ModuleNotFoundError: No module named 'create_tables'
[2023-12-11T09:31:25.962+0000] {processor.py:841} WARNING - No viable dags retrieved from /opt/airflow/dags/main_de_project_1_dag.py
[2023-12-11T09:31:26.682+0000] {processor.py:179} INFO - Processing /opt/airflow/dags/main_de_project_1_dag.py took 2.198 seconds
